Workbook
Name JR_PAGE_ANCHOR_0_1: report1!$A$1

Sheet report1
C1: UAPB | D1: : | F1: KEMENTERIAN KESEHATAN
C2: UAPPB-E1 | D2: : | F2: DITJEN BINA UPAYA KESEHATAN
C3: UAPPB-W | D3: : | F3: DIT JEN PELAYANAN KESEHATAN
A4: LAPORAN RINCIAN BARANG PERSEDIAAN
A5: UNTUK PERIODE YANG BERAKHIR TANGGAL 31-12-2022
A6: TAHUN ANGGARAN : 2022
C7: NAMA UAPKPB : RUMAH SAKIT FATMAWATI JAKARTA
C8: KODE UAPKPB : 024.04.0100.415432.001.KD
C9: KODE | G9: U R A I A N | N9: N I L A I | Q9: MUTASI
V10: S/D 31-12-2022
N11: JUMLAH | O11: RUPIAH | R11: KELUAR | U11: JUMLAH | V11: JUMLAH | X11: RUPIAH
G12: BAHAN BANGUNAN DAN KONSTRUKSI LAINNYA | N12: 0 | V12: 0
C13: 000001 | G13: BAHAN BANGUNAN | N13: 0 | P13: 1 | R13: 1 | U13: 0 | V13: 0 | X13: 0
G14: BAHAN BAKAR MINYAK (BAHAN BAKU) | N14: 0 | V14: 0
C15: 000001 | G15: Mobil Diesel Oil | N15: 0 | P15: 2 | R15: 2 | U15: 0 | V15: 0 | X15: 0
G16: SUKU CADANG ALAT ANGKUTAN DARAT TAK BERMOTOR | N16: 0 | V16: 0
C17: 000001 | G17: SUKU CADANG ALAT ANGKUTAN DARAT | N17: 0 | P17: 1 | R17: 1 | U17: 0 | V17: 0 | X17: 0
G18: OBAT CAIR (BARANG KONSUMSI) | N18: 0 | V18: 0
C19: 000001 | G19: OBAT CAIR (BARANG KONSUMSI) | N19: 0 | P19: 1 | R19: 1 | U19: 0 | V19: 0 | X19: 0
G20: OBAT PADAT (BARANG KONSUMSI) | N20: 0 | V20: 0
C21: 000001 | G21: Obat Padat (Barang Konsumsi) | N21: 0 | P21: 2 | R21: 2 | U21: 0 | V21: 0 | X21: 0
G22: OBAT SERBUK/TEPUNG (BARANG KONSUMSI) | N22: 0 | V22: 0
C23: 000001 | G23: Obat Serbuk/Tepung (Barang Konsumsi) | N23: 0 | P23: 1 | R23: 1 | U23: 0 | V23: 0 | X23: 0
G24: OBAT LAINNYA (BARANG KONSUMSI) | N24: 0 | V24: 0
C25: 000001 | G25: OBAT LAINNYA (BARANG KONSUMSI) | N25: 0 | P25: 1 | R25: 1 | U25: 0 | V25: 0 | X25: 0
G26: OBAT CAIR (PERSEDIAAN LAINNYA) | N26: 5961704986 | V26: 32453103381
C27: 000002 | G27: NONCORT MND | N27: 0 | P27: 740 | R27: 0 | U27: 740 | V27: 740 | X27: 31233870
C28: 000003 | G28: IODINE POVIDONE 10% 1 L | N28: 0 | P28: 1282 | R28: 0 | U28: 1282 | V28: 1282 | X28: 62522076
C29: 000008 | G29: MgSO4 INJ 40% | N29: 19 | P29: 0 | R29: 0 | U29: 0 | V29: 19 | X29: 76000
C30: 000010 | G30: AMPICILIN SERBUK INJEKSI I.M I.V 1000 MG VIAL (SBG | N30: 7 | P30: 0 | R30: 0 | U30: 0 | V30: 7 | X30: 39200
C31: 000016 | G31: INPEPSA SUSP.100 ML (500 MG ML) | N31: 12 | P31: 0 | R31: 0 | U31: 0 | V31: 12 | X31: 712800
C32: 000018 | G32: HAEMOCTIN SERBUK INJEKSI 500 UI VIAL + PELARUT 5 M | N32: 23 | P32: 0 | R32: 0 | U32: 0 | V32: 23 | X32: 26737500
C33: 000020 | G33: MEROPENEM INJ 0.5 GR | N33: 246 | P33: 0 | R33: 0 | U33: 0 | V33: 246 | X33: 4024314
C34: 000021 | G34: IODINE POVIDONE 10% 1 L | N34: 0 | P34: 450 | R34: 0 | U34: 450 | V34: 450 | X34: 21748500
A35: LAPORAN RINCIAN BARANG PERSEDIAAN
A36: UNTUK PERIODE YANG BERAKHIR TANGGAL 31-12-2022
A37: TAHUN ANGGARAN : 2022
C38: NAMA UAPKPB : RUMAH SAKIT FATMAWATI JAKARTA
C39: KODE UAPKPB : 024.04.0100.415432.001.KD
C40: KODE | G40: U R A I A N | N40: N I L A I | Q40: MUTASI
...

Sheet ObatCair
A1: NOMOR | B1: NAMA SAKTI | D1: NAMA INVENTORY | E1: KODE INTERNAL | F1: SALDO | G1: MASUK | H1: SALDO INV | I1: PENGADAAN
A2: 000294 | B2: ACETON TEKNIS | C2: =IF(B2=D2,1,0) -> 1 | D2: ACETON TEKNIS | E2: =VLOOKUP(D2,'kode internal'!$B$1:$D$4717,2,FALSE) -> 50A002 | F2: 5 | G2: 0 | H2: =VLOOKUP(D2,'kode internal'!$B$1:$E$4717,4,FALSE) -> 5 | I2: =VLOOKUP(D2,'kode internal'!$B$1:$F$4717,5,FALSE) -> 0
A3: 000116 | B3: ACNE FELDIN LOTION 6.6% 110 ML | C3: =IF(B3=D3,1,0) -> 1 | D3: ACNE FELDIN LOTION 6.6% 110 ML | E3: =VLOOKUP(D3,'kode internal'!$B$1:$D$4717,2,FALSE) -> 60A005 | F3: 0 | G3: 2 | H3: =VLOOKUP(D3,'kode internal'!$B$1:$E$4717,4,FALSE) -> 0 | I3: =VLOOKUP(D3,'kode internal'!$B$1:$F$4717,5,FALSE) -> 2
A4: 000579 | B4: ACRAN INJ 25 MG / ML, 2 ML | C4: =IF(B4=D4,1,0) -> 1 | D4: ACRAN INJ 25 MG / ML, 2 ML | E4: =VLOOKUP(D4,'kode internal'!$B$1:$D$4717,2,FALSE) -> 40A120 | F4: 0 | G4: 360 | H4: =VLOOKUP(D4,'kode internal'!$B$1:$E$4717,4,FALSE) -> 0 | I4: =VLOOKUP(D4,'kode internal'!$B$1:$F$4717,5,FALSE) -> 360
A5: 000575 | B5: ACTABONE INJEKSI 300 MG 5 ML,AMPUL 5 ML | C5: =IF(B5=D5,1,0) -> 0 | D5: ACTABONE INJEKSI 300 MG/5 ML,AMPUL 5 ML | E5: =VLOOKUP(D5,'kode internal'!$B$1:$D$4717,2,FALSE) -> 12A009 | F5: 0 | G5: 35 | H5: =VLOOKUP(D5,'kode internal'!$B$1:$E$4717,4,FALSE) -> 0 | I5: =VLOOKUP(D5,'kode internal'!$B$1:$F$4717,5,FALSE) -> 35
A6: 000492 | B6: ACTILYSE INJ 50 MG/ML | C6: =IF(B6=D6,1,0) -> 1 | D6: ACTILYSE INJ 50 MG/ML | E6: =VLOOKUP(D6,'kode internal'!$B$1:$D$4717,2,FALSE) -> 40A104 | F6: 3 | G6: 60 | H6: =VLOOKUP(D6,'kode internal'!$B$1:$E$4717,4,FALSE) -> 3 | I6: =VLOOKUP(D6,'kode internal'!$B$1:$F$4717,5,FALSE) -> 60
A7: 000496 | B7: ACTRAPID HM 100IU 10 ML | C7: =IF(B7=D7,1,0) -> 0 | D7: ACTRAPID HM 100IU / 10 ML | E7: =VLOOKUP(D7,'kode internal'!$B$1:$D$4717,2,FALSE) -> 40A080 | F7: 121 | G7: 35 | H7: =VLOOKUP(D7,'kode internal'!$B$1:$E$4717,4,FALSE) -> 120.53 | I7: =VLOOKUP(D7,'kode internal'!$B$1:$F$4717,5,FALSE) -> 35
A8: 000729 | B8: ADS (DIPHTHERIA ANTITOKSIN B.P) 10.000 IU | C8: =IF(B8=D8,1,0) -> 1 | D8: ADS (DIPHTHERIA ANTITOKSIN B.P) 10.000 IU | E8: =VLOOKUP(D8,'kode internal'!$B$1:$D$4717,2,FALSE) -> 17A003 | F8: 0 | G8: 10 | H8: =VLOOKUP(D8,'kode internal'!$B$1:$E$4717,4,FALSE) -> 0 | I8: =VLOOKUP(D8,'kode internal'!$B$1:$F$4717,5,FALSE) -> 10
A9: 000625 | B9: ALBAPURE INFUS 20%, BOTOL @ 100 ML | C9: =IF(B9=D9,1,0) -> 1 | D9: ALBAPURE INFUS 20%, BOTOL @ 100 ML | E9: =VLOOKUP(D9,'kode internal'!$B$1:$D$4717,2,FALSE) -> 40A081 | F9: 0 | G9: 524 | H9: =VLOOKUP(D9,'kode internal'!$B$1:$E$4717,4,FALSE) -> 0 | I9: =VLOOKUP(D9,'kode internal'!$B$1:$F$4717,5,FALSE) -> 524
A10: 000679 | B10: ALBOTHYL CONC 30 ML | C10: =IF(B10=D10,1,0) -> 1 | D10: ALBOTHYL CONC 30 ML | E10: =VLOOKUP(D10,'kode internal'!$B$1:$D$4717,2,FALSE) -> 70A031 | F10: 0 | G10: 3 | H10: =VLOOKUP(D10,'kode internal'!$B$1:$E$4717,4,FALSE) -> 0 | I10: =VLOOKUP(D10,'kode internal'!$B$1:$F$4717,5,FALSE) -> 3
A11: 000275 | B11: ALEGYSAL ED 0.1% 5 ML | C11: =IF(B11=D11,1,0) -> 1 | D11: ALEGYSAL ED 0.1% 5 ML | E11: =VLOOKUP(D11,'kode internal'!$B$1:$D$4717,2,FALSE) -> 70A027 | F11: 5 | G11: 0 | H11: =VLOOKUP(D11,'kode internal'!$B$1:$E$4717,4,FALSE) -> 5 | I11: =VLOOKUP(D11,'kode internal'!$B$1:$F$4717,5,FALSE) -> 0
A12: 000164 | B12: ALKOHOL CAIRAN 70 % | C12: =IF(B12=D12,1,0) -> 1 | D12: ALKOHOL CAIRAN 70 % | E12: =VLOOKUP(D12,'kode internal'!$B$1:$D$4717,2,FALSE) -> PFA004 | F12: 5 | G12: 0 | H12: =VLOOKUP(D12,'kode internal'!$B$1:$E$4717,4,FALSE) -> 4.8 | I12: =VLOOKUP(D12,'kode internal'!$B$1:$F$4717,5,FALSE) -> 0
A13: 000603 | B13: ALPROSTADIL 500 MCG/ML AMP INJ | C13: =IF(B13=D13,1,0) -> 1 | D13: ALPROSTADIL 500 MCG/ML AMP INJ | E13: =VLOOKUP(D13,'kode internal'!$B$1:$D$4717,2,FALSE) -> 40A145 | F13: 0 | G13: 2 | H13: =VLOOKUP(D13,'kode internal'!$B$1:$E$4717,4,FALSE) -> 0 | I13: =VLOOKUP(D13,'kode internal'!$B$1:$F$4717,5,FALSE) -> 2
... A573: 000296 | B573: ZOVIRAX INJ | C573: =IF(B573=D573,1,0) -> 1 | D573: ZOVIRAX INJ | E573: =VLOOKUP(D573,'kode internal'!$B$1:$D$4717,2,FALSE) -> 40Z006 | F573: 56 | G573: 61 | H573: =VLOOKUP(D573,'kode internal'!$B$1:$E$4717,4,FALSE) -> 56 | I573: =VLOOKUP(D573,'kode internal'!$B$1:$F$4717,5,FALSE) -> 110
F574: =SUM(F2:F573) -> 244039 | G574: =SUM(G2:G573) -> 1157342 | H574: =VLOOKUP(D574,'kode internal'!$B$1:$E$4717,4,FALSE) -> #N/A | I574: =VLOOKUP(D574,'kode internal'!$B$1:$F$4717,5,FALSE) -> #N/A
B5060: BARANG PERSEDIAAN | D5060: BARANG PERSEDIAAN | F5060: 0
A5061: 000001 | B5061: Vaksin Meningitis Menivax 2020 | D5061: Vaksin Meningitis Menivax 2020 | F5061: 0 | G5061: 2104
A5062: Jumlah
A5063: Keterangan
A5064: 1. Persediaan senilai
A5065: 2. Persediaan senilai

Sheet obat padat
B1: NAMA SAKTI | C1: =IF(B1=D1,1,0) -> 0 | D1: NAMA INVENTORI | E1: KODE INTERNAL | F1: SALDO | G1: PENGADAAN | H1: SALDO INV | I1: PENGADAAN INV
A2: 000002 | B2: KETOSTERIL TAB 630 MG | C2: =IF(B2=D2,1,0) -> 1 | D2: KETOSTERIL TAB 630 MG | E2: =VLOOKUP(D2,'kode internal'!$B$1:$D$4717,2,FALSE) -> 10K024 | F2: 3 | G2: 0 | H2: =VLOOKUP(D2,'kode internal'!$B$1:$E$4717,4,FALSE) -> 3 | I2: =VLOOKUP(D2,'kode internal'!$B$1:$F$4717,5,FALSE) -> 0
A3: 000003 | B3: ASPILETS 80 MG TAB | C3: =IF(B3=D3,1,0) -> 1 | D3: ASPILETS 80 MG TAB | E3: =VLOOKUP(D3,'kode internal'!$B$1:$D$4717,2,FALSE) -> 10A105 | F3: 22 | G3: 88 | H3: =VLOOKUP(D3,'kode internal'!$B$1:$E$4717,4,FALSE) -> 22 | I3: =VLOOKUP(D3,'kode internal'!$B$1:$F$4717,5,FALSE) -> 88
A4: 000009 | B4: ERYTROMICIN KAPL 500 MG | C4: =IF(B4=D4,1,0) -> 1 | D4: ERYTROMICIN KAPL 500 MG | E4: =VLOOKUP(D4,'kode internal'!$B$1:$D$4717,2,FALSE) -> 10E094 | F4: 1200 | G4: 800 | H4: =VLOOKUP(D4,'kode internal'!$B$1:$E$4717,4,FALSE) -> 1200 | I4: =VLOOKUP(D4,'kode internal'!$B$1:$F$4717,5,FALSE) -> 800
A5: 000010 | B5: KETESSE TAB 25 MG | C5: =IF(B5=D5,1,0) -> 1 | D5: KETESSE TAB 25 MG | E5: =VLOOKUP(D5,'kode internal'!$B$1:$D$4717,2,FALSE) -> 10K071 | F5: 150 | G5: 200 | H5: =VLOOKUP(D5,'kode internal'!$B$1:$E$4717,4,FALSE) -> 150 | I5: =VLOOKUP(D5,'kode internal'!$B$1:$F$4717,5,FALSE) -> 200
A6: 000011 | B6: LACTO - B SACHET | C6: =IF(B6=D6,1,0) -> 1 | D6: LACTO - B SACHET | E6: =VLOOKUP(D6,'kode internal'!$B$1:$D$4717,2,FALSE) -> 10L158 | F6: 237 | G6: 760 | H6: =VLOOKUP(D6,'kode internal'!$B$1:$E$4717,4,FALSE) -> 237 | I6: =VLOOKUP(D6,'kode internal'!$B$1:$F$4717,5,FALSE) -> 760
A7: 000012 | B7: HP PRO PLUS | C7: =IF(B7=D7,1,0) -> 1 | D7: HP PRO PLUS | E7: =VLOOKUP(D7,'kode internal'!$B$1:$D$4717,2,FALSE) -> 10H086 | F7: 440 | G7: 20 | H7: =VLOOKUP(D7,'kode internal'!$B$1:$E$4717,4,FALSE) -> 440 | I7: =VLOOKUP(D7,'kode internal'!$B$1:$F$4717,5,FALSE) -> 20
A8: 000013 | B8: UROTRACTIN KAPSUL 400 MG | C8: =IF(B8=D8,1,0) -> 1 | D8: UROTRACTIN KAPSUL 400 MG | E8: =VLOOKUP(D8,'kode internal'!$B$1:$D$4717,2,FALSE) -> 10U028 | F8: 83 | G8: 430 | H8: =VLOOKUP(D8,'kode internal'!$B$1:$E$4717,4,FALSE) -> 83 | I8: =VLOOKUP(D8,'kode internal'!$B$1:$F$4717,5,FALSE) -> 430
A9: 000015 | B9: SERLOF TABLET SALUT 50 MG | C9: =IF(B9=D9,1,0) -> 1 | D9: SERLOF TABLET SALUT 50 MG | E9: =VLOOKUP(D9,'kode internal'!$B$1:$D$4717,2,FALSE) -> 10S170 | F9: 150 | G9: 0 | H9: =VLOOKUP(D9,'kode internal'!$B$1:$E$4717,4,FALSE) -> 150 | I9: =VLOOKUP(D9,'kode internal'!$B$1:$F$4717,5,FALSE) -> 0
A10: 000019 | B10: CITICOLINE 500 MG TAB | C10: =IF(B10=D10,1,0) -> 1 | D10: CITICOLINE 500 MG TAB | E10: =VLOOKUP(D10,'kode internal'!$B$1:$D$4717,2,FALSE) -> #N/A | F10: 0 | G10: 3000 | H10: =VLOOKUP(D10,'kode internal'!$B$1:$E$4717,4,FALSE) -> #N/A | I10: =VLOOKUP(D10,'kode internal'!$B$1:$F$4717,5,FALSE) -> #N/A
A11: 000020 | B11: KALXETIN CAP 10 MG | C11: =IF(B11=D11,1,0) -> 1 | D11: KALXETIN CAP 10 MG | E11: =VLOOKUP(D11,'kode internal'!$B$1:$D$4717,2,FALSE) -> 10K067 | F11: 335 | G11: 1380 | H11: =VLOOKUP(D11,'kode internal'!$B$1:$E$4717,4,FALSE) -> 335 | I11: =VLOOKUP(D11,'kode internal'!$B$1:$F$4717,5,FALSE) -> 1380
A12: 000021 | B12: GEMFIBROZIL TAB 300 MG | C12: =IF(B12=D12,1,0) -> 1 | D12: GEMFIBROZIL TAB 300 MG | E12: =VLOOKUP(D12,'kode internal'!$B$1:$D$4717,2,FALSE) -> 10G077 | F12: 2714 | G12: 2400 | H12: =VLOOKUP(D12,'kode internal'!$B$1:$E$4717,4,FALSE) -> 2714 | I12: =VLOOKUP(D12,'kode internal'!$B$1:$F$4717,5,FALSE) -> 2400
A13: 000022 | B13: ORALIT 200 ml | C13: =IF(B13=D13,1,0) -> 1 | D13: ORALIT 200 ml | E13: =VLOOKUP(D13,'kode internal'!$B$1:$D$4717,2,FALSE) -> 10O014 | F13: 9 | G13: 800 | H13: =VLOOKUP(D13,'kode internal'!$B$1:$E$4717,4,FALSE) -> 9 | I13: =VLOOKUP(D13,'kode internal'!$B$1:$F$4717,5,FALSE) -> 800
... A462: 000599 | B462: LEVOFLOXACIN 100 MG | C462: =IF(B462=D462,1,0) -> 1 | D462: LEVOFLOXACIN 100 MG | E462: =VLOOKUP(D462,'kode internal'!$B$1:$D$4717,2,FALSE) -> 14L007.1 | F462: 0 | G462: 400 | H462: =VLOOKUP(D462,'kode internal'!$B$1:$E$4717,4,FALSE) -> 0 | I462: =VLOOKUP(D462,'kode internal'!$B$1:$F$4717,5,FALSE) -> 400

Sheet obat gas
B1: NAMA SAKTI | C1: =IF(B1=D1,1,0) -> 0 | D1: NAMA INVENTORI | E1: KODE INTERNAL | F1: SALDO | G1: PENGADAAN | H1: SALDO INV | I1: PENGADAAN INV
A2: 000001 | B2: O2 GAS BTL 6 M3 | C2: =IF(B2=D2,1,0) -> 1 | D2: O2 GAS BTL 6 M3 | E2: =VLOOKUP(D2,'kode internal'!$B$1:$D$4717,2,FALSE) -> #N/A | F2: 0 | G2: 122 | H2: =VLOOKUP(D2,'kode internal'!$B$1:$E$4717,4,FALSE) -> #N/A | I2: =VLOOKUP(D2,'kode internal'!$B$1:$F$4717,5,FALSE) -> #N/A
A3: 000002 | B3: N2 CAIR | C3: =IF(B3=D3,1,0) -> 1 | D3: N2 CAIR | E3: =VLOOKUP(D3,'kode internal'!$B$1:$D$4717,2,FALSE) -> 85N013 | F3: 0 | G3: 75 | H3: =VLOOKUP(D3,'kode internal'!$B$1:$E$4717,4,FALSE) -> 0 | I3: =VLOOKUP(D3,'kode internal'!$B$1:$F$4717,5,FALSE) -> 75
A4: 000003 | B4: N2O 25 KG | C4: =IF(B4=D4,1,0) -> 1 | D4: N2O 25 KG | E4: =VLOOKUP(D4,'kode internal'!$B$1:$D$4717,2,FALSE) -> 85N008 | F4: 0 | G4: 406818 | H4: =VLOOKUP(D4,'kode internal'!$B$1:$E$4717,4,FALSE) -> 14160.75 | I4: =VLOOKUP(D4,'kode internal'!$B$1:$F$4717,5,FALSE) -> 509787
A5: 000004 | B5: CO2 25 KG | C5: =IF(B5=D5,1,0) -> 1 | D5: CO2 25 KG | E5: =VLOOKUP(D5,'kode internal'!$B$1:$D$4717,2,FALSE) -> 85C009 | F5: 0 | G5: 18 | H5: =VLOOKUP(D5,'kode internal'!$B$1:$E$4717,4,FALSE) -> 4 | I5: =VLOOKUP(D5,'kode internal'!$B$1:$F$4717,5,FALSE) -> 21
A6: 000005 | B6: CO2 2 KG | C6: =IF(B6=D6,1,0) -> 1 | D6: CO2 2 KG | E6: =VLOOKUP(D6,'kode internal'!$B$1:$D$4717,2,FALSE) -> 85C012 | F6: 0 | G6: 4 | H6: =VLOOKUP(D6,'kode internal'!$B$1:$E$4717,4,FALSE) -> 0 | I6: =VLOOKUP(D6,'kode internal'!$B$1:$F$4717,5,FALSE) -> 4
A7: 000007 | B7: O2 GAS BTL 1 M3 | C7: =IF(B7=D7,1,0) -> 1 | D7: O2 GAS BTL 1 M3 | E7: =VLOOKUP(D7,'kode internal'!$B$1:$D$4717,2,FALSE) -> 85O008 | F7: 0 | G7: 1337 | H7: =VLOOKUP(D7,'kode internal'!$B$1:$E$4717,4,FALSE) -> 0 | I7: =VLOOKUP(D7,'kode internal'!$B$1:$F$4717,5,FALSE) -> 2760
A8: 000008 | B8: O2 GAS BTL 6 M3 | C8: =IF(B8=D8,1,0) -> 1 | D8: O2 GAS BTL 6 M3 | E8: =VLOOKUP(D8,'kode internal'!$B$1:$D$4717,2,FALSE) -> 85O006 | F8: 0 | G8: 759 | H8: =VLOOKUP(D8,'kode internal'!$B$1:$E$4717,4,FALSE) -> 104 | I8: =VLOOKUP(D8,'kode internal'!$B$1:$F$4717,5,FALSE) -> 1318
A9: 000009 | B9: SODALIME 4.5 kg | C9: =IF(B9=D9,1,0) -> 1 | D9: SODALIME 4.5 kg | E9: =VLOOKUP(D9,'kode internal'!$B$1:$D$4717,2,FALSE) -> 85S001 | F9: 0 | G9: 120 | H9: =VLOOKUP(D9,'kode internal'!$B$1:$E$4717,4,FALSE) -> 0 | I9: =VLOOKUP(D9,'kode internal'!$B$1:$F$4717,5,FALSE) -> 120
A10: 000010 | B10: O2 GAS BTL 1 M3 | C10: =IF(B10=D10,1,0) -> 1 | D10: O2 GAS BTL 1 M3 | E10: =VLOOKUP(D10,'kode internal'!$B$1:$D$4717,2,FALSE) -> 85O008 | F10: 0 | G10: 1413 | H10: =VLOOKUP(D10,'kode internal'!$B$1:$E$4717,4,FALSE) -> 0 | I10: =VLOOKUP(D10,'kode internal'!$B$1:$F$4717,5,FALSE) -> 2760
A11: 000011 | B11: O2 GAS BTL 6 M3 | C11: =IF(B11=D11,1,0) -> 1 | D11: O2 GAS BTL 6 M3 | E11: =VLOOKUP(D11,'kode internal'!$B$1:$D$4717,2,FALSE) -> 85O006 | F11: 104 | G11: 443 | H11: =VLOOKUP(D11,'kode internal'!$B$1:$E$4717,4,FALSE) -> 104 | I11: =VLOOKUP(D11,'kode internal'!$B$1:$F$4717,5,FALSE) -> 1318
A12: 000012 | B12: N2O 25 KG | C12: =IF(B12=D12,1,0) -> 1 | D12: N2O 25 KG | E12: =VLOOKUP(D12,'kode internal'!$B$1:$D$4717,2,FALSE) -> 85N008 | F12: 14161 | G12: 99125 | H12: =VLOOKUP(D12,'kode internal'!$B$1:$E$4717,4,FALSE) -> 14160.75 | I12: =VLOOKUP(D12,'kode internal'!$B$1:$F$4717,5,FALSE) -> 509787
A13: 000013 | B13: CO2 25 KG | C13: =IF(B13=D13,1,0) -> 1 | D13: CO2 25 KG | E13: =VLOOKUP(D13,'kode internal'!$B$1:$D$4717,2,FALSE) -> 85C009 | F13: 4 | G13: 3 | H13: =VLOOKUP(D13,'kode internal'!$B$1:$E$4717,4,FALSE) -> 4 | I13: =VLOOKUP(D13,'kode internal'!$B$1:$F$4717,5,FALSE) -> 21

Sheet serbuktepung
B1: NAMA SAKTI | C1: =IF(B1=D1,1,0) -> 0 | D1: NAMA INVENTORI | E1: KODE INTERNAL | F1: SALDO | G1: PENGADAAN | H1: SALDO INV | I1: PENGADAAN INV
A2: 000003 | B2: FRESUBIN 2 KCAL FIBRE 200 ML | C2: =IF(B2=D2,1,0) -> 1 | D2: FRESUBIN 2 KCAL FIBRE 200 ML | E2: =VLOOKUP(D2,'kode internal'!$B$1:$D$4717,2,FALSE) -> 60F003 | F2: 16 | G2: 0 | H2: =VLOOKUP(D2,'kode internal'!$B$1:$E$4717,4,FALSE) -> 16 | I2: =VLOOKUP(D2,'kode internal'!$B$1:$F$4717,5,FALSE) -> 0
A3: 000004 | B3: CHLORAMPHENICOL BASE PULV | C3: =IF(B3=D3,1,0) -> 1 | D3: CHLORAMPHENICOL BASE PULV | E3: =VLOOKUP(D3,'kode internal'!$B$1:$D$4717,2,FALSE) -> 50C013 | F3: 360 | G3: 0 | H3: =VLOOKUP(D3,'kode internal'!$B$1:$E$4717,4,FALSE) -> 360 | I3: =VLOOKUP(D3,'kode internal'!$B$1:$F$4717,5,FALSE) -> 0
A4: 000006 | B4: MICROBAR POWDER 3.5 KG | C4: =IF(B4=D4,1,0) -> 1 | D4: MICROBAR POWDER 3.5 KG | E4: =VLOOKUP(D4,'kode internal'!$B$1:$D$4717,2,FALSE) -> 50M012 | F4: 2 | G4: 3 | H4: =VLOOKUP(D4,'kode internal'!$B$1:$E$4717,4,FALSE) -> 2 | I4: =VLOOKUP(D4,'kode internal'!$B$1:$F$4717,5,FALSE) -> 3
A5: 000009 | B5: THEOPHYLIN PULV | C5: =IF(B5=D5,1,0) -> 1 | D5: THEOPHYLIN PULV | E5: =VLOOKUP(D5,'kode internal'!$B$1:$D$4717,2,FALSE) -> 50T004 | F5: 1057 | G5: 0 | H5: =VLOOKUP(D5,'kode internal'!$B$1:$E$4717,4,FALSE) -> 1058.25 | I5: =VLOOKUP(D5,'kode internal'!$B$1:$F$4717,5,FALSE) -> 0
A6: 000013 | B6: RESORCINE | C6: =IF(B6=D6,1,0) -> 1 | D6: RESORCINE | E6: =VLOOKUP(D6,'kode internal'!$B$1:$D$4717,2,FALSE) -> 50R001 | F6: 409 | G6: 0 | H6: =VLOOKUP(D6,'kode internal'!$B$1:$E$4717,4,FALSE) -> 408.86 | I6: =VLOOKUP(D6,'kode internal'!$B$1:$F$4717,5,FALSE) -> 0
A7: 000014 | B7: NIPAGIN PULV | C7: =IF(B7=D7,1,0) -> 1 | D7: NIPAGIN PULV | E7: =VLOOKUP(D7,'kode internal'!$B$1:$D$4717,2,FALSE) -> 50N006 | F7: 300 | G7: 0 | H7: =VLOOKUP(D7,'kode internal'!$B$1:$E$4717,4,FALSE) -> 300 | I7: =VLOOKUP(D7,'kode internal'!$B$1:$F$4717,5,FALSE) -> 0
A8: 000015 | B8: MASKER JERAWAT 500 G | C8: =IF(B8=D8,1,0) -> 1 | D8: MASKER JERAWAT 500 G | E8: =VLOOKUP(D8,'kode internal'!$B$1:$D$4717,2,FALSE) -> 50M018 | F8: 0 | G8: 5 | H8: =VLOOKUP(D8,'kode internal'!$B$1:$E$4717,4,FALSE) -> 0 | I8: =VLOOKUP(D8,'kode internal'!$B$1:$F$4717,5,FALSE) -> 5
A9: 000016 | B9: MENTHOL CRYSTAL 1 KG | C9: =IF(B9=D9,1,0) -> 1 | D9: MENTHOL CRYSTAL 1 KG | E9: =VLOOKUP(D9,'kode internal'!$B$1:$D$4717,2,FALSE) -> 50M004.1 | F9: 1000 | G9: 5 | H9: =VLOOKUP(D9,'kode internal'!$B$1:$E$4717,4,FALSE) -> 1000 | I9: =VLOOKUP(D9,'kode internal'!$B$1:$F$4717,5,FALSE) -> 5
A10: 000017 | B10: KCL CRYSTAL | C10: =IF(B10=D10,1,0) -> 1 | D10: KCL CRYSTAL | E10: =VLOOKUP(D10,'kode internal'!$B$1:$D$4717,2,FALSE) -> 50K020 | F10: 650 | G10: 0 | H10: =VLOOKUP(D10,'kode internal'!$B$1:$E$4717,4,FALSE) -> 650 | I10: =VLOOKUP(D10,'kode internal'!$B$1:$F$4717,5,FALSE) -> 0
A11: 000019 | B11: CHLORAL HYDRAS PULV | C11: =IF(B11=D11,1,0) -> 1 | D11: CHLORAL HYDRAS PULV | E11: =VLOOKUP(D11,'kode internal'!$B$1:$D$4717,2,FALSE) -> 50C012 | F11: 217 | G11: 0 | H11: =VLOOKUP(D11,'kode internal'!$B$1:$E$4717,4,FALSE) -> 217.38 | I11: =VLOOKUP(D11,'kode internal'!$B$1:$F$4717,5,FALSE) -> 0
A12: 000020 | B12: CALCIUM CARBONAT PULV | C12: =IF(B12=D12,1,0) -> 1 | D12: CALCIUM CARBONAT PULV | E12: =VLOOKUP(D12,'kode internal'!$B$1:$D$4717,2,FALSE) -> 50C001 | F12: 75000 | G12: 70000 | H12: =VLOOKUP(D12,'kode internal'!$B$1:$E$4717,4,FALSE) -> 75000 | I12: =VLOOKUP(D12,'kode internal'!$B$1:$F$4717,5,FALSE) -> 70000
A13: 000021 | B13: ARGENTI NITRAS PULV | C13: =IF(B13=D13,1,0) -> 1 | D13: ARGENTI NITRAS PULV | E13: =VLOOKUP(D13,'kode internal'!$B$1:$D$4717,2,FALSE) -> 50A035 | F13: 75 | G13: 0 | H13: =VLOOKUP(D13,'kode internal'!$B$1:$E$4717,4,FALSE) -> 75 | I13: =VLOOKUP(D13,'kode internal'!$B$1:$F$4717,5,FALSE) -> 0
... A25: 000045 | B25: STREPTOMYSIN SULFAT INJEKSI | C25: =IF(B25=D25,1,0) -> 1 | D25: STREPTOMYSIN SULFAT INJEKSI | E25: =VLOOKUP(D25,'kode internal'!$B$1:$D$4717,2,FALSE) -> 14S022 | F25: 0 | G25: 908 | H25: =VLOOKUP(D25,'kode internal'!$B$1:$E$4717,4,FALSE) -> 0 | I25: =VLOOKUP(D25,'kode internal'!$B$1:$F$4717,5,FALSE) -> 908

Sheet gel salep
B1: NAMA SAKTI | C1: =IF(B1=D1,1,0) -> 0 | D1: NAMA INVENTORI | E1: KODE INTERNAL | F1: SALDO | G1: PENGADAAN | H1: SALDO INV | I1: PENGADAAN INV
A2: 000001 | B2: PURIFYING CLEANSING MILK NORMAL SKIN 100ML | C2: =IF(B2=D2,1,0) -> 1 | D2: PURIFYING CLEANSING MILK NORMAL SKIN 100ML | E2: =VLOOKUP(D2,'kode internal'!$B$1:$D$4717,2,FALSE) -> 30P032 | F2: 0 | G2: 10 | H2: =VLOOKUP(D2,'kode internal'!$B$1:$E$4717,4,FALSE) -> 0 | I2: =VLOOKUP(D2,'kode internal'!$B$1:$F$4717,5,FALSE) -> 10
A3: 000008 | B3: KEMICETIN ZK 2% 15 gr | C3: =IF(B3=D3,1,0) -> 1 | D3: KEMICETIN ZK 2% 15 gr | E3: =VLOOKUP(D3,'kode internal'!$B$1:$D$4717,2,FALSE) -> PF048 | F3: 171 | G3: 0 | H3: =VLOOKUP(D3,'kode internal'!$B$1:$E$4717,4,FALSE) -> 171 | I3: =VLOOKUP(D3,'kode internal'!$B$1:$F$4717,5,FALSE) -> 0
A4: 000010 | B4: PURIFYING CLEANSING MILK OILY SKIN 100ML | C4: =IF(B4=D4,1,0) -> 1 | D4: PURIFYING CLEANSING MILK OILY SKIN 100ML | E4: =VLOOKUP(D4,'kode internal'!$B$1:$D$4717,2,FALSE) -> 30P033 | F4: 20 | G4: 0 | H4: =VLOOKUP(D4,'kode internal'!$B$1:$E$4717,4,FALSE) -> 20 | I4: =VLOOKUP(D4,'kode internal'!$B$1:$F$4717,5,FALSE) -> 0
A5: 000011 | B5: PROTOFEN SUPP | C5: =IF(B5=D5,1,0) -> 1 | D5: PROTOFEN SUPP | E5: =VLOOKUP(D5,'kode internal'!$B$1:$D$4717,2,FALSE) -> 30P013 | F5: 1695 | G5: 3300 | H5: =VLOOKUP(D5,'kode internal'!$B$1:$E$4717,4,FALSE) -> 1695 | I5: =VLOOKUP(D5,'kode internal'!$B$1:$F$4717,5,FALSE) -> 3300
A6: 000012 | B6: DERMASOLON CREAM 5 G (0,25 MG/G) | C6: =IF(B6=D6,1,0) -> 1 | D6: DERMASOLON CREAM 5 G (0,25 MG/G) | E6: =VLOOKUP(D6,'kode internal'!$B$1:$D$4717,2,FALSE) -> 30D019 | F6: 11 | G6: 30 | H6: =VLOOKUP(D6,'kode internal'!$B$1:$E$4717,4,FALSE) -> 11 | I6: =VLOOKUP(D6,'kode internal'!$B$1:$F$4717,5,FALSE) -> 30
A7: 000013 | B7: CENDO FENICOL ZM 3.5 gr | C7: =IF(B7=D7,1,0) -> 1 | D7: CENDO FENICOL ZM 3.5 gr | E7: =VLOOKUP(D7,'kode internal'!$B$1:$D$4717,2,FALSE) -> 30C011 | F7: 0 | G7: 445 | H7: =VLOOKUP(D7,'kode internal'!$B$1:$E$4717,4,FALSE) -> 0.75 | I7: =VLOOKUP(D7,'kode internal'!$B$1:$F$4717,5,FALSE) -> 485
A8: 000014 | B8: REFAQUIN CREAM 15 G | C8: =IF(B8=D8,1,0) -> 1 | D8: REFAQUIN CREAM 15 G | E8: =VLOOKUP(D8,'kode internal'!$B$1:$D$4717,2,FALSE) -> 30R038 | F8: 0 | G8: 60 | H8: =VLOOKUP(D8,'kode internal'!$B$1:$E$4717,4,FALSE) -> 0 | I8: =VLOOKUP(D8,'kode internal'!$B$1:$F$4717,5,FALSE) -> 60
A9: 000015 | B9: GLYCORE CREAM 10% 10 G | C9: =IF(B9=D9,1,0) -> 1 | D9: GLYCORE CREAM 10% 10 G | E9: =VLOOKUP(D9,'kode internal'!$B$1:$D$4717,2,FALSE) -> 30G017 | F9: 0 | G9: 49 | H9: =VLOOKUP(D9,'kode internal'!$B$1:$E$4717,4,FALSE) -> 0 | I9: =VLOOKUP(D9,'kode internal'!$B$1:$F$4717,5,FALSE) -> 49
A10: 000016 | B10: BEAUTY FACIAL WASH OILY SKIN 100 ML | C10: =IF(B10=D10,1,0) -> 1 | D10: BEAUTY FACIAL WASH OILY SKIN 100 ML | E10: =VLOOKUP(D10,'kode internal'!$B$1:$D$4717,2,FALSE) -> 30B037 | F10: 12 | G10: 60 | H10: =VLOOKUP(D10,'kode internal'!$B$1:$E$4717,4,FALSE) -> 12 | I10: =VLOOKUP(D10,'kode internal'!$B$1:$F$4717,5,FALSE) -> 60
A11: 000017 | B11: REVIDERM CREAM 0,02% 15G | C11: =IF(B11=D11,1,0) -> 1 | D11: REVIDERM CREAM 0,02% 15G | E11: =VLOOKUP(D11,'kode internal'!$B$1:$D$4717,2,FALSE) -> 30R040 | F11: 3 | G11: 7 | H11: =VLOOKUP(D11,'kode internal'!$B$1:$E$4717,4,FALSE) -> 3 | I11: =VLOOKUP(D11,'kode internal'!$B$1:$F$4717,5,FALSE) -> 7
A12: 000018 | B12: MELANOX FORTE CREAM 4% 15G | C12: =IF(B12=D12,1,0) -> 1 | D12: MELANOX FORTE CREAM 4% 15G | E12: =VLOOKUP(D12,'kode internal'!$B$1:$D$4717,2,FALSE) -> 30M027 | F12: 10 | G12: 10 | H12: =VLOOKUP(D12,'kode internal'!$B$1:$E$4717,4,FALSE) -> 10 | I12: =VLOOKUP(D12,'kode internal'!$B$1:$F$4717,5,FALSE) -> 10
A13: 000019 | B13: BENZOLAC CL GEL 10 G | C13: =IF(B13=D13,1,0) -> 1 | D13: BENZOLAC CL GEL 10 G | E13: =VLOOKUP(D13,'kode internal'!$B$1:$D$4717,2,FALSE) -> 30B035 | F13: 3 | G13: 5 | H13: =VLOOKUP(D13,'kode internal'!$B$1:$E$4717,4,FALSE) -> 3 | I13: =VLOOKUP(D13,'kode internal'!$B$1:$F$4717,5,FALSE) -> 5
... A107: 000124 | B107: KETOKONAZOL KRIM 2% 5 G | C107: =IF(B107=D107,1,0) -> 1 | D107: KETOKONAZOL KRIM 2% 5 G | E107: =VLOOKUP(D107,'kode internal'!$B$1:$D$4717,2,FALSE) -> 30K021 | F107: 0 | G107: 20 | H107: =VLOOKUP(D107,'kode internal'!$B$1:$E$4717,4,FALSE) -> 0 | I107: =VLOOKUP(D107,'kode internal'!$B$1:$F$4717,5,FALSE) -> 20

Sheet alat obat kontrasepsi
B1: NAMA SAKTI | C1: =IF(B1=D1,1,0) -> 0 | D1: NAMA INVENTORI | E1: KODE INTERNAL | F1: SALDO | G1: PENGADAAN | H1: SALDO INV | I1: PENGADAAN INV
A2: 000006 | B2: PERFUSOR SYRINGE 50 ml | C2: =IF(B2=D2,1,0) -> 1 | D2: PERFUSOR SYRINGE 50 ml | E2: =VLOOKUP(B2,'kode internal'!$B$1:$D$4717,2,FALSE) -> 80P002 | F2: 0 | G2: 31900 | H2: =VLOOKUP(D2,'kode internal'!$B$1:$E$4717,4,FALSE) -> 4088 | I2: =VLOOKUP(D2,'kode internal'!$B$1:$F$4717,5,FALSE) -> 31900
A3: 000008 | B3: FEEDING TUBE FR 5 | C3: =IF(B3=D3,1,0) -> 1 | D3: FEEDING TUBE FR 5 | E3: =VLOOKUP(B3,'kode internal'!$B$1:$D$4717,2,FALSE) -> 80F006 | F3: 10 | G3: 50 | H3: =VLOOKUP(D3,'kode internal'!$B$1:$E$4717,4,FALSE) -> 10 | I3: =VLOOKUP(D3,'kode internal'!$B$1:$F$4717,5,FALSE) -> 50
A4: 000010 | B4: NEEDLE NO 25 | C4: =IF(B4=D4,1,0) -> 1 | D4: NEEDLE NO 25 | E4: =VLOOKUP(B4,'kode internal'!$B$1:$D$4717,2,FALSE) -> 80N014 | F4: 1 | G4: 0 | H4: =VLOOKUP(D4,'kode internal'!$B$1:$E$4717,4,FALSE) -> 1 | I4: =VLOOKUP(D4,'kode internal'!$B$1:$F$4717,5,FALSE) -> 0
A5: 000012 | B5: LONGARM POLYAXIAL SCREW 55-65 X 4045 | C5: =IF(B5=D5,1,0) -> 1 | D5: LONGARM POLYAXIAL SCREW 55-65 X 4045 | E5: =VLOOKUP(B5,'kode internal'!$B$1:$D$4717,2,FALSE) -> 42L133 | F5: 0 | G5: 27 | H5: =VLOOKUP(D5,'kode internal'!$B$1:$E$4717,4,FALSE) -> 0 | I5: =VLOOKUP(D5,'kode internal'!$B$1:$F$4717,5,FALSE) -> 27
A6: 000013 | B6: LONGARM MONOAXIAL SCREW 55-65 X 4045 | C6: =IF(B6=D6,1,0) -> 1 | D6: LONGARM MONOAXIAL SCREW 55-65 X 4045 | E6: =VLOOKUP(B6,'kode internal'!$B$1:$D$4717,2,FALSE) -> 42L115 | F6: 0 | G6: 10 | H6: =VLOOKUP(D6,'kode internal'!$B$1:$E$4717,4,FALSE) -> 0 | I6: =VLOOKUP(D6,'kode internal'!$B$1:$F$4717,5,FALSE) -> 10
A7: 000014 | B7: KYPHOPLASTY | C7: =IF(B7=D7,1,0) -> 1 | D7: KYPHOPLASTY | E7: =VLOOKUP(B7,'kode internal'!$B$1:$D$4717,2,FALSE) -> 42K075 | F7: 0 | G7: 1 | H7: =VLOOKUP(D7,'kode internal'!$B$1:$E$4717,4,FALSE) -> 0 | I7: =VLOOKUP(D7,'kode internal'!$B$1:$F$4717,5,FALSE) -> 1
A8: 000016 | B8: NEOGEN FEMORAL NAIL 9.5-12 X 360-440 MM (R/L) | C8: =IF(B8=D8,1,0) -> 1 | D8: NEOGEN FEMORAL NAIL 9.5-12 X 360-440 MM (R/L) | E8: =VLOOKUP(B8,'kode internal'!$B$1:$D$4717,2,FALSE) -> 42N041 | F8: 0 | G8: 5 | H8: =VLOOKUP(D8,'kode internal'!$B$1:$E$4717,4,FALSE) -> 0 | I8: =VLOOKUP(D8,'kode internal'!$B$1:$F$4717,5,FALSE) -> 5
A9: 000017 | B9: K-WIRE THREADED 1.2 * 150 | C9: =IF(B9=D9,1,0) -> 1 | D9: K-WIRE THREADED 1.2 * 150 | E9: =VLOOKUP(B9,'kode internal'!$B$1:$D$4717,2,FALSE) -> 42K034 | F9: 0 | G9: 2 | H9: =VLOOKUP(D9,'kode internal'!$B$1:$E$4717,4,FALSE) -> 0 | I9: =VLOOKUP(D9,'kode internal'!$B$1:$F$4717,5,FALSE) -> 2
A10: 000018 | B10: POSTERIOR AUGMENT | C10: =IF(B10=D10,1,0) -> 1 | D10: POSTERIOR AUGMENT | E10: =VLOOKUP(B10,'kode internal'!$B$1:$D$4717,2,FALSE) -> #N/A | F10: 0 | G10: 1 | H10: =VLOOKUP(D10,'kode internal'!$B$1:$E$4717,4,FALSE) -> #N/A | I10: =VLOOKUP(D10,'kode internal'!$B$1:$F$4717,5,FALSE) -> #N/A
A11: 000019 | B11: REDAX DRENTECH COMPACT (10105PX) | C11: =IF(B11=D11,1,0) -> 1 | D11: REDAX DRENTECH COMPACT (10105PX) | E11: =VLOOKUP(B11,'kode internal'!$B$1:$D$4717,2,FALSE) -> 80R052 | F11: 6 | G11: 20 | H11: =VLOOKUP(D11,'kode internal'!$B$1:$E$4717,4,FALSE) -> 6 | I11: =VLOOKUP(D11,'kode internal'!$B$1:$F$4717,5,FALSE) -> 20
A12: 000020 | B12: FERRULE FOR CABLE | C12: =IF(B12=D12,1,0) -> 1 | D12: FERRULE FOR CABLE | E12: =VLOOKUP(B12,'kode internal'!$B$1:$D$4717,2,FALSE) -> 42F028 | F12: 0 | G12: 3 | H12: =VLOOKUP(D12,'kode internal'!$B$1:$E$4717,4,FALSE) -> 0 | I12: =VLOOKUP(D12,'kode internal'!$B$1:$F$4717,5,FALSE) -> 3
A13: 000021 | B13: CORTEX SCREW 4.5 X 28MM | C13: =IF(B13=D13,1,0) -> 1 | D13: CORTEX SCREW 4.5 X 28MM | E13: =VLOOKUP(B13,'kode internal'!$B$1:$D$4717,2,FALSE) -> 42C097 | F13: 0 | G13: 1 | H13: =VLOOKUP(D13,'kode internal'!$B$1:$E$4717,4,FALSE) -> 0 | I13: =VLOOKUP(D13,'kode internal'!$B$1:$F$4717,5,FALSE) -> 1
... A760: 001109 | B760: LOCKING FULLY CANCELLOUS SCREW 3.5 12-50 MM,TI | C760: =IF(B760=D760,1,0) -> 1 | D760: LOCKING FULLY CANCELLOUS SCREW 3.5 12-50 MM,TI | E760: =VLOOKUP(B760,'kode internal'!$B$1:$D$4717,2,FALSE) -> 42L782 | F760: 0 | G760: 3 | H760: =VLOOKUP(D760,'kode internal'!$B$1:$E$4717,4,FALSE) -> 0 | I760: =VLOOKUP(D760,'kode internal'!$B$1:$F$4717,5,FALSE) -> 3

Sheet non alat obat kontrasepsi
B1: NAMA SAKTI | C1: =IF(B1=D1,1,0) -> 0 | D1: NAMA INVENTORI | E1: KODE INTERNAL | F1: SALDO | G1: PENGADAAN | H1: SALDO INV | I1: PENGADAAN INV
A2: 000001 | B2: NON ALAT/OBAT KONTRASEPSI | C2: =IF(B2=D2,1,0) -> 1 | D2: NON ALAT/OBAT KONTRASEPSI | E2: =VLOOKUP(B2,'kode internal'!$B$1:$D$4717,2,FALSE) -> #N/A | F2: 0 | G2: 2 | H2: =VLOOKUP(D2,'kode internal'!$B$1:$E$4717,4,FALSE) -> #N/A | I2: =VLOOKUP(D2,'kode internal'!$B$1:$F$4717,5,FALSE) -> #N/A
A3: 000002 | B3: ENDURITY CORE DR PM2162 | C3: =IF(B3=D3,1,0) -> 1 | D3: ENDURITY CORE DR PM2162 | E3: =VLOOKUP(B3,'kode internal'!$B$1:$D$4717,2,FALSE) -> 81E074 | F3: 0 | G3: 1 | H3: =VLOOKUP(D3,'kode internal'!$B$1:$E$4717,4,FALSE) -> 0 | I3: =VLOOKUP(D3,'kode internal'!$B$1:$F$4717,5,FALSE) -> 1

Sheet obat lainnya
B1: NAMA SAKTI | C1: =IF(B1=D1,1,0) -> 0 | D1: NAMA INVENTORI | E1: KODE INTERNAL | F1: SALDO | G1: PENGADAAN | H1: SALDO INV | I1: PENGADAAN INV
A2: 000002 | B2: MEDIGRIP PF STERILE SURGICAL GLOVES SIZE 7.5 | C2: =IF(B2=D2,1,0) -> 1 | D2: MEDIGRIP PF STERILE SURGICAL GLOVES SIZE 7.5 | E2: =VLOOKUP(B2,'kode internal'!$B$1:$D$4717,2,FALSE) -> 80M224 | F2: 0 | G2: 10500 | H2: =VLOOKUP(D2,'kode internal'!$B$1:$E$4717,4,FALSE) -> 3903 | I2: =VLOOKUP(D2,'kode internal'!$B$1:$F$4717,5,FALSE) -> 16750
A3: 000007 | B3: UF-FLUOROCELL CR 29ML AG792864 | C3: =IF(B3=D3,1,0) -> 1 | D3: UF-FLUOROCELL CR 29ML AG792864 | E3: =VLOOKUP(B3,'kode internal'!$B$1:$D$4717,2,FALSE) -> 15U019 | F3: 0 | G3: 10 | H3: =VLOOKUP(D3,'kode internal'!$B$1:$E$4717,4,FALSE) -> 1 | I3: =VLOOKUP(D3,'kode internal'!$B$1:$F$4717,5,FALSE) -> 12
A4: 000008 | B4: UF-FLUOROCELL SF 29ML CE919553 | C4: =IF(B4=D4,1,0) -> 1 | D4: UF-FLUOROCELL SF 29ML CE919553 | E4: =VLOOKUP(B4,'kode internal'!$B$1:$D$4717,2,FALSE) -> 15U018 | F4: 0 | G4: 11 | H4: =VLOOKUP(D4,'kode internal'!$B$1:$E$4717,4,FALSE) -> 1 | I4: =VLOOKUP(D4,'kode internal'!$B$1:$F$4717,5,FALSE) -> 13
A5: 000009 | B5: UF-CELLPACK CR 2.1L CB505392 | C5: =IF(B5=D5,1,0) -> 1 | D5: UF-CELLPACK CR 2.1L CB505392 | E5: =VLOOKUP(B5,'kode internal'!$B$1:$D$4717,2,FALSE) -> 15U017 | F5: 0 | G5: 9 | H5: =VLOOKUP(D5,'kode internal'!$B$1:$E$4717,4,FALSE) -> 1 | I5: =VLOOKUP(D5,'kode internal'!$B$1:$F$4717,5,FALSE) -> 13
A6: 000010 | B6: UF-CELLPACK SF 2.1L CE604532 | C6: =IF(B6=D6,1,0) -> 1 | D6: UF-CELLPACK SF 2.1L CE604532 | E6: =VLOOKUP(B6,'kode internal'!$B$1:$D$4717,2,FALSE) -> 15U016.1 | F6: 0 | G6: 9 | H6: =VLOOKUP(D6,'kode internal'!$B$1:$E$4717,4,FALSE) -> 1 | I6: =VLOOKUP(D6,'kode internal'!$B$1:$F$4717,5,FALSE) -> 13
A7: 000011 | B7: TESTPOINT HEMATOLOGI CONTROL LOW 1x4mL 10330063V | C7: =IF(B7=D7,1,0) -> 1 | D7: TESTPOINT HEMATOLOGI CONTROL LOW 1x4mL 10330063V | E7: =VLOOKUP(B7,'kode internal'!$B$1:$D$4717,2,FALSE) -> 15T056 | F7: 0 | G7: 46 | H7: =VLOOKUP(D7,'kode internal'!$B$1:$E$4717,4,FALSE) -> 0 | I7: =VLOOKUP(D7,'kode internal'!$B$1:$F$4717,5,FALSE) -> 54
A8: 000013 | B8: SARS-COV-2 ANTIGEN PANBIO ABBOTT | C8: =IF(B8=D8,1,0) -> 1 | D8: SARS-COV-2 ANTIGEN PANBIO ABBOTT | E8: =VLOOKUP(B8,'kode internal'!$B$1:$D$4717,2,FALSE) -> 15S099 | F8: 0 | G8: 6000 | H8: =VLOOKUP(D8,'kode internal'!$B$1:$E$4717,4,FALSE) -> 0 | I8: =VLOOKUP(D8,'kode internal'!$B$1:$F$4717,5,FALSE) -> 6000
A9: 000016 | B9: SALMONELLA SHIGELLA AGAR (CM 99) | C9: =IF(B9=D9,1,0) -> 1 | D9: SALMONELLA SHIGELLA AGAR (CM 99) | E9: =VLOOKUP(B9,'kode internal'!$B$1:$D$4717,2,FALSE) -> 15S003 | F9: 0 | G9: 1 | H9: =VLOOKUP(D9,'kode internal'!$B$1:$E$4717,4,FALSE) -> 0 | I9: =VLOOKUP(D9,'kode internal'!$B$1:$F$4717,5,FALSE) -> 1
A10: 000017 | B10: RPR ANTIGEN TEST | C10: =IF(B10=D10,1,0) -> 1 | D10: RPR ANTIGEN TEST | E10: =VLOOKUP(B10,'kode internal'!$B$1:$D$4717,2,FALSE) -> 15R048 | F10: 0 | G10: 7 | H10: =VLOOKUP(D10,'kode internal'!$B$1:$E$4717,4,FALSE) -> 0 | I10: =VLOOKUP(D10,'kode internal'!$B$1:$F$4717,5,FALSE) -> 10
A11: 000018 | B11: PCO2 MEMBRANE CAP KIT, 3/BOX 25048 | C11: =IF(B11=D11,1,0) -> 1 | D11: PCO2 MEMBRANE CAP KIT, 3/BOX 25048 | E11: =VLOOKUP(B11,'kode internal'!$B$1:$D$4717,2,FALSE) -> 15P112 | F11: 0 | G11: 3 | H11: =VLOOKUP(D11,'kode internal'!$B$1:$E$4717,4,FALSE) -> 1 | I11: =VLOOKUP(D11,'kode internal'!$B$1:$F$4717,5,FALSE) -> 3
A12: 000020 | B12: PH ELECTRODE CONDITIONING SOLUTION, 100 ML | C12: =IF(B12=D12,1,0) -> 1 | D12: PH ELECTRODE CONDITIONING SOLUTION, 100 ML | E12: =VLOOKUP(B12,'kode internal'!$B$1:$D$4717,2,FALSE) -> 15P110 | F12: 0 | G12: 1 | H12: =VLOOKUP(D12,'kode internal'!$B$1:$E$4717,4,FALSE) -> 0 | I12: =VLOOKUP(D12,'kode internal'!$B$1:$F$4717,5,FALSE) -> 1
A13: 000021 | B13: K-TOTAL PROTEIN URINE CSF GEN.3 (TPUC3) 3333825190 | C13: =IF(B13=D13,1,0) -> 0 | D13: K-TOTAL PROTEIN URINE/CSF GEN.3 (TPUC3) 3333825190 | E13: =VLOOKUP(B13,'kode internal'!$B$1:$D$4717,2,FALSE) -> #N/A | F13: 0 | G13: 1350 | H13: =VLOOKUP(D13,'kode internal'!$B$1:$E$4717,4,FALSE) -> 300 | I13: =VLOOKUP(D13,'kode internal'!$B$1:$F$4717,5,FALSE) -> 1350
... A3099: 004316 | B3099: NAT (PROCLEIX ELITEASSAY KIT) | C3099: =IF(B3099=D3099,1,0) -> 1 | D3099: NAT (PROCLEIX ELITEASSAY KIT) | E3099: =VLOOKUP(B3099,'kode internal'!$B$1:$D$4717,2,FALSE) -> #N/A | F3099: 0 | G3099: 6000 | H3099: =VLOOKUP(D3099,'kode internal'!$B$1:$E$4717,4,FALSE) -> #N/A | I3099: =VLOOKUP(D3099,'kode internal'!$B$1:$F$4717,5,FALSE) -> #N/A

Sheet kode internal
A1: katalog_kode | B1: katalog_nama | C1: katalog_kode | D1: habisDiTW1 | E1: awal2022 | F1: pengadaan2022 | G1: pengadaanTW1 | H1: awal | I1: pengadaan | J1: prodHasil | K1: prodBahan | L1: transaksi_simgos | M1: transaksi | N1: jumlah_adj | O1: opname
A2: 10A020 | B2: ACYCLOVIR TAB 400 MG | C2: 10A020 | D2: 0 | E2: 0 | F2: =G2+I2 -> 200 | G2: 0 | H2: 0 | I2: 200 | J2: 0 | K2: 0 | L2: 443 | M2: -475 | N2: -918 | O2: 675
A3: 10A025 | B3: ADALAT OROS TAB 30 MG | C3: 10A025 | D3: 0 | E3: 17589 | F3: =G3+I3 -> 138750 | G3: 56250 | H3: 36298 | I3: 82500 | J3: 0 | K3: 0 | L3: 109119 | M3: 112911 | N3: 3792 | O3: 5887
A4: 10A043 | B4: ALLOPURINOLTAB 100 MG | C4: 10A043 | D4: 0 | E4: 0 | F4: =G4+I4 -> 28000 | G4: 0 | H4: 0 | I4: 28000 | J4: 0 | K4: 0 | L4: 10924 | M4: 27365 | N4: 16441 | O4: 635
A5: 10A044 | B5: ALLORIS TABLET 10 MG | C5: 10A044 | D5: 0 | E5: 259 | F5: =G5+I5 -> 0 | G5: 0 | H5: 131 | I5: 0 | J5: 0 | K5: 0 | L5: 130 | M5: 124 | N5: -6 | O5: 7
A6: 10A054 | B6: AMBROXOL 30 mg | C6: 10A054 | D6: 0 | E6: 24684 | F6: =G6+I6 -> 4910 | G6: 0 | H6: 19208.25 | I6: 4910 | J6: 0 | K6: 0 | L6: 9608.53 | M6: 20884.25 | N6: 11275.72 | O6: 3234
A7: 10A058 | B7: AMITRIPTYLLINE TAB 25 MG | C7: 10A058 | D7: 0 | E7: 161 | F7: =G7+I7 -> 5020 | G7: 0 | H7: 60 | I7: 5020 | J7: 0 | K7: 0 | L7: 5577.45 | M7: 2115 | N7: -3462.45 | O7: 2965
A8: 10A059 | B8: AMLODIPIN TAB 5 MG | C8: 10A059 | D8: 0 | E8: 112933 | F8: =G8+I8 -> 85600 | G8: 70500 | H8: 130273.5 | I8: 15100 | J8: 0 | K8: 0 | L8: 117995 | M8: 145309.5 | N8: 27314.5 | O8: 64
A9: 10A085 | B9: ARCALION 200 TAB | C9: 10A085 | D9: 0 | E9: 81 | F9: =G9+I9 -> 1200 | G9: 1020 | H9: 777 | I9: 180 | J9: 0 | K9: 0 | L9: 943 | M9: 957 | N9: 14 | O9: 0
A10: 10A095 | B10: ASAM FOLAT 1 MG | C10: 10A095 | D10: 1 | E10: 30983 | F10: =G10+I10 -> 0 | G10: 0 | H10: 0 | I10: 0 | J10: 0 | K10: 0 | L10: 50176 | M10: 0 | N10: -50176 | O10: 0
A11: 10A096 | B11: ATORVASTATIN TAB 20MG | C11: 10A096 | D11: 0 | E11: 0 | F11: =G11+I11 -> 60000 | G11: 0 | H11: 0 | I11: 60000 | J11: 0 | K11: 0 | L11: 13022 | M11: 40760 | N11: 27738 | O11: 19240
A12: 10A097.1 | B12: ARIPIPRAZOLE TAB 5MG | C12: 10A097.1 | D12: 0 | E12: 0 | F12: =G12+I12 -> 700 | G12: 0 | H12: 0 | I12: 700 | J12: 0 | K12: 0 | L12: 86 | M12: 155 | N12: 69 | O12: 545
A13: 10A098 | B13: ASCARDIA TABLET SALUT ENTERIK 80 MG | C13: 10A098 | D13: 0 | E13: 265 | F13: =G13+I13 -> 0 | G13: 0 | H13: 1 | I13: 0 | J13: 0 | K13: 0 | L13: 197 | M13: 1 | N13: -196 | O13: 0
... A4701: PFA047 | B4701: ALKOHOL 96% 100 ML | C4701: PFA047 | D4701: 0 | E4701: 0 | F4701: =G4701+I4701 -> 0 | G4701: 0 | H4701: 0 | I4701: 0 | J4701: 1 | K4701: 1 | L4701: 1 | M4701: 0 | N4701: -1 | O4701: 0
A4702: PFA048 | C4702: PFA048 | D4702: 0 | E4702: 0 | F4702: =G4702+I4702 -> 0 | G4702: 0 | H4702: 0 | I4702: 0 | J4702: 6 | K4702: 0 | L4702: 0 | M4702: 1 | N4702: 1 | O4702: 5
A4703: PFB006 | B4703: BICARBONAT NATRICUS 500 MG | C4703: PFB006 | D4703: 0 | E4703: 2289 | F4703: =G4703+I4703 -> 0 | G4703: 0 | H4703: 10276 | I4703: 0 | J4703: 120200 | K4703: 0 | L4703: 98276.2 | M4703: 130476 | N4703: 32199.8 | O4703: 0
A4704: PFC001 | B4704: CARBOL GLYCERIN 10 % | C4704: PFC001 | D4704: 1 | E4704: 0.4 | F4704: =G4704+I4704 -> 0 | G4704: 0 | H4704: 0 | I4704: 0 | J4704: 0 | K4704: 0 | L4704: 0 | M4704: 0 | N4704: 0 | O4704: 0
A4705: PFC005 | B4705: CARBOL GLYCERIN 20 ML | C4705: PFC005 | D4705: 0 | E4705: 10 | F4705: =G4705+I4705 -> 0 | G4705: 0 | H4705: 2 | I4705: 0 | J4705: 0 | K4705: 0 | L4705: 2 | M4705: 2 | N4705: 0 | O4705: 0
A4706: PFC006 | B4706: CALADINE LOTION 95 ML + MENTHOL 0,5% | C4706: PFC006 | D4706: 1 | E4706: 0 | F4706: =G4706+I4706 -> 2 | G4706: 2 | H4706: 0 | I4706: 0 | J4706: 0 | K4706: 0 | L4706: 0 | M4706: 0 | N4706: 0 | O4706: 0
A4707: PFD001 | C4707: PFD001 | D4707: 0 | E4707: 0 | F4707: =G4707+I4707 -> 0 | G4707: 0 | H4707: 0 | I4707: 0 | J4707: 5 | K4707: 0 | L4707: 0 | M4707: -1 | N4707: -1 | O4707: 6
A4708: PFF | B4708: FORMALIN 10% LITER | C4708: PFF | D4708: 0 | E4708: 2 | F4708: =G4708+I4708 -> 0 | G4708: 0 | H4708: 0 | I4708: 0 | J4708: 38 | K4708: 0 | L4708: 0 | M4708: 33 | N4708: 33 | O4708: 5
A4709: PFH046 | B4709: H2O2 3% 50 ml | C4709: PFH046 | D4709: 0 | E4709: 2 | F4709: =G4709+I4709 -> 0 | G4709: 0 | H4709: 4 | I4709: 0 | J4709: 110 | K4709: 0 | L4709: 62 | M4709: 72 | N4709: 10 | O4709: 42
A4710: PFH051 | B4710: HANDRUB 500 ML | C4710: PFH051 | D4710: 0 | E4710: 0 | F4710: =G4710+I4710 -> 0 | G4710: 0 | H4710: 177 | I4710: 0 | J4710: 11547 | K4710: 0 | L4710: 14 | M4710: 11713 | N4710: 11699 | O4710: 11
A4711: PFH053 | B4711: HYPO CHLORIDE 0,5% 100 ML | C4711: PFH053 | D4711: 1 | E4711: 2 | F4711: =G4711+I4711 -> 0 | G4711: 0 | H4711: 0 | I4711: 0 | J4711: 0 | K4711: 0 | L4711: 0 | M4711: 0 | N4711: 0 | O4711: 0
A4712: PFL002 | B4712: LYSOL 1:5 L | C4712: PFL002 | D4712: 0 | E4712: 0 | F4712: =G4712+I4712 -> 0 | G4712: 0 | H4712: 0 | I4712: 0 | J4712: 75 | K4712: 0 | L4712: 0 | M4712: 75 | N4712: 75 | O4712: 0
A4713: PFM004 | B4713: MANTOX TEST 0,15 ML | C4713: PFM004 | D4713: 1 | E4713: 7 | F4713: =G4713+I4713 -> 0 | G4713: 0 | H4713: 0 | I4713: 0 | J4713: 0 | K4713: 0 | L4713: 0 | M4713: 0 | N4713: 0 | O4713: 0
A4714: PFN005 | B4714: NACL 500 MG | C4714: PFN005 | D4714: 0 | E4714: 0 | F4714: =G4714+I4714 -> 0 | G4714: 0 | H4714: 0 | I4714: 0 | J4714: 7900 | K4714: 0 | L4714: 6942 | M4714: 7053 | N4714: 111 | O4714: 847
A4715: PFV002 | B4715: VASELIN 50 GRAM | C4715: PFV002 | D4715: 0 | E4715: 21.3 | F4715: =G4715+I4715 -> 0 | G4715: 0 | H4715: 28.97 | I4715: 0 | J4715: 283 | K4715: 0 | L4715: 274.07 | M4715: 256.97 | N4715: -17.1 | O4715: 55
A4716: PFV003 | B4716: VIOREX 4% 100ML | C4716: PFV003 | D4716: 0 | E4716: 0 | F4716: =G4716+I4716 -> 0 | G4716: 0 | H4716: 7 | I4716: 0 | J4716: 111 | K4716: 0 | L4716: 90.7 | M4716: 103.7 | N4716: 13 | O4716: 14.3
A4717: PFV004 | B4717: VIOREX 4% 200ML | C4717: PFV004 | D4717: 0 | E4717: 0 | F4717: =G4717+I4717 -> 0 | G4717: 0 | H4717: 3 | I4717: 0 | J4717: 40 | K4717: 0 | L4717: 35 | M4717: 24 | N4717: -11 | O4717: 19
