Workbook

Sheet KD_SATKER
A3: NO | B3: NAMA_UNIT_KERJA | C3: KD_UNIT | D3: NAMA_UNIT_BARU | E3: KD_UNIT_BARU | F3: DIREKTORAT | G3: SATUAN KERJA | H3: KD_UNIT_LAMA
A4: 1 | F4: Direktorat Utama | G4: Direktur Utama
A5: =A4+1 -> 2 | F5: Direktorat Pelayanan Medik, Keperawatan, dan Penunjang | G5: Direktur Pelayanan Medik, Keperawatan, dan Penunjang
F6: Direktorat SDM, Pendidikan dan Penelitian | G6: Direktur SDM, Pendidikan dan Penelitian
A7: =A5+1 -> 3 | F7: Direktorat Keuangan dan Barang Milik Negara | G7: Direktur Keuangan dan Barang Milik Negara
A8: =A7+1 -> 4 | F8: Direktorat Perencanaan, Organisasi, dan Umum | G8: Direktur Perencanaan, Organisasi, dan Umum
A9: =#REF!+1 -> #REF! | F9: Direktorat Utama | G9: Komite Koordinasi Pendidikan
A10: =A9+1 -> #REF! | F10: Direktorat Utama | G10: Komite Mutu Rumah Sakit
A11: =A10+1 -> #REF! | F11: Direktorat Utama | G11: Komite Pencegahan & Pengendalian Infeksi
A12: =A11+1 -> #REF! | F12: Direktorat Utama | G12: Komite Penelitian
A13: =A12+1 -> #REF! | F13: Direktorat Utama | G13: Komite Keperawatan
A14: =A13+1 -> #REF! | F14: Direktorat Utama | G14: Komite Tenaga Kesehatan Lain
A15: =A14+1 -> #REF! | F15: Direktorat Utama | G15: Komite Medik
A16: =A15+1 -> #REF! | F16: Direktorat Utama | G16: Satuan Pemeriksaan Intern
A17: =A16+1 -> #REF! | F17: Direktorat Pelayanan Medik, Keperawatan, dan Penunjang | G17: Kelompok Substansi Pelayanan Medik
A18: =A17+1 -> #REF! | F18: Direktorat Pelayanan Medik, Keperawatan, dan Penunjang | G18: Kelompok Substansi Pelayanan Keperawatan
A19: =A18+1 -> #REF! | F19: Direktorat Pelayanan Medik, Keperawatan, dan Penunjang | G19: Kelompok Substansi Pelayanan Penunjang
A20: =A19+1 -> #REF! | F20: Direktorat Pelayanan Medik, Keperawatan, dan Penunjang | G20: Instalasi Bedah Sentral
A21: =A20+1 -> #REF! | F21: Direktorat Pelayanan Medik, Keperawatan, dan Penunjang | G21: Instalasi Farmasi
... A70: =A69+1 -> #REF! | F70: Direktorat SDM, Pendidikan dan Penelitian | G70: Instalasi Pengelolaan Inovasi dan Kekayaan Intelektual

Sheet Laporan
F1: NO. | G1: JENIS TENAGA | H1: ASN | J1: NON ASN | L1: TOTAL
A2: NO. | B2: URAIAN | C2: JUMLAH | H2: PNS/CPNS | I2: PPPK | J2: BLU | K2: PTT
A3: 1 | B3: TENAGA MEDIS | C3: =SUM(C4:C8) -> 292 | F3: I. | G3: TENAGA MEDIS | H3: =COUNTIFS(Konsep!$AD$2:$AD$2322,G3,Konsep!$K$2:$K$2322,"PNS")+COUNTIFS(Konsep!$AD$2:$AD$2322,G3,Konsep!$K$2:$K$2322,"CPNS") -> 225 | I3: =COUNTIFS(Konsep!$AD$2:$AD$2322,G3,Konsep!$K$2:$K$2322,"PPPK") -> 6 | J3: =COUNTIFS(Konsep!$AD$2:$AD$2322,G3,Konsep!$K$2:$K$2322,"Pegawai Tetap BLU") -> 15 | K3: =COUNTIFS(Konsep!$AD$2:$AD$2322,G3,Konsep!$K$2:$K$2322,"Pegawai Tidak Tetap") -> 46 | L3: =SUM(H3:K3) -> 292
B4: DOKTER UMUM | C4: =COUNTIF(Konsep!$AC$3:$AC$2322,Laporan!B4) -> 60 | F4: II. | G4: PERAWAT | H4: =COUNTIFS(Konsep!$AD$2:$AD$2322,G4,Konsep!$K$2:$K$2322,"PNS")+COUNTIFS(Konsep!$AD$2:$AD$2322,G4,Konsep!$K$2:$K$2322,"CPNS") -> 637 | I4: =COUNTIFS(Konsep!$AD$2:$AD$2322,G4,Konsep!$K$2:$K$2322,"PPPK") -> 8 | J4: =COUNTIFS(Konsep!$AD$2:$AD$2322,G4,Konsep!$K$2:$K$2322,"Pegawai Tetap BLU") -> 187 | K4: =COUNTIFS(Konsep!$AD$2:$AD$2322,G4,Konsep!$K$2:$K$2322,"Pegawai Tidak Tetap") -> 121 | L4: =SUM(H4:K4) -> 953
B5: DOKTER SPESIALIS | C5: =COUNTIF(Konsep!$AC$3:$AC$2322,Laporan!B5) -> 125 | F5: III. | G5: BIDAN | H5: =COUNTIFS(Konsep!$AD$2:$AD$2322,G5,Konsep!$K$2:$K$2322,"PNS")+COUNTIFS(Konsep!$AD$2:$AD$2322,G5,Konsep!$K$2:$K$2322,"CPNS") -> 35 | I5: =COUNTIFS(Konsep!$AD$2:$AD$2322,G5,Konsep!$K$2:$K$2322,"PPPK") -> 0 | J5: =COUNTIFS(Konsep!$AD$2:$AD$2322,G5,Konsep!$K$2:$K$2322,"Pegawai Tetap BLU") -> 9 | K5: =COUNTIFS(Konsep!$AD$2:$AD$2322,G5,Konsep!$K$2:$K$2322,"Pegawai Tidak Tetap") -> 3 | L5: =SUM(H5:K5) -> 47
B6: DOKTER SPESIALIS KONSULTAN | C6: =COUNTIF(Konsep!$AC$3:$AC$2322,Laporan!B6) -> 95 | F6: IV. | G6: TENAGA KESEHATAN LAIN | H6: =COUNTIFS(Konsep!$AD$2:$AD$2322,G6,Konsep!$K$2:$K$2322,"PNS")+COUNTIFS(Konsep!$AD$2:$AD$2322,G6,Konsep!$K$2:$K$2322,"CPNS") -> 295 | I6: =COUNTIFS(Konsep!$AD$2:$AD$2322,G6,Konsep!$K$2:$K$2322,"PPPK") -> 5 | J6: =COUNTIFS(Konsep!$AD$2:$AD$2322,G6,Konsep!$K$2:$K$2322,"Pegawai Tetap BLU") -> 50 | K6: =COUNTIFS(Konsep!$AD$2:$AD$2322,G6,Konsep!$K$2:$K$2322,"Pegawai Tidak Tetap") -> 77 | L6: =SUM(H6:K6) -> 427
B7: DOKTER GIGI UMUM | C7: =COUNTIF(Konsep!$AC$3:$AC$2322,Laporan!B7) -> 1 | F7: V. | G7: NON MEDIS / ADMINISTRASI | H7: =COUNTIFS(Konsep!$AD$2:$AD$2322,G7,Konsep!$K$2:$K$2322,"PNS")+COUNTIFS(Konsep!$AD$2:$AD$2322,G7,Konsep!$K$2:$K$2322,"CPNS") -> 374 | I7: =COUNTIFS(Konsep!$AD$2:$AD$2322,G7,Konsep!$K$2:$K$2322,"PPPK") -> 0 | J7: =COUNTIFS(Konsep!$AD$2:$AD$2322,G7,Konsep!$K$2:$K$2322,"Pegawai Tetap BLU") -> 160 | K7: =COUNTIFS(Konsep!$AD$2:$AD$2322,G7,Konsep!$K$2:$K$2322,"Pegawai Tidak Tetap") -> 67 | L7: =SUM(H7:K7) -> 601
B8: DOKTER GIGI SPESIALIS | C8: =COUNTIF(Konsep!$AC$3:$AC$2322,Laporan!B8) -> 11 | F8: JUMLAH | H8: =SUM(H3:H7) -> 1566 | I8: =SUM(I3:I7) -> 19 | J8: =SUM(J3:J7) -> 421 | K8: =SUM(K3:K7) -> 314 | L8: =SUM(L3:L7) -> 2320
A9: 2 | B9: TENAGA KEPERAWATAN | C9: =COUNTIF(Konsep!$AC$3:$AC$2322,"PERAWAT") -> 953 | F9: TOTAL | H9: =SUM(H8:I8) -> 1585 | J9: =SUM(J8:K8) -> 735
A10: 3 | B10: TENAGA KEBIDANAN | C10: =COUNTIF(Konsep!$AC$3:$AC$2322,"BIDAN") -> 47
A11: 4 | B11: TENAGA KESEHATAN LAIN | C11: =COUNTIF(Konsep!$AC$3:$AC$2322,Laporan!B11) -> 427
B12: ( Apoteker, Fisioterapi, Gizi, Teknis Elektromedik, Teknik Radiologi, dll) | F12: ASN | G12: =H9 -> 1585
A13: 5 | B13: TENAGA NON MEDIS | C13: =COUNTIF(Konsep!$AC$3:$AC$2322,Laporan!B13) -> 601 | F13: NON ASN | G13: =J9 -> 735
B14: ( Hukum, Komputer, Keuangan, Kesehatan Masyarakat, Manajemen, Akuntansi, dll)
B15: TOTAL | C15: =SUM(C4:C14) -> 2320
A17: PNS/CPNS | B17: PPPK | C17: BLU | D17: PTT
A18: =H8 -> 1566 | B18: =I8 -> 19 | C18: =J8 -> 421 | D18: =K8 -> 314
J23: Tenaga Kesehatan | K23: =SUM(C4:C11) -> 1719
J24: Tenaga Non Kesehatan | K24: =C13 -> 601

Sheet Konsep
A1: Data Konsep Per 06 April 2023 | BH1: =+BH:ANN -> 0 | DP1: =COUNTA(DP3:DP2229) -> 2227
A2: NO | B2: NAMA | C2: NIP LAMA | D2: NIP | E2: updt | F2: JENJANG | G2: BUP | H2: PERKIRAAN PENSIUN | I2: NIP SIMKA | J2: STATUS KEPEGAWAIAN | K2: STATUS PEGAWAI | L2: STATUS PEGAWAI SUB | M2: JENIS KELAMIN | N2: GOL | O2: KD GOL | P2: TMT GOL | Q2: NOMOR SK GOLONGAN/ SK TERAKHIR | R2: MASA KERJA THN | S2: MASA KERJA BLN | T2: TGL PERPANJANGAN KONTRAK | U2: NO. BUNDEL | V2: NO. KARPEG | W2: TEMPAT LAHIR | X2: TGL LAHIR | Y2: USIA | Z2: KATEGORI USIA | AA2: TMT PENSIUN | AB2: PENDIDIKAN | AC2: KHUSUS LAP BULANAN1 | AD2: KHUSUS LAP BULANAN2 | AE2: KHUSUS LAP KSM | AF2: KD PENDIDIKAN | AG2: KD PENDIDIKAN TAMBAHAN | AH2: KD JENIS TENAGA | AI2: KD TINGKAT PENDIDIKAN | AJ2: NO INDUK MAHASISWA | AK2: NOMOR IJAZAH | AL2: Tgl Ijazah | AM2: INSTITUSI PENDIDIKAN | AN2: SUB SPESIALIS | AO2: TGL LULUS | AP2: SATUAN KERJA | AQ2: TMT Tempat Baru | AR2: JENIS TENAGA UTK SERAGAM | AS2: JENIS TENAGA | AT2: UPDATE NOTA DINAS | AU2: LEVEL JABATAN | AV2: JABATAN ( INTERN & STRUKTURAL ) | AW2: TMT JABATAN | AX2: TMT MASA BERAKHIR JABATAN | AY2: DIREKTORAT | AZ2: KD_UNIT_BARU | BA2: UNIT KERJA BARU | BB2: UNIT KERJA SUB | BC2: UNIT KERJA TERKECIL | BD2: KD_JABATAN | BE2: KD_JBT1 | BF2: JABATAN INTERNAL | BG2: JABATAN INTERNAL TAMBAHAN_1 | BH2: NM JABATAN INTERNAL TAMBAHAN_1 | BI2: KD_JABFUNG | BJ2: JABATAN SIMKA DEPKES | BK2: GOL_SIMKA | BL2: KD_JBTN_SIMKA | BM2: TMT JABATAN PLH/PLTS DARI | BN2: TMT JABATAN PLH/PLTS SAMPAI | BO2: NON FUNGSIONAL (TUNJ UMUM) | BP2: STRUKTURAL | BQ2: JABATAN FUNGSIONAL | BR2: TMT JABFUNG | BS2: ANGKA KREDIT | BT2: TMT JADI PEG CPNS | BU2: TMT PNS 100% | BV2: TMT AKTIF DI RSF | BW2: MASA KERJA RSF THN | BX2: MASA KERJA RSF BLN | BY2: TMT PEG BLU | BZ2: NO KARSU/KARIS | CA2: AGAMA | CB2: STATUS | CC2: ANAK | CD2: ISTRI/SUAMI | CE2: STATUS PAJAK | CF2: PIAGAM PENGHARGAAN 8 TH | CG2: 10 TH | CH2: 16 TH | CI2: 20 TH | CJ2: 24 TH | CK2: 30 TH | CL2: NO STR | CM2: BERLAKU S.D | CN2: MASA BERLAKU STR | CO2: NO SIP / SIK | CP2: BERLAKU S.D | CQ2: MASA BERLAKU SIP | CR2: NO ABSEN | CS2: Konfirmasi Ijasah | CT2: NO SURAT | CU2: TGL SURAT | CV2: SURAT KELUAR | CW2: INSTITUSI PENDIDIKAN | CX2: TGL SURAT | CY2: SURAT KELUAR DOKTER UMUM /DOKTER GIGI UMUM | CZ2: INSTITUSI PENDIDIKAN | DA2: TGL SURAT | DB2: KONFIRMASI STR | DC2: NO. SURAT | DD2: TGL SURAT | DE2: MASA BERLAKU | DF2: KONFIRMASI SIP | DG2: NO SURAT | DH2: MASA BERLAKU | DI2: SURAT KELUAR KONFIRMASI STR | DJ2: TGL SURAT | DK2: SURAT KELUAR KONFIRMASI SIP | DL2: TGL SURAT | DM2: NPWP | DN2: BPJS KETENAGAKERJAAN | DO2: NO KARTU KELUARGA | DP2: NIK KTP | DQ2: ALAMAT KTP | DR2: ALAMAT LAIN | DS2: NO TELEPON | DT2: E-MAIL | DU2: VAKSINASI KE | DV2: JENIS VAKSIN | DW2: SK PENGANGKATAN BYK PK | DX2: KEWENANGAN KLINIS KOMITE PK | DY2: NO SK KEWENANGAN KLINIS | DZ2: TGL SK KEWENANGAN KLINIS | EA2: TGL HABIS SK KEWENANGAN KLINIS | EB2: No. Rekam Medik | EC2: LAPORAN BIOS | ED2: STATUS MANAJERIAL | EE2: S1 | EF2: SPESIALIS 1 | EG2: SPESIALIS 2 | EH2: STATUS TUBEL/IBEL | EI2: TANGGAL MULAI KULIAH | EJ2: TANGGAL SELESAI KULIAH
A3: 1 | B3: dr. Andi Saguni, MA | C3: PNS | D3: 197201172000121001 | F3: Non Jabfung | G3: =IF(F3="Ahli Madya",60,IF(F3="Ahli Utama",65,58)) -> 58 | H3: =DATE(YEAR(X3)+G3,MONTH(X3)+1,1) -> 47515 | J3: ASN | K3: PNS | L3: PNS | M3: L | N3: IV/d | O3: 4D | P3: 01-04-2022 | R3: 23 | S3: 4 | W3: Ujung Pandang | X3: 17-01-1972 | Y3: =YEAR(NOW())-YEAR(X3) -> #VALUE! | Z3: =IF(AND(Y3>=21,Y3<=35),"21-35",IF(AND(Y3>35,Y3<=45),"36-45",IF(AND(Y3>45,Y3<=58),"46-58",IF(Y3>58,"Lebih dari 58",0)))) -> #VALUE! | AB3: Dokter Umum + S2 Perencanaan dan Kebijakan Publik | AC3: TENAGA NON MEDIS | AD3: NON MEDIS / ADMINISTRASI | AF3: MDS | AG3: A | AH3: A | AI3: S2 | AP3: Direksi | AQ3: 14-12-2021 | AR3: MANAJEMEN | AS3: MANAJEMEN | AT3: =_xlfn.IFNA(VLOOKUP(D3,'[1]5. 1 Mei 2022'!$C$7:$F$60,4,FALSE),"") | AU3: Direktur Utama | AV3: Direktur Utama | AW3: 14-12-2021 | AX3: =AW3+1903 -> 46447 | AY3: Direktorat Utama | AZ3: DIRUT | BA3: Direktur Utama | BD3: DIREKSI | BE3: MJ | BF3: Direktur Utama | BJ3: Direktur Utama | BK3: =N3 -> IV/d | BL3: II.a | BV3: 14-12-2021 | BW3: =YEAR(NOW())-YEAR(BV3) -> #VALUE! | BX3: =DATEDIF(BV3,NOW(),"YM") -> #VALUE! | CA3: Islam | CB3: Belum Menikah | DM3: 45.773.465.5-009.000 | DP3: 3275101701720010 | DS3: 081310000677 | DU3: 3 | DV3: Moderna | EC3: Tenaga Non Medis Administrasi | ED3: MANAJERIAL
A4: 2 | B4: dr. Amrizal Umran, Sp.U (K) | C4: 140338323 | D4: 196611281997031002 | F4: Ahli Madya | G4: =IF(F4="Ahli Madya",60,IF(F4="Ahli Utama",65,58)) -> 60 | H4: =DATE(YEAR(X4)+G4,MONTH(X4)+1,1) -> 46357 | J4: ASN | K4: PNS | L4: PNS | M4: L | N4: IV/b | O4: 4B | P4: 01-10-2019 | R4: 26 | S4: 0 | U4: 54 | W4: Fakfak | X4: 28-11-1966 | Y4: =YEAR(NOW())-YEAR(X4) -> #VALUE! | Z4: =IF(AND(Y4>=21,Y4<=35),"21-35",IF(AND(Y4>35,Y4<=45),"36-45",IF(AND(Y4>45,Y4<=58),"46-58",IF(Y4>58,"Lebih dari 58",0)))) -> #VALUE! | AB4: Dokter Spesialis Bedah Urologi + Konsultan Urologi Andrologi | AC4: DOKTER SPESIALIS KONSULTAN | AD4: TENAGA MEDIS | AE4: KSM Bedah | AF4: MDS | AG4: A | AH4: A | AI4: KONSULTAN | AJ4: 419818108X | AK4: 0003/Sp-FK/1/2006 | AL4: 28-11-2005 | AM4: Universitas Indonesia | AN4: Konsultan Urologi Andrologi | AP4: Direksi | AQ4: 16-01-2023 | AR4: MANAJEMEN | AS4: MANAJEMEN | AT4: =_xlfn.IFNA(VLOOKUP(D4,'[1]5. 1 Mei 2022'!$C$7:$F$60,4,FALSE),"") | AU4: Plt Direktur Pelayanan Medik, Keperawatan, dan Penunjang | AV4: Plt Direktur Pelayanan Medik, Keperawatan, dan Penunjang | AW4: 21-12-2020 // 31-07-2018 | AX4: =AW4+1903 -> #VALUE! | AY4: Direktorat Utama | AZ4: DIRMED | BA4: Direktur Pelayanan Medik, Keperawatan, dan Penunjang | BD4: DIREKSI | BE4: MJ | BF4: Plt Direktur Pelayanan Medik, Keperawatan, dan Penunjang | BI4: DR | BJ4: Dokter Pendidik Klinis Ahli Madya | BK4: =N4 -> IV/b | BL4: JFT | BP4: - | BQ4: Dokter Pendidik Klinis Ahli Madya | BR4: 01-04-2019 | BS4: 566.7050 | BT4: 01-03-1997 | BV4: 01-11-2006 | BW4: =YEAR(NOW())-YEAR(BV4) -> 17 | BX4: =DATEDIF(BV4,NOW(),"YM") -> 3 | CA4: Islam | CB4: Menikah | CC4: 1 | CD4: 1 | CE4: Menanggung | CG4: 2007 | CL4: 3111106421011025 | CM4: 28-11-2026 | CN4: 126 | CO4: 170/B.15B/31.74.06.1001.05.023.S.2.a.b/3/-1.779.3/e/2021 | CP4: 28-11-2026 | CQ4: 126 | CR4: 2008 | CS4: Benar Lulusan Sp1 FKUI // Benar lulusan Dokter Umum UI | CT4: 0 // 11089/H2.F1.D/PDP.02.01.02/2013 | CU4: 14-02-2012 // 07-10-2013 | CV4: KP.00.02/II.4/110/2012 | CW4: Dokter Spesialis Bedah Urologi UI | CX4: 18-01-2012 | CY4: KP.00.02/II.4/2728/2013 | CZ4: Dokter Umum UI | DA4: 26-07-2013 | DB4: Dicek Melalui Website KKI | DE4: 2021 | DF4: Benar SIP dokter dikeluarkan oleh UP PTSP Kec Cilandak | DG4: 210/-072.1 | DH4: 2021 | DK4: HK.02.03/VIII.2/15141/2019 | DL4: 24-10-2019 | DM4: 67.058.020.8-407.000 | DO4: 0 | DP4: 3275022811660005 | DQ4: Grand Prima Bintara Cluster D.26 Rt. 008/016 Kel. Bintara Kec. Bekasi Barat Bekasi | DS4: 08129232705 | DU4: 3 | DV4: Moderna | DY4: 3789/2022 | DZ4: 23-03-2022 | EA4: 18-02-2025 | EB4: 911913 | EC4: Dokter Spesialis | ED4: MANAJERIAL | EE4: Universitas Indonesia | EF4: Universitas Indonesia
A5: 3 | B5: Ni Ketut Rupini, SH, MARS | C5: PNS | D5: 196807241994032002 | F5: Non Jabfung | G5: =IF(F5="Ahli Madya",60,IF(F5="Ahli Utama",65,58)) -> 58 | H5: =DATE(YEAR(X5)+G5,MONTH(X5)+1,1) -> 46235 | J5: ASN | K5: PNS | L5: PNS | M5: P | N5: IV/c | O5: 4C | P5: 01-04-2018 | R5: 28 | S5: 0 | W5: Denpasar | X5: 24-07-1968 | Y5: =YEAR(NOW())-YEAR(X5) -> #VALUE! | Z5: =IF(AND(Y5>=21,Y5<=35),"21-35",IF(AND(Y5>35,Y5<=45),"36-45",IF(AND(Y5>45,Y5<=58),"46-58",IF(Y5>58,"Lebih dari 58",0)))) -> #VALUE! | AB5: Magister Administrasi Rumah Sakit | AC5: TENAGA NON MEDIS | AD5: NON MEDIS / ADMINISTRASI | AF5: NONMDS | AG5: A | AH5: A | AI5: S2 | AP5: Direksi | AQ5: 19-08-2021 | AR5: MANAJEMEN | AS5: MANAJEMEN | AT5: =_xlfn.IFNA(VLOOKUP(D5,'[1]5. 1 Mei 2022'!$C$7:$F$60,4,FALSE),"") | AU5: Direktur Keuangan dan Barang Milik Negara | AV5: Direktur Keuangan dan Barang Milik Negara | AW5: 19-08-2021 // 02-11-2022 | AX5: =AW5+1903 -> #VALUE! | AY5: Direktorat Keuangan dan Barang Milik Negara | AZ5: DIRKEU | BA5: Direktur Keuangan dan Barang Milik Negara | BD5: DIREKSI | BE5: MJ | BF5: Direktur Keuangan dan Barang Milik Negara | BG5: Pejabat Penandatanganan Surat Perintah Membayar (PP-SPM) | BH5: Plt Direktur Perencanan, Organisasi, dan Umum | BJ5: Direktur Keuangan dan Barang Milik Negara | BK5: =N5 -> IV/c | BL5: II.b | BV5: 20-08-2021 | BW5: =YEAR(NOW())-YEAR(BV5) -> #VALUE! | BX5: =DATEDIF(BV5,NOW(),"YM") -> #VALUE! | CA5: Hindu | CB5: Menikah | CD5: 1 | CR5: 1002 | DM5: 47.022.066.6-901.000 | DP5: 5104066407680001 | DQ5: Br. Bayad Kel. Kedisan Kec. Tegallalang Kab. Gianyar Bali | DS5: 081237923761 | DT5: niketutrupini@gmail.com | DU5: 3 | DV5: Moderna | EC5: Tenaga Non Medis Administrasi | ED5: MANAJERIAL
A6: 4 | B6: Dr. Dra. Vivi Lisdawati, M.Si, Apt | C6: PNS | D6: 196811181996032001 | F6: Non Jabfung | G6: =IF(F6="Ahli Madya",60,IF(F6="Ahli Utama",65,58)) -> 58 | H6: =DATE(YEAR(X6)+G6,MONTH(X6)+1,1) -> 46357 | J6: ASN | K6: PNS | L6: PNS | M6: P | N6: IV/c | O6: 4C | P6: 01-10-2020 | R6: 24 | S6: 7 | W6: Padang | X6: 18-11-1968 | Y6: =YEAR(NOW())-YEAR(X6) -> #VALUE! | Z6: =IF(AND(Y6>=21,Y6<=35),"21-35",IF(AND(Y6>35,Y6<=45),"36-45",IF(AND(Y6>45,Y6<=58),"46-58",IF(Y6>58,"Lebih dari 58",0)))) -> #VALUE! | AB6: Doktor + Magister | AC6: TENAGA NON MEDIS | AD6: NON MEDIS / ADMINISTRASI | AF6: TKL | AG6: A | AH6: A | AI6: S3 | AJ6: 0706310160 | AK6: NC.10-007669 | AL6: 09-08-2011 | AM6: Universitas Indonesia | AP6: Direksi | AQ6: 10-02-2022 | AR6: MANAJEMEN | AS6: MANAJEMEN | AT6: =_xlfn.IFNA(VLOOKUP(D6,'[1]5. 1 Mei 2022'!$C$7:$F$60,4,FALSE),"") | AU6: Direktur SDM, Pendidikan dan Penelitian | AV6: Direktur SDM, Pendidikan dan Penelitian | AW6: 10-02-2022 | AX6: =AW6+1903 -> 46505 | AY6: Direktorat SDM, Pendidikan dan Penelitian | AZ6: DIRSDM | BA6: Direktur SDM, Pendidikan dan Penelitian | BD6: DIREKSI | BE6: MJ | BF6: Direktur SDM, Pendidikan dan Penelitian | BJ6: Direktur SDM, Pendidikan, dan Penelitian | BK6: =N6 -> IV/c | BL6: II.b | BQ6: Pembebasan Sementara dari Jabatan Fungsional Peneliti Madya | BR6: 01-03-2015 | BV6: 10-02-2022 | BW6: =YEAR(NOW())-YEAR(BV6) -> 1 | BX6: =DATEDIF(BV6,NOW(),"YM") -> 6 | CA6: Islam | CB6: Menikah | CD6: 1 | CE6: Menanggung | DM6: 06.689.277.9-031.000 | DP6: 3173070308650005 | DS6: 0818953717 | EC6: Tenaga Non Medis Administrasi | ED6: MANAJERIAL
A7: 5 | B7: Ahmad Subhan, Apt, M.Si | C7: K2010061064 | D7: 197904172010121001 | F7: Ahli Madya | G7: =IF(F7="Ahli Madya",60,IF(F7="Ahli Utama",65,58)) -> 60 | H7: =DATE(YEAR(X7)+G7,MONTH(X7)+1,1) -> 50891 | J7: ASN | K7: PNS | L7: PNS | M7: L | N7: IV/a | O7: 4A | P7: 01-10-2020 | R7: 10 | S7: 0 | U7: 1740 | V7: Q 102174 | W7: Lamongan | X7: 17-04-1979 | Y7: =YEAR(NOW())-YEAR(X7) -> #VALUE! | Z7: =IF(AND(Y7>=21,Y7<=35),"21-35",IF(AND(Y7>35,Y7<=45),"36-45",IF(AND(Y7>45,Y7<=58),"46-58",IF(Y7>58,"Lebih dari 58",0)))) -> #VALUE! | AB7: S2 Farmasi Klinik | AC7: TENAGA KESEHATAN LAIN | AD7: TENAGA KESEHATAN LAIN | AF7: TKL | AG7: A | AH7: C | AI7: S2 | AJ7: 16372/PS/MFK/05 | AK7: 1089/M.Si./08 | AL7: 24-01-2008 | AM7: Universitas Gajah Mada Yogyakarta | AP7: Instalasi Pengelolaan Inovasi dan Kekayaan Intelektual | AQ7: 14-02-2022 | AR7: MANAJEMEN | AS7: MANAJEMEN | AT7: =_xlfn.IFNA(VLOOKUP(D7,'[1]5. 1 Mei 2022'!$C$7:$F$60,4,FALSE),"") | AU7: Kepala Instalasi | AV7: Kepala Instalasi Pengelolaan Inovasi dan Kekayaan Intelektual | AW7: 14-02-2022 | AX7: =AW7+1903 -> 46509 | AY7: Direktorat SDM, Pendidikan dan Penelitian | AZ7: IPIKI | BA7: Instalasi Pengelolaan Inovasi dan Kekayaan Intelektual | BD7: KA_INST | BE7: MJ | BF7: Kepala Instalasi Pengelolaan Inovasi dan Kekayaan Intelektual | BI7: APT | BJ7: Apoteker Ahli Madya | BK7: =N7 -> IV/a | BL7: JFT | BP7: - | BQ7: Apoteker Ahli Madya | BR7: 01-08-2020 | BS7: 450.3520 | BT7: 01-12-2010 | BU7: 01-04-2012 | BV7: 01-06-2010 | BW7: =YEAR(NOW())-YEAR(BV7) -> 13 | BX7: =DATEDIF(BV7,NOW(),"YM") -> 3 | CA7: Islam | CB7: Menikah | CC7: 1 | CD7: 1 | CE7: Menanggung | CL7: 19790417/STRA-UII/2004/11839 | CM7: 17-04-2026 | CN7: 126 | CO7: 32/B.19/31.74.06.1001.05.023.S.2.a.b/3/-1.779.3/e/2021 | CP7: 17-04-2026 | CQ7: 126 | CR7: 4350 | CS7: Benar Lulusan S2 Farmasi Klinik UGM | CV7: KP.00.02/II.4/2960/2012 | CW7: S2 Farmasi Klinis UGM | CX7: 29-10-2012 | DB7: Benar STRA dikeluarkan oleh Komite Farmasi Nasional | DC7: UM.01.05/KF/348/2019 | DD7: 25-09-2019 | DE7: 2021 | DI7: HK.02.03/VIII.2/11705/2019 | DJ7: 04-09-2019 | DM7: 67.868.601.5-542.000 | DO7: 3273291501140004 | DP7: 3404121704790001 | DQ7: Cluster Kilimanjaro No. 167 - 169 Pinus Regency Rt. 003 / 008 Kel. Babakan Penghulu Kec. Cinambo Bandung | DR7: Tamansari Puri Bali Blok J5 No.5 Curug Depok | DS7: 081316018687 | DT7: apt.asubhan@gmail.com | DU7: 3 | DV7: Moderna | DY7: 1407/2022 | DZ7: 20-12-2021 | EA7: 17-04-2025 | EB7: 0 | EC7: Tenaga Profesional Lainnya | ED7: MANAJERIAL
A8: 6 | B8: Ali Syahrul Chairuman, SKM, M.KKK | C8: 140333454 | D8: 197310201997031002 | F8: Ahli Muda | G8: =IF(F8="Ahli Madya",60,IF(F8="Ahli Utama",65,58)) -> 58 | H8: =DATE(YEAR(X8)+G8,MONTH(X8)+1,1) -> 48153 | J8: ASN | K8: PNS | L8: PNS | M8: L | N8: III/c | O8: 3C | P8: 01-10-2014 | R8: 22 | S8: 0 | U8: 1396 | W8: Jakarta | X8: 20-10-1973 | Y8: =YEAR(NOW())-YEAR(X8) -> #VALUE! | Z8: =IF(AND(Y8>=21,Y8<=35),"21-35",IF(AND(Y8>35,Y8<=45),"36-45",IF(AND(Y8>45,Y8<=58),"46-58",IF(Y8>58,"Lebih dari 58",0)))) -> #VALUE! | AB8: Magister Keselamatan dan Kesehatan Kerja | AC8: TENAGA KESEHATAN LAIN | AD8: TENAGA KESEHATAN LAIN | AF8: TKL | AG8: A | AH8: C | AI8: S2 | AJ8: 1206300100 | AK8: NC.12-019092 | AL8: 17-07-2014 | AM8: Universitas Indonesia | AP8: Instalasi Kesehatan Lingkungan dan K3 Rumah Sakit | AQ8: 14-02-2022 | AR8: MANAJEMEN | AS8: MANAJEMEN | AT8: =_xlfn.IFNA(VLOOKUP(D8,'[1]5. 1 Mei 2022'!$C$7:$F$60,4,FALSE),"") | AU8: Kepala Instalasi | AV8: Kepala Instalasi Kesehatan Lingkungan dan K3 Rumah Sakit | AW8: 14-02-2022 | AX8: =AW8+1903 -> 46509 | AY8: Direktorat Perencanaan, Organisasi, dan Umum | AZ8: K3 | BA8: Instalasi Kesehatan Lingkungan dan K3 Rumah Sakit | BD8: KA_INST | BE8: MJ | BF8: Kepala Instalasi Kesehatan Lingkungan dan K3 Rumah Sakit | BJ8: Pembimbing Kesehatan Kerja Ahli Muda | BK8: =N8 -> III/c | BL8: JFT | BP8: - | BQ8: Pembimbing Kesehatan Kerja Ahli Muda | BR8: 01-12-2018 | BS8: 261 | BT8: 01-03-1997 | BV8: 01-02-1995 | BW8: =YEAR(NOW())-YEAR(BV8) -> 28 | BX8: =DATEDIF(BV8,NOW(),"YM") -> 3 | CA8: Islam | CB8: Menikah | CC8: 3 | CD8: 1 | CE8: Menanggung | CG8: 2008 | CL8: 122781118-1584822 | CM8: 20-10-2023 | CN8: 123 | CO8: 0 | CP8: 0 | CQ8: 0 | CR8: 3922 | CS8: Benar lulusan Sarjana Kesehatan Masyarakat UI // Dicek Melalui Forlap Dikti (S2) | CT8: 1031/H2.F10/PPM.00.00/2014 | CU8: 18-02-2014 | CV8: KP.00.02/II.4/2962/2012 // KP.00.02/II.4/317/2014 | CW8: D3 Teknik Radiologi Poltekkes Jakarta II // S1 Kesehatan Masyarakat UI | CX8: 29-10-2012 // 10-01-2014 | DM8: 69.934.801.7-412.000 | DO8: 0 | DP8: 3276032010730005 | DQ8: Pasir Putih Rt. 006 / 004 Kel. Pasir Putih Kec. Sawangan Kota Depok | DS8: 081288925272 | DT8: alisyachrul@gmail.com | DU8: 3 | DV8: Moderna | DY8: 14067/2022 | DZ8: 03-10-2022 | EA8: 20-10-2025 | EB8: 17813 | EC8: Tenaga Profesional Lainnya | ED8: MANAJERIAL
A9: 7 | B9: Anisah, A.Md | C9: 140375340 | D9: 197407262007012009 | F9: Mahir | G9: =IF(F9="Ahli Madya",60,IF(F9="Ahli Utama",65,58)) -> 58 | H9: =DATE(YEAR(X9)+G9,MONTH(X9)+1,1) -> 48427 | J9: ASN | K9: PNS | L9: PNS | M9: P | N9: III/b | O9: 3B | P9: 01-10-2022 | Q9: KP.02.01/5/21486/2022 | R9: 22 | S9: 8 | U9: 1518 | V9: P 177587 | W9: Jakarta | X9: 26-07-1974 | Y9: =YEAR(NOW())-YEAR(X9) -> #VALUE! | Z9: =IF(AND(Y9>=21,Y9<=35),"21-35",IF(AND(Y9>35,Y9<=45),"36-45",IF(AND(Y9>45,Y9<=58),"46-58",IF(Y9>58,"Lebih dari 58",0)))) -> #VALUE! | AB9: D3 Rekam Medis dan Informasi Kesehatan | AC9: TENAGA KESEHATAN LAIN | AD9: TENAGA KESEHATAN LAIN | AF9: TKL | AG9: C | AH9: C | AI9: D3 | AJ9: 2008-36-047 | AK9: 0457/N36/UEU-08757/04/2011 | AL9: 26-05-2011 | AM9: Universitas Esa Unggul | AP9: Instalasi Rekam Medik | AR9: MANAJEMEN | AS9: MANAJEMEN | AT9: =_xlfn.IFNA(VLOOKUP(D9,'[1]5. 1 Mei 2022'!$C$7:$F$60,4,FALSE),"") | AU9: Kepala Instalasi | AV9: Kepala Instalasi Rekam Medik | AW9: 14-02-2022 | AX9: =AW9+1903 -> 46509 | AY9: Direktorat Pelayanan Medik, Keperawatan, dan Penunjang | AZ9: IRMEDIK | BA9: Instalasi Rekam Medik | BD9: KA_INST | BE9: MJ | BF9: Kepala Instalasi Rekam Medik | BI9: PRM | BJ9: Perekam Medis Mahir | BK9: =N9 -> III/b | BL9: JFT | BP9: - | BQ9: Perekam Medis Mahir | BR9: 1 Juli 2022 | BS9: 156.469 | BT9: 01-01-2007 | BV9: 01-02-1995 | BW9: =YEAR(NOW())-YEAR(BV9) -> 28 | BX9: =DATEDIF(BV9,NOW(),"YM") -> 3 | BZ9: 011086 LL | CA9: Islam | CB9: Menikah | CC9: 2 | CD9: 1 | CE9: Menanggung | CL9: 121052222-4392613 | CM9: 26-07-2027 | CN9: 127 | CO9: 29/B.33/31.74.06.1001.05.023.S.2/3/-1.779.3/e/2022 | CP9: 26-07-2027 | CQ9: 127 | CR9: 5199 | CS9: Benar lulusan D3 Rekam Medis Universitas Esa Unggul | CU9: 12-11-2012 | CV9: KP.00.02/II.4/2875/2012 | CW9: D3 Rekam Medis Univ Esa Unggul | CX9: 18-10-2012 | DB9: Benar STR Tenaga Perekam Medis dan Informasi Kesehatan dikeluarkan oleh Majelis Tenaga Kesehatan Indonesia | DD9: 06-09-2013 | DI9: HK.02.03/VIII.2/12142/2019 | DJ9: 16-09-2019 | DM9: 87.499.527.7-016.000 | DO9: 0 | DP9: 3174066607740002 | DQ9: Jl. Lebak Bulus II / 22 Rt. 006/004 Kel. Cilandak Barat Kec. Cilandak Jakarta Selatan | DS9: 081510852867 | DT9: anisahtarja@gmail.com | DU9: 3 | DV9: Moderna | DY9: 16329/2018 | DZ9: 31-12-2018 | EB9: 0 | EC9: Tenaga Profesional Lainnya | ED9: MANAJERIAL
A10: 8 | B10: Didi Nurhadi, S.Sos | C10: 197708042008121003 | D10: 197708042008121003 | F10: Non Jabfung | G10: =IF(F10="Ahli Madya",60,IF(F10="Ahli Utama",65,58)) -> 58 | H10: =DATE(YEAR(X10)+G10,MONTH(X10)+1,1) -> 49553 | J10: ASN | K10: PNS | L10: PNS | M10: L | N10: III/c | O10: 3C | P10: 01-04-2022 | R10: 20 | S10: 0 | U10: 414 | V10: P 202991 | W10: Jakarta | X10: 04-08-1977 | Y10: =YEAR(NOW())-YEAR(X10) -> 46 | Z10: =IF(AND(Y10>=21,Y10<=35),"21-35",IF(AND(Y10>35,Y10<=45),"36-45",IF(AND(Y10>45,Y10<=58),"46-58",IF(Y10>58,"Lebih dari 58",0)))) -> 46-58 | AB10: S1 Administrasi Niaga | AC10: TENAGA NON MEDIS | AD10: NON MEDIS / ADMINISTRASI | AF10: NONMDS | AG10: D | AH10: D | AI10: S1 | AJ10: 12.0910.10249 | AK10: No. 12.048.77.122.11 | AL10: 28-02-2011 | AM10: STISIP Bekasi | AP10: Instalasi Verifikasi dan Penjamin Pasien | AQ10: 01-09-2019 | AR10: MANAJEMEN | AS10: MANAJEMEN | AT10: =_xlfn.IFNA(VLOOKUP(D10,'[1]5. 1 Mei 2022'!$C$7:$F$60,4,FALSE),"") | AU10: Kepala Instalasi | AV10: Kepala Instalasi Verifikasi dan Penjamin Pasien | AW10: 14-02-2022 | AX10: =AW10+1903 -> 46509 | AY10: Direktorat Keuangan dan Barang Milik Negara | AZ10: IVPP | BA10: Instalasi Verifikasi dan Penjamin Pasien | BD10: KA_INST | BE10: MJ | BF10: Kepala Instalasi Verifikasi dan Penjamin Pasien | BJ10: Pengadministrasi Umum | BK10: =N10 -> III/c | BL10: JFU | BP10: - | BT10: 01-12-2008 | BU10: 01-06-2010 | BV10: 01-06-1997 | BW10: =YEAR(NOW())-YEAR(BV10) -> 26 | BX10: =DATEDIF(BV10,NOW(),"YM") -> 3 | CA10: Islam | CB10: Menikah | CC10: 3 | CD10: 1 | CE10: Menanggung | CR10: 3049 | CV10: KP.00.02/II.4/6507/2016 | CW10: S1 Ilmu Administrasi Niaga STISIP Bekasi | CX10: 10-11-2016 | DM10: 87.499.489.0-016.000 | DO10: 3174061601096001 | DP10: 3174060408770009 | DQ10: Jl Wijaya Kusuma No.57 A RT 009 RW 004 Pondok Labu Cilandak Jakarta Selatan | DS10: 085711800118 | DU10: 3 | DV10: Moderna | EB10: 0 | EC10: Tenaga Non Medis | ED10: MANAJERIAL
A11: 9 | B11: dr. Dany K Ramdhan, Sp.B.S | C11: K20110110110 | D11: 197409132014121001 | F11: Ahli Muda | G11: =IF(F11="Ahli Madya",60,IF(F11="Ahli Utama",65,58)) -> 58 | H11: =DATE(YEAR(X11)+G11,MONTH(X11)+1,1) -> 48488 | J11: ASN | K11: PNS | L11: PNS | M11: L | N11: III/d | O11: 3D | P11: 01-10-2022 | Q11: KP.02.01/5/21528/2022 | R11: 14 | S11: 9 | U11: 59 | V11: B 00014562 | W11: Purwakarta | X11: 13-09-1974 | Y11: =YEAR(NOW())-YEAR(X11) -> #VALUE! | Z11: =IF(AND(Y11>=21,Y11<=35),"21-35",IF(AND(Y11>35,Y11<=45),"36-45",IF(AND(Y11>45,Y11<=58),"46-58",IF(Y11>58,"Lebih dari 58",0)))) -> #VALUE! | AB11: Dokter Spesialis Bedah Saraf | AC11: DOKTER SPESIALIS | AD11: TENAGA MEDIS | AE11: KSM Bedah Saraf | AF11: MDS | AG11: A | AH11: A | AI11: FELLOW / MS | AJ11: 4104190011 | AK11: 0020/Sp-FK/2/2010 | AL11: 12-08-2010 | AM11: Universitas Indonesia | AP11: Instalasi Bedah Sentral | AQ11: 11-03-2019 | AR11: MANAJEMEN | AS11: MANAJEMEN | AT11: =_xlfn.IFNA(VLOOKUP(D11,'[1]5. 1 Mei 2022'!$C$7:$F$60,4,FALSE),"") | AU11: Kepala Instalasi | AV11: Kepala Instalasi Bedah Sentral | AW11: 14-02-2022 | AX11: =AW11+1903 -> 46509 | AY11: Direktorat Pelayanan Medik, Keperawatan, dan Penunjang | AZ11: IBS | BA11: Instalasi Bedah Sentral | BD11: KA_INST | BE11: MJ | BF11: Kepala Instalasi Bedah Sentral | BI11: DR | BJ11: Dokter Ahli Muda | BK11: =N11 -> III/d | BL11: JFT | BQ11: Dokter Ahli Muda | BR11: 1 Juli 2022 | BS11: 304.57 | BT11: 01-12-2014 | BU11: 01-05-2016 | BV11: 01-01-2011 | BW11: =YEAR(NOW())-YEAR(BV11) -> 12 | BX11: =DATEDIF(BV11,NOW(),"YM") -> 3 | BZ11: AB 00033267 | CA11: Islam | CB11: Menikah | CC11: 2 | CD11: 1 | CE11: Menanggung | CL11: 3111105420079575 | CM11: 13-09-2026 | CN11: 126 | CO11: 116/B.15B/31.74.06.1001.05.023.S.2.a.b/3/-1.779.3/e/2020 | CP11: 13-09-2026 | CQ11: 126 | CR11: 2258 | CS11: Benar Lulusan Sp1 FKUI // Benar lulusan Dokter Umum UI | CT11: 0 // 11089/H2.F1.D/PDP.02.01.02/2013 | CU11: 14-02-2012 // 07-10-2013 | CV11: KP.00.02/II.4/110/2012 | CW11: Dokter Spesialis Bedah Syaraf UI | CX11: 18-01-2012 | CY11: KP.00.02/II.4/2728/2013 | CZ11: Dokter Umum UI | DA11: 26-07-2013 | DB11: Benar STR Dokter dikeluarkan oleh Konsil Kedokteran Indonesia | DC11: KD.01.01/02/KKI/IX/4754/2016 | DD11: 29-09-2016 | DE11: 2020 | DF11: Benar SIP dokter dikeluarkan oleh UP PTSP Kec Cilandak | DG11: 210/-072.1 | DH11: 2020 | DI11: KP.00.02/II.4/5142/2016 | DJ11: 23-08-2016 | DK11: HK.02.03/VIII.2/15141/2019 | DL11: 24-10-2019 | DM11: 24.936.517.0-023.000 | DO11: 3275102101110021 | DP11: 3275101309740002 | DQ11: Jl. Leme Silaturahim Residen No.10 Rt.02 Rw.05 Kel.Jatikarya Kec.Jatisampurna | DR11: JL. Kenanga Raya No. 186 RT 02/05 Kel Depok Jaya Kec Pancoran Mas Depok 16432 | DS11: 081908728774 | DT11: danykur@gmail.com | DU11: 3 | DV11: Moderna | DY11: HK.01.07/VIII.2/1734/2019 | DZ11: 28-01-2019 | EB11: 1330941 | EC11: Dokter Spesialis | ED11: MANAJERIAL | EE11: Universitas Indonesia | EF11: Universitas Indonesia
A12: 10 | B12: dr. Dieby Adrisyel, Sp.Rad | C12: K2018011003 | D12: 202005198304111024 | F12: Non Jabfung | G12: =IF(F12="Ahli Madya",60,IF(F12="Ahli Utama",65,58)) -> 58 | H12: =DATE(YEAR(X12)+G12,MONTH(X12)+1,1) -> 51622 | I12: 919830411201801102 | J12: NON ASN | K12: Pegawai Tetap BLU | L12: PEG TETAP BLU | M12: L | N12: III/b | O12: 3B | P12: 01-05-2020 | U12: K-888 | W12: Lubuk Alung | X12: 11-04-1983 | Y12: =YEAR(NOW())-YEAR(X12) -> 40 | Z12: =IF(AND(Y12>=21,Y12<=35),"21-35",IF(AND(Y12>35,Y12<=45),"36-45",IF(AND(Y12>45,Y12<=58),"46-58",IF(Y12>58,"Lebih dari 58",0)))) -> 36-45 | AB12: Dokter Spesialis Radiologi + Konsultan Radiologi Intervensi | AC12: DOKTER SPESIALIS KONSULTAN | AD12: TENAGA MEDIS | AE12: KSM Radiologi | AF12: MDS | AG12: A | AH12: A | AI12: KONSULTAN | AJ12: 131521120010 | AK12: UN6.0025422/C21.003502 | AL12: 04-06-2016 | AM12: Universitas Padjadjaran + Kolegium Radiologi Indonesia | AO12: 20-09-2022 | AP12: Instalasi Radiologi Terpadu | AQ12: 14-02-2022 | AR12: MANAJEMEN | AS12: MANAJEMEN | AT12: =_xlfn.IFNA(VLOOKUP(D12,'[1]5. 1 Mei 2022'!$C$7:$F$60,4,FALSE),"") | AU12: Kepala Instalasi | AV12: Kepala Instalasi Radiologi Terpadu | AW12: 14-02-2022 // 30-09-2022 | AX12: =AW12+1903 -> #VALUE! | AY12: Direktorat Pelayanan Medik, Keperawatan, dan Penunjang | AZ12: I_RADIOLOGI | BA12: Instalasi Radiologi Terpadu | BD12: KA_INST | BE12: MDS | BF12: Kepala Instalasi Radiologi Terpadu | BG12: Pelaksana Harian Kepala Instalasi Rehabilitasi Medik | BJ12: 0 | BK12: =N12 -> III/b | BV12: 01-01-2018 | BW12: =YEAR(NOW())-YEAR(BV12) -> 5 | BX12: =DATEDIF(BV12,NOW(),"YM") -> 3 | BY12: 01-05-2020 | CA12: Islam | CB12: Menikah | CC12: 3 | CD12: 1 | CL12: 3211503321105297 | CM12: 11-04-2027 | CN12: 127 | CO12: 26/B.15B/31.74.06.1001.05.023.S.2/3/-1.779.3/e/2022 | CP12: 11-04-2027 | CQ12: 127 | CR12: 2401 | CS12: Benar Lulusan Dokter umum Universitas YARSI // Sp1 Dicek Melalui Forlap Dikti | CT12: 2312/DEK/BIA/X/2017 | CU12: 26-10-2017 | CV12: KP.02.01/II.4/4206/2017 // KP.02.01/II.4/4081/2017 | CW12: Sp1 Universitas Padjadjaran // Sp1 Universitas Padjadjaran | CX12: 17-10-2017 // 09-10-2017 | CY12: KP.02.01/II.4/4243/2017 | CZ12: Dokter Umum Universitas YARSI | DA12: 19-10-2017 | DB12: Dicek Melalui Website | DE12: 2022 | DF12: Benar SIP dokter dikeluarkan oleh UP PTSP Kec Cilandak | DG12: 210/-072.1 | DH12: 2022 | DK12: HK.02.03/VIII.2/15141/2019 | DL12: 24-10-2019 | DM12: 15.369.344.8-215.000 | DP12: 2171091104830001 | DQ12: Jl. Sawo No.56 RT.007 RW.002 Kel. Cipete Utara Kec. Kebayoran Baru Jakarta Selatan | DS12: 081298701437 | DT12: adrisyel.adri@gmail.com | DU12: 3 | DV12: Moderna | DY12: D.XXI/284/2023 | DZ12: 03-03-2023 | EA12: 03-03-2026 | EB12: 0 | EC12: Dokter Spesialis | ED12: MANAJERIAL | EE12: Universitas YARSI | EF12: Universitas Padjadjaran
A13: 11 | B13: dr. Jerry Nasarudin, Sp.PD, FINASIM | C13: K2018021001 | D13: 198510212019021001 | F13: Ahli Muda | G13: =IF(F13="Ahli Madya",60,IF(F13="Ahli Utama",65,58)) -> 58 | H13: =DATE(YEAR(X13)+G13,MONTH(X13)+1,1) -> 52536 | J13: ASN | K13: PNS | L13: PNS | M13: L | N13: III/c | O13: 3C | P13: 01-04-2023 | Q13: KP.02.01/A/19185/2023 | R13: 4 | S13: 2 | U13: 133 | V13: B 00051256 | W13: Jakarta | X13: 21-10-1985 | Y13: =YEAR(NOW())-YEAR(X13) -> #VALUE! | Z13: =IF(AND(Y13>=21,Y13<=35),"21-35",IF(AND(Y13>35,Y13<=45),"36-45",IF(AND(Y13>45,Y13<=58),"46-58",IF(Y13>58,"Lebih dari 58",0)))) -> #VALUE! | AB13: Dokter Spesialis Penyakit Dalam | AC13: DOKTER SPESIALIS | AD13: TENAGA MEDIS | AE13: KSM Penyakit Dalam | AF13: MDS | AG13: A | AH13: A | AI13: FELLOW / MS | AJ13: 1006824371 | AK13: NC.16-002191 | AL13: 05-02-2016 | AM13: Universitas Indonesia | AP13: Instalasi Rawat Inap | AQ13: 14-02-2022 | AR13: MANAJEMEN | AS13: MANAJEMEN | AT13: =_xlfn.IFNA(VLOOKUP(D13,'[1]5. 1 Mei 2022'!$C$7:$F$60,4,FALSE),"") | AU13: Kepala Instalasi | AV13: Kepala Instalasi Rawat Inap | AW13: 14-02-2022 | AX13: =AW13+1903 -> 46509 | AY13: Direktorat Pelayanan Medik, Keperawatan, dan Penunjang | AZ13: IRINAP | BA13: Instalasi Rawat Inap | BB13: IRNA | BD13: KA_INST | BE13: MDS | BF13: Kepala Instalasi Rawat Inap | BI13: DR | BJ13: Dokter Ahli Pertama | BK13: =N13 -> III/c | BL13: JFT | BQ13: Dokter Ahli Muda | BR13: 01-11-2022 | BS13: 205.6560. | BT13: 01-02-2019 | BU13: 01-02-2020 | BV13: 01-02-2018 | BW13: =YEAR(NOW())-YEAR(BV13) -> 5 | BX13: =DATEDIF(BV13,NOW(),"YM") -> 3 | BZ13: AB 00037616 | CA13: Islam | CB13: Menikah | CC13: 1 | CD13: 1 | CL13: 3111401421099138 | CM13: 21-10-2026 | CN13: 126 | CO13: 145/B.15B/31.74.06.1001.05.023.S.2.a.b/3/-1.779.3/e/2021 | CP13: 21-10-2026 | CQ13: 126 | CR13: 2403 | CS13: Dokter Umum dicek Melalui Forlap Dikti // Benar Lulusan Sp1 UI // Benar Lulusan Sp1 UI | CT13: 0 // 13515/UN2.F1.D1.1/PDP.00.06/2017 // 10734/UN2.F1.D1.1/PDP.00.06/2017 | CU13: 0 // 02-11-2017 // 05-09-2017 | CV13: KP.02.01/II.4/3728/2017 | CW13: Sp1 UI | CX13: 12-09-2017 | CY13: KP.02.01/II.4/4242/2017 | CZ13: Dokter Umum UI | DA13: 19-10-2017 | DB13: Dicek Melalui Website KKI | DE13: 2021 | DF13: Benar SIP dokter dikeluarkan oleh UP PTSP Kec Cilandak | DG13: 210/-072.1 | DH13: 2021 | DK13: HK.02.03/VIII.2/15141/2019 | DL13: 24-10-2019 | DM13: 59.022.028.1.045.000 | DP13: 3172032110850012 | DQ13: Jl. Mantang Blok L.GG IV/21 RT.006 RW.012 Kel. Lagoa Kec. Koja Jakarta Utara | DR13: Jl. Minang L4 No.21 Koja Jakarta Utara | DS13: 081288202354 | DT13: jerrynasarudin@gmail.com | DU13: 3 | DV13: Moderna | DY13: HK.01.07/VIII.2/3004/2019 | DZ13: 25-02-2019 | EB13: 1451366 | EC13: Dokter Spesialis | ED13: MANAJERIAL | EE13: Universitas Indonesia | EF13: Universitas Indonesia
A14: 12 | B14: dr. Kumalayanti Kamaludin | C14: K2012092037 | D14: 197710162014122001 | F14: Ahli Muda | G14: =IF(F14="Ahli Madya",60,IF(F14="Ahli Utama",65,58)) -> 58 | H14: =DATE(YEAR(X14)+G14,MONTH(X14)+1,1) -> 49614 | J14: ASN | K14: PNS | L14: PNS | M14: P | N14: III/d | O14: 3D | P14: 01-04-2022 | Q14: KP.02.01/2/8082/2022 | R14: 12 | S14: 7 | U14: 479 | V14: B 00014560 | W14: Jakarta | X14: 16-10-1977 | Y14: =YEAR(NOW())-YEAR(X14) -> #VALUE! | Z14: =IF(AND(Y14>=21,Y14<=35),"21-35",IF(AND(Y14>35,Y14<=45),"36-45",IF(AND(Y14>45,Y14<=58),"46-58",IF(Y14>58,"Lebih dari 58",0)))) -> #VALUE! | AB14: Dokter Umum | AC14: DOKTER UMUM | AD14: TENAGA MEDIS | AE14: KSM Umum | AF14: MDS | AG14: A | AH14: A | AI14: S1 | AJ14: 1101996089 | AK14: 1432/FK/REK/VIII/2004 | AL14: 10-08-2004 | AM14: Universitas Yarsi | AP14: Instalasi Sistem Informasi Manajemen Rumah Sakit | AQ14: 14-02-2022 | AR14: MANAJEMEN | AS14: MANAJEMEN | AT14: =_xlfn.IFNA(VLOOKUP(D14,'[1]5. 1 Mei 2022'!$C$7:$F$60,4,FALSE),"") | AU14: Kepala Instalasi | AV14: Kepala Instalasi Sistem Informasi Manajemen Rumah Sakit | AW14: 14-02-2022 | AX14: =AW14+1903 -> 46509 | AY14: Direktorat Perencanaan, Organisasi, dan Umum | AZ14: ISIRS | BA14: Instalasi Sistem Informasi Manajemen Rumah Sakit | BD14: KA_INST | BE14: MJ | BF14: Kepala Instalasi Sistem Informasi Manajemen Rumah Sakit | BI14: DR | BJ14: Dokter Ahli Muda | BK14: =N14 -> III/d | BL14: JFT | BP14: - | BQ14: Dokter Ahli Muda | BR14: 01-12-2021 | BS14: 304.9240 | BT14: 01-12-2014 | BU14: 01-05-2016 | BV14: 01-09-2009 | BW14: =YEAR(NOW())-YEAR(BV14) -> 14 | BX14: =DATEDIF(BV14,NOW(),"YM") -> 3 | BZ14: BB 00006683 | CA14: Islam | CB14: Menikah | CC14: 1 | CD14: 1 | CE14: Menanggung | CL14: 3121100422033841 | CM14: 16-10-2028 | CN14: 128 | CO14: 121/B.15A/31.74.06.1001.23.SPU-1.d/4/-1.779.3/e/2022 | CP14: 16-10-2028 | CQ14: 128 | CR14: 2218 | CS14: Benar lulusan Fakultas Kedokteran YARSI | CU14: 20-11-2012 | CY14: KP.00.02/II.4/2811/2012 | CZ14: Dokter Umum Universitas YARSI | DA14: 15-10-2012 | DB14: Dicek Melalui Website KKI | DE14: 2022 | DF14: Benar SIP dokter dikeluarkan oleh Suku Dinas Kesehatan Jakarta Selatan | DG14: 931/-1.777.11 | DH14: 41313 | DI14: KP.00.02/II.4/4140/2013 | DJ14: 10-12-2013 | DK14: HK.02.03/VIII.2/9541/2019 | DL14: 29-07-2019 | DM14: 49.280.376.2-016.000 | DO14: 0 | DP14: 3174065610770001 | DQ14: Jl. Poncol Jaya II No. 15 Rt. 08 / 06 Kel. Gandaria Selatan Kec. Cilandak Jakarta Selatan | DS14: 085880860071 | DT14: kumala77@gmail.com | DU14: 3 | DV14: Moderna | DY14: 10588/2022 | DZ14: 44771 | EA14: 45867 | EB14: 961288 | EC14: Tenaga Non Medis | ED14: MANAJERIAL
A15: 13 | B15: dr. Lidya Utami, Sp.PK (K) | C15: K20110320134 | D15: 197912082014122003 | F15: Ahli Muda | G15: =IF(F15="Ahli Madya",60,IF(F15="Ahli Utama",65,58)) -> 58 | H15: =DATE(YEAR(X15)+G15,MONTH(X15)+1,1) -> 50406 | J15: ASN | K15: PNS | L15: PNS | M15: P | N15: III/d | O15: 3D | P15: 01-04-2022 | Q15: KP.02.01/2/8083/2022 | R15: 11 | S15: 1 | U15: 581 | V15: B 00038245 | W15: Bandung | X15: 08-12-1979 | Y15: =YEAR(NOW())-YEAR(X15) -> 44 | Z15: =IF(AND(Y15>=21,Y15<=35),"21-35",IF(AND(Y15>35,Y15<=45),"36-45",IF(AND(Y15>45,Y15<=58),"46-58",IF(Y15>58,"Lebih dari 58",0)))) -> 36-45 | AB15: Dokter Spesialis Patologi Klinik + Konsultan Hematologi | AC15: DOKTER SPESIALIS KONSULTAN | AD15: TENAGA MEDIS | AE15: KSM Patologi Klinik | AF15: MDS | AG15: A | AH15: A | AI15: KONSULTAN | AJ15: 4104162034 | AK15: 0108/Sp-FK/2/2010 | AL15: 12-08-2010 | AM15: Universitas Indonesia | AN15: Konsultan Hematologi | AO15: 25-11-2016 | AP15: Instalasi Laboratorium | AQ15: 11-03-2019 | AR15: MANAJEMEN | AS15: MANAJEMEN | AT15: =_xlfn.IFNA(VLOOKUP(D15,'[1]5. 1 Mei 2022'!$C$7:$F$60,4,FALSE),"") | AU15: Kepala Instalasi | AV15: Kepala Instalasi Laboratorium | AW15: 14-02-2022 | AX15: =AW15+1903 -> 46509 | AY15: Direktorat Pelayanan Medik, Keperawatan, dan Penunjang | AZ15: I_LABORATORIUM | BA15: Instalasi Laboratorium | BD15: KA_INST | BE15: MJ | BF15: Kepala Instalasi Laboratorium | BI15: DR | BJ15: Dokter Ahli Muda | BK15: =N15 -> III/d | BL15: JFT | BQ15: Dokter Ahli Muda | BR15: 01-12-2021 | BS15: 312.7810 | BT15: 01-12-2014 | BU15: 01-05-2016 | BV15: 01-03-2011 | BW15: =YEAR(NOW())-YEAR(BV15) -> 12 | BX15: =DATEDIF(BV15,NOW(),"YM") -> 3 | BZ15: BB 00006678 | CA15: Kristen Protestan | CB15: Menikah | CC15: 1 | CD15: 1 | CE15: Menanggung | CL15: 312150200420031548 | CM15: 08-12-2025 | CN15: 125 | CO15: 88/B.15B/31.74.06.1001.05.023.S.2.a.b/3/-1.779.3/e/2020 | CP15: 08-12-2025 | CQ15: 125 | CR15: 2282 | CS15: Benar Lulusan Sp1 FKUI // Benar lulusan Dokter Umum Universitas Brawijaya | CU15: 14-02-2012 //05-09-2013 | CV15: KP.00.02/II.4/110/2012 // KP.00.02/II.4/6996/2016 | CW15: Spesialis I UI // Konsultan Hematologi | CX15: 18-01-2012 // 08-12-2016 | CY15: ''KP.00.02/II.4/2707/2013 | CZ15: Dokter Umum Universitas Brawijaya | DA15: 24-07-2013 | DB15: Benar STR Dokter Sudah Terregistrasi di database Konsil Kedokteran Indonesia | DC15: KD.01.01/02/KKI/II/0323/2016 | DD15: 09-02-2016 | DF15: Benar SIP dokter dikeluarkan oleh UP PTSP Kec Cilandak | DG15: 210/-072.1 | DH15: 2020 | DI15: 0 // KP.00.02/II.4/6882/2015 | DJ15: 0 // '25-11-2015 | DK15: HK.02.03/VIII.2/15141/2019 | DL15: 24-10-2019 | DM15: 36.015.718.4-009.000 | DO15: 3175050501097948 | DP15: 3175054812790002 | DQ15: Jl Gongseng Raya RT 007 RW 010 Cijantung Pasar Rebo Jakarta Timur Rt.07 Rw.10 Kel.Cijantung Kec.Pasar Rebo | DR15: Komplek The Address Cibubur G-154 Leuwinanggung, Tapos, Depok, Jawa Barat | DS15: 081219119966 | DT15: lidyautami97@gmail.com | DU15: 3 | DV15: Moderna | DY15: 10622/2022 | DZ15: 12-08-2022 | EA15: 12-08-2025 | EB15: 1065771 | EC15: Dokter Spesialis | ED15: MANAJERIAL | EE15: Universitas Brawijaya | EF15: Universitas Indonesia | EG15: Kolegium Patologi Klinik
A16: 14 | B16: dr. Muhammad Azhari Taufik, Sp.An, KIC | C16: 202005198308261001 | D16: 198308262020121001 | F16: Ahli Pertama | G16: =IF(F16="Ahli Madya",60,IF(F16="Ahli Utama",65,58)) -> 58 | H16: =DATE(YEAR(X16)+G16,MONTH(X16)+1,1) -> 51745 | J16: ASN | K16: PNS | L16: PNS | M16: L | N16: III/b | O16: 3B | P16: 01-12-2021 | Q16: KP.03.02./VIII.2/7223/2022 | R16: 6 | S16: 11 | U16: K-671 | W16: Bandung | X16: 26-08-1983 | Y16: =YEAR(NOW())-YEAR(X16) -> #VALUE! | Z16: =IF(AND(Y16>=21,Y16<=35),"21-35",IF(AND(Y16>35,Y16<=45),"36-45",IF(AND(Y16>45,Y16<=58),"46-58",IF(Y16>58,"Lebih dari 58",0)))) -> #VALUE! | AB16: Dokter Spesialis Anestesiologi + Konsultan Intensive Care | AC16: DOKTER SPESIALIS KONSULTAN | AD16: TENAGA MEDIS | AE16: KSM Anestesiologi & Terapi Intensif | AF16: MDS | AG16: A | AH16: A | AI16: KONSULTAN | AJ16: 1006767191 | AK16: No. 0010/Sp-FK/2/2014 | AL16: 17-07-2014 | AM16: Universitas Indonesia | AN16: Konsultan Intensive Care | AO16: Blm ngasih Sertifikat KIC | AP16: Instalasi Rawat Intensif | AQ16: 09-10-2018 | AR16: MANAJEMEN | AS16: MANAJEMEN | AT16: =_xlfn.IFNA(VLOOKUP(D16,'[1]5. 1 Mei 2022'!$C$7:$F$60,4,FALSE),"") | AU16: Kepala Instalasi | AV16: Kepala Instalasi Rawat Intensif | AW16: 14-02-2022 | AX16: =AW16+1903 -> 46509 | AY16: Direktorat Pelayanan Medik, Keperawatan, dan Penunjang | AZ16: IRI | BA16: Instalasi Rawat Intensif | BD16: KA_INST | BE16: MJ | BF16: Kepala Instalasi Rawat Intensif | BI16: DR | BJ16: 0 | BK16: =N16 -> III/b | BL16: JFT | BQ16: Dokter Ahli Pertama | BR16: 27-06-2022 | BS16: 171.4060 | BT16: 01-12-2020 | BU16: 01-12-2021 | BV16: 01-01-2015 | BW16: =YEAR(NOW())-YEAR(BV16) -> 8 | BX16: =DATEDIF(BV16,NOW(),"YM") -> 3 | BY16: 01-05-2020 | CA16: Islam | CB16: Menikah | CC16: 2 | CD16: 1 | CE16: Menanggung | CL16: 311150107319106994 | CM16: 26-08-2024 | CN16: 124 | CO16: 51/B.15b/31.74.06.1001.05.023.S.2/3/-1.779.3/e/2019 | CP16: 26-08-2024 | CQ16: 124 | CR16: 2361 | CS16: Benar Lulusan Sp1 UI | CT16: 13672/UN2.F1.D1.1/PDP.00.06/2015 | CU16: 19-11-2015 | CV16: KP.00.02/II.4/4531/2015 | CW16: Sp1 Universitas Indonesia | CX16: 28-10-2015 | CY16: KP.00.02/II.4/5799/2016 | CZ16: Dokter Umum Univ. Diponegoro | DA16: 29-09-2016 | DB16: Benar STR Dokter Sudah Terregistrasi di database Konsil Kedokteran Indonesia | DC16: KD.01.01/02/KKI/II/0323/2016 | DD16: 09-02-2016 | DF16: Benar SIP dokter dikeluarkan oleh UP PTSP Kec Cilandak | DG16: 210/-072.1 | DH16: 2024 | DI16: KP.00.02/II.4/6882/2015 | DJ16: 25-11-2015 | DK16: HK.02.03/VIII.2/15141/2019 | DL16: 24-10-2019 | DM16: 66.018.934.1-407.000 | DO16: 3174061208160007 | DP16: 3275022608830021 | DQ16: Arden RSD Jl. Bango II No. A3 Kel. Pondok Labu Kec. Cilandak Jakarta Selatan | DS16: 081906142116 | DT16: taufik_azhari@yahoo.com | DU16: 3 | DV16: Moderna | DY16: 15213/2022 | DZ16: 21-10-2022 | EA16: 21-10-2025 | EB16: 0 | EC16: Dokter Spesialis | ED16: MANAJERIAL | EE16: Universitas Diponegoro | EF16: Universitas Indonesia | EG16: Universitas Indonesia
A17: 15 | B17: dr. Retno Sawitri, Sp.F.M | C17: PNS | D17: 198411262018012001 | F17: Ahli Muda | G17: =IF(F17="Ahli Madya",60,IF(F17="Ahli Utama",65,58)) -> 58 | H17: =DATE(YEAR(X17)+G17,MONTH(X17)+1,1) -> 52201 | J17: ASN | K17: PNS | L17: PNS | M17: P | N17: III/c | O17: 3C | P17: 01-04-2021 | R17: 4 | S17: 0 | U17: 69 | V17: B 00038655 | W17: Ujung Pandang | X17: 26-11-1984 | Y17: =YEAR(NOW())-YEAR(X17) -> #VALUE! | Z17: =IF(AND(Y17>=21,Y17<=35),"21-35",IF(AND(Y17>35,Y17<=45),"36-45",IF(AND(Y17>45,Y17<=58),"46-58",IF(Y17>58,"Lebih dari 58",0)))) -> #VALUE! | AB17: Dokter Spesialis Kedokteran Forensik dan Medikolegal | AC17: DOKTER SPESIALIS | AD17: TENAGA MEDIS | AE17: KSM Patologi Anatomi | AF17: MDS | AG17: A | AH17: A | AI17: FELLOW / MS | AJ17: No. 1106025901 | AK17: No. NC.14-005683 | AL17: 26-01-2015 | AM17: Universitas Indonesia | AO17: 42030 | AP17: Instalasi Forensik & Pemulasaraan Jenazah | AR17: MANAJEMEN | AS17: MANAJEMEN | AT17: =_xlfn.IFNA(VLOOKUP(D17,'[1]5. 1 Mei 2022'!$C$7:$F$60,4,FALSE),"") | AU17: Kepala Instalasi | AV17: Kepala Instalasi Forensik & Pemulasaraan Jenazah | AW17: 14-02-2022 | AX17: =AW17+1903 -> 46509 | AY17: Direktorat Pelayanan Medik, Keperawatan, dan Penunjang | AZ17: IFPJ | BA17: Instalasi Forensik & Pemulasaraan Jenazah | BD17: KA_INST | BE17: MJ | BF17: Kepala Instalasi Forensik & Pemulasaraan Jenazah | BJ17: Dokter Ahli Muda | BK17: =N17 -> III/c | BL17: JFT | BQ17: Dokter Ahli Muda | BR17: 01-12-2020 | BS17: 214.5710 | BT17: 01-01-2018 | BU17: 01-02-2019 | BV17: 01-09-2015 | BW17: =YEAR(NOW())-YEAR(BV17) -> 8 | BX17: =DATEDIF(BV17,NOW(),"YM") -> 3 | BZ17: BB 00020297 | CA17: Islam | CB17: Menikah | CD17: 1 | CE17: Menanggung | CL17: Belum Menyerahkan | CM17: 26-11-2025 | CN17: 125 | CO17: 41/B.15B/31.74.06.1001.05.023.S.2.a.b/3/-1.779.3/e/2020 | CP17: 26-11-2025 | CQ17: 125 | CR17: 2368 | CS17: Benar Lulusan Sp1 FKUI | CT17: 4789/UN2.F1.D1.1/PDP.00.06/2015 | CU17: 28-04-2015 | CV17: KP.00.02/II.4/846/2015 | CW17: Sp 1 UI | CX17: 19-03-2015 | CY17: KP.00.02/II.4/847/2015 | CZ17: Dokter Umum Universitas Diponegoro | DA17: 19-03-2015 | DB17: Benar STR Sudah terregistrasi di data base KKI | DC17: KD.01.01/02/KKI/V/1781/2015 | DD17: 06-05-2015 | DF17: Benar SIP dokter dikeluarkan oleh UP PTSP Kec Cilandak | DG17: 210/-072.1 | DH17: 2020 | DI17: KP.00.02/II.4/845/2015 | DJ17: 19-03-2015 | DK17: HK.02.03/VIII.2/15141/2019 | DL17: 24-10-2019 | DM17: 89.884.678.7-017.000 | DO17: 3174041401091421 | DP17: 3174046611840011 | DQ17: Jl. Hortikultura No. 11 A Rt. 008/006 Jatipadang, Pasar Minggu Jakarta Selatan | DS17: 081294379978 | DT17: retnosawitrimd@gmail.com | DU17: 2 | DV17: CoronaVac | DY17: 10776/2021 | DZ17: 07-11-2021 | EB17: 0 | EC17: Dokter Spesialis | ED17: MANAJERIAL | EE17: Universitas Indonesia | EF17: Universitas Indonesia
A18: 16 | B18: dr. Rianita, M.Gizi, Sp.G.K | C18: PNS | D18: 197001101998032004 | F18: Ahli Madya | G18: =IF(F18="Ahli Madya",60,IF(F18="Ahli Utama",65,58)) -> 60 | H18: =DATE(YEAR(X18)+G18,MONTH(X18)+1,1) -> 47515 | J18: ASN | K18: PNS | L18: PNS | M18: P | N18: IV/b | O18: 4B | P18: 01-04-2022 | Q18: KP.02.01/Menkes/944/2022 | R18: 27 | S18: 1 | U18: 18 | V18: G 444382 | W18: Surabaya | X18: 10-01-1970 | Y18: =YEAR(NOW())-YEAR(X18) -> 53 | Z18: =IF(AND(Y18>=21,Y18<=35),"21-35",IF(AND(Y18>35,Y18<=45),"36-45",IF(AND(Y18>45,Y18<=58),"46-58",IF(Y18>58,"Lebih dari 58",0)))) -> 46-58 | AB18: Dokter Spesialis Gizi Klinik + Magister Gizi | AC18: DOKTER SPESIALIS | AD18: TENAGA MEDIS | AE18: KSM Gizi Klinik | AF18: MDS | AG18: A | AH18: A | AI18: FELLOW / MS | AJ18: 0188001058 + 6104020118 | AK18: 112/Dok.II/94 + 0022/S2-FK/2/2007 | AL18: 06-09-1991 + 25-08-2007 | AM18: Universitas Indonesia + Universitas Indonesia | AP18: Instalasi Gizi | AQ18: 14-02-2022 | AR18: MANAJEMEN | AS18: MANAJEMEN | AT18: =_xlfn.IFNA(VLOOKUP(D18,'[1]5. 1 Mei 2022'!$C$7:$F$60,4,FALSE),"") | AU18: Kepala Instalasi | AV18: Kepala Instalasi Gizi | AW18: 14-02-2022 | AX18: =AW18+1903 -> 46509 | AY18: Direktorat Pelayanan Medik, Keperawatan, dan Penunjang | AZ18: I_GIZI | BA18: Instalasi Gizi | BD18: KA_INST | BE18: MDS | BF18: Kepala Instalasi Gizi | BI18: DR | BJ18: Dokter Ahli Madya | BK18: =N18 -> IV/b | BL18: JFT | BQ18: Dokter Ahli Madya | BR18: 01-12-2021 | BS18: 550.4120 | BT18: 01-03-1998 | BU18: 01-05-2001 | BV18: 01-03-2014 | BW18: =YEAR(NOW())-YEAR(BV18) -> 9 | BX18: =DATEDIF(BV18,NOW(),"YM") -> 3 | CA18: Kristen Protestan | CB18: Menikah | CC18: 3 | CD18: 1 | CE18: Menanggung | CL18: 3121701421080166 | CM18: 10-01-2027 | CN18: 127 | CO18: 4/B.15B/31.74.06.1001.05.023.S.2/3/-1.779.3/e/2022 | CP18: 10-01-2027 | CQ18: 127 | CR18: 2340 | CS18: Benar lulusan Ilmu Gizi UI // Benar Lulusan Dokter Umum UI | CT18: 7564/H2.F1.D1/PDP.01/2013 // 10941/UN2.F1.D1.2/PDP.02.01.02/2016 | CU18: 08-07-2013 // 01-09-2016 | CV18: KP.00.02/II.4/1993/2012 // KP.00.02/II.4/6826/2016 | CW18: Magister Gizi Universitas Indonesia // Dokter Spesialis Gizi Klinik UI | CX18: 31-05-2013 // 25-11-2016 | CY18: KP.00.02/II.4/5048/2016 | CZ18: Dokter Umum UI | DA18: 15-08-2016 | DB18: Dicek Melalui Website KKI | DE18: 2022 | DF18: Benar SIP dokter dikeluarkan oleh UP PTSP Kec Cilandak | DG18: 210/-072.1 | DH18: 2022 | DI18: KP.00.02/II.4/6882/2015 | DJ18: 25-11-2015 | DK18: HK.02.03/VIII.2/15141/2019 | DL18: 24-10-2019 | DM18: 15.108.881.2-821.000 | DP18: 7171095001770052 | DQ18: Jl. Alam Pesanggrahan I No. 12 Blok O Rt. 001 / 016 Cinere Depok | DS18: 081340789444 | DU18: 3 | DV18: Moderna | DY18: HK.01.07/VIII.2/13944/2018 | DZ18: 16-11-2018 | EB18: 1529639 | EC18: Dokter Spesialis | ED18: MANAJERIAL | EE18: Universitas Indonesia | EF18: Universitas Indonesia
A19: 17 | B19: dr. Sharon Loraine Samuel, Sp.K.F.R (K) | C19: 202005198211122025 | D19: 198211122020122001 | F19: Ahli Pertama | G19: =IF(F19="Ahli Madya",60,IF(F19="Ahli Utama",65,58)) -> 58 | H19: =DATE(YEAR(X19)+G19,MONTH(X19)+1,1) -> 51471 | J19: ASN | K19: PNS | L19: PNS | M19: P | N19: III/b | O19: 3B | P19: 01-12-2021 | R19: 4 | S19: 0 | W19: Jakarta Pusat | X19: 12-11-1982 | Y19: =YEAR(NOW())-YEAR(X19) -> 41 | Z19: =IF(AND(Y19>=21,Y19<=35),"21-35",IF(AND(Y19>35,Y19<=45),"36-45",IF(AND(Y19>45,Y19<=58),"46-58",IF(Y19>58,"Lebih dari 58",0)))) -> 36-45 | AB19: Dokter Spesialis Kedokteran Fisik dan Rehabilitasi + Konsultan Neuromuskuler | AC19: DOKTER SPESIALIS KONSULTAN | AD19: TENAGA MEDIS | AE19: KSM Kedokteran Fisik dan Rehabilitasi | AF19: MDS | AG19: A | AH19: A | AI19: KONSULTAN | AJ19: 1306401095 | AK19: NC.17-006070 | AL19: 24-08-2017 | AM19: Universitas Indonesia | AN19: Konsultan Neuromuskuler | AO19: 09-08-2022 | AP19: Instalasi Rehabilitasi Medik | AQ19: 14-02-2022 | AR19: MANAJEMEN | AS19: MANAJEMEN | AT19: =_xlfn.IFNA(VLOOKUP(D19,'[1]5. 1 Mei 2022'!$C$7:$F$60,4,FALSE),"") | AU19: Kepala Instalasi | AV19: Kepala Instalasi Rehabilitasi Medik | AW19: 14-02-2022 | AX19: =AW19+1903 -> 46509 | AY19: Direktorat Pelayanan Medik, Keperawatan, dan Penunjang | AZ19: IRM | BA19: Instalasi Rehabilitasi Medik | BD19: KA_INST | BE19: MDS | BF19: Kepala Instalasi Rehabilitasi Medik | BJ19: 0 | BK19: =N19 -> III/b | BL19: JFT | BQ19: Dokter Ahli Pertama | BR19: 27-06-2022 | BS19: 173.6210 | BT19: 01-12-2020 | BU19: 01-12-2021 | BV19: 01-07-2018 | BW19: =YEAR(NOW())-YEAR(BV19) -> 5 | BX19: =DATEDIF(BV19,NOW(),"YM") -> 3 | BY19: 01-05-2020 | CA19: Kristen Protestan | CB19: Belum Menikah | CL19: 3121608422090266 | CM19: 12-11-2027 | CN19: 127 | CO19: 251/B.15B/31.74.06.1001.05.023.S.2/3/-1.779.3/e/2022 | CP19: 12-11-2027 | CQ19: 127 | CR19: 2410 | CS19: Dicek Melalui Forlap Dikti (Dokter Umum + SP1) // Benar Lulusan Dokter Umum UI // Benar Lulusan Sp1 UI // Benar lulusan Sp1 UI | CT19: 0 // 3416/UN2.F1.D1/PDP.02.01.02/2018 // 3426/UN2.F1.D1.1/PDP.00.06/2018 // 4028/UN2.F1.D1.1/PDP.00.06/2018 | CU19: 0 // 12-03-2018 // 12-03-2018 // 23-03-2018 | CV19: KP.01.03/VIII.2/4817/2018 | CW19: Dokter Umum + Sp1 UI | CX19: 23-04-2018 | DB19: Dicek di KKI | DE19: 12-11-2022 | DF19: Benar SIP dokter dikeluarkan oleh UP PTSP Kec Cilandak | DG19: 210/-072.1 | DH19: 2022 | DK19: HK.02.03/VIII.2/15141/2019 | DL19: 24-10-2019 | DM19: 80.613.314.6-001.000 | DO19: 3175011001090638 | DP19: 3175015211820010 | DQ19: Kebon Kelapa Tinggi RT.014 RW.008 Kel. Utan Kayu Selatan Kec.Matraman Jakarta Timur | DS19: 081291897877 | DT19: sh.loraine@gmail.com | DU19: 3 | DV19: Moderna | DY19: 5193/2020 | DZ19: 03-06-2020 | EB19: 0 | EC19: Dokter Spesialis | ED19: MANAJERIAL | EE19: Universitas Indonesia | EF19: Universitas Indonesia
A20: 18 | B20: dr. Ugi Sugiri, Sp.EM | C20: 140243840 | D20: 196005211989121001 | F20: Ahli Utama | G20: =IF(F20="Ahli Madya",60,IF(F20="Ahli Utama",65,58)) -> 65 | H20: =DATE(YEAR(X20)+G20,MONTH(X20)+1,1) -> 45809 | J20: ASN | K20: PNS | L20: PNS | M20: L | N20: IV/c | O20: 4C | P20: 01-04-2021 | R20: 32 | S20: 0 | U20: 333 | V20: E. 652160 | W20: Jakarta | X20: 21-05-1960 | Y20: =YEAR(NOW())-YEAR(X20) -> #VALUE! | Z20: =IF(AND(Y20>=21,Y20<=35),"21-35",IF(AND(Y20>35,Y20<=45),"36-45",IF(AND(Y20>45,Y20<=58),"46-58",IF(Y20>58,"Lebih dari 58",0)))) -> #VALUE! | AB20: Dokter Spesialis Emergency Medicine | AC20: DOKTER SPESIALIS | AD20: TENAGA MEDIS | AE20: KSM Umum | AF20: MDS | AG20: A | AH20: A | AI20: FELLOW / MS | AJ20: 0321380013-08 | AK20: 194/UB/FK/Sp1/2008 | AL20: 27-06-2008 | AM20: Universitas Brawijaya Malang | AP20: Instalasi Gawat Darurat | AQ20: 09-10-2018 | AR20: MANAJEMEN | AS20: MANAJEMEN | AT20: =_xlfn.IFNA(VLOOKUP(D20,'[1]5. 1 Mei 2022'!$C$7:$F$60,4,FALSE),"") | AU20: Kepala Instalasi | AV20: Kepala Instalasi Gawat Darurat | AW20: 14-02-2022 | AX20: =AW20+1903 -> 46509 | AY20: Direktorat Pelayanan Medik, Keperawatan, dan Penunjang | AZ20: IGD | BA20: Instalasi Gawat Darurat | BD20: KA_INST | BE20: MDS | BF20: Kepala Instalasi Gawat Darurat | BI20: DR | BJ20: Dokter Pendidik Klinis Ahli Utama | BK20: =N20 -> IV/c | BL20: JFT | BP20: - | BQ20: Dokter Pendidik Klinis Ahli Utama | BR20: 27-04-2020 | BT20: 01-12-1989 | BV20: 01-04-1992 | BW20: =YEAR(NOW())-YEAR(BV20) -> 31 | BX20: =DATEDIF(BV20,NOW(),"YM") -> 3 | BZ20: AB 00032984 | CA20: Islam | CB20: Menikah | CC20: 3 | CD20: 1 | CE20: Menanggung | CH20: 2007 | CI20: 67/TK/TAHUN 2011 | CL20: 3511403421029138 | CM20: 21-05-2026 | CN20: 126 | CO20: 208/B.15B/31.74.06.1001.05.023.S.2/3/-1.779.3/e/2022 | CP20: 21-05-2026 | CQ20: 126 | CR20: 2168 | CS20: Benar lulusan dokter umum Universitas Trisakti // Benar lulusan Spesialis Emergency Medicine Universitas Brawijaya | CT20: 0 // 15531/UN 10.7/AK/2013 | CU20: 29-08-2013 // 31-12-2013 | CV20: KP.00.02/II.4/4054/2013 | CW20: Spesialis Emergency Medicine Universitas Brawijaya | CX20: 03-12-2013 | CY20: KP.00.02/II.4/2734/2013 | CZ20: Dokter Umum Universitas Trisakti | DA20: 29-07-2013 | DB20: Dicek Melalui Website KKI | DE20: 2022 | DF20: SIP Sudah terbit | DG20: 11368/-1.777.11 | DH20: 29-11-2013 | DI20: KP.00.02/II.4/6882/2015 | DJ20: 25-11-2015 | DK20: HK.02.03/VIII.2/9541/2019 | DL20: 29-07-2019 | DM20: 68.658.213.1-432.000 | DO20: 0 | DP20: 3275042105600005 | DQ20: Pondok Pekayon Indah D.XI No.3 Rt. 004 / 010 Kel. Pekayon Jaya Kec. Bekasi Selatan | DS20: 0817388878 | DT20: drugisugiri@gmail.com | DU20: 3 | DV20: Moderna | DY20: 10575/2022 | DZ20: 44771 | EA20: 45867 | EB20: 0 | EC20: Dokter Spesialis | ED20: MANAJERIAL | EE20: Universitas Trisakti | EF20: Universitas Brawijaya Malang
A21: 19 | B21: Dra. Magdalena Niken Oktovina, Apt, M.Si | C21: PNS | D21: 196710201997032001 | F21: Ahli Madya | G21: =IF(F21="Ahli Madya",60,IF(F21="Ahli Utama",65,58)) -> 60 | H21: =DATE(YEAR(X21)+G21,MONTH(X21)+1,1) -> 46692 | J21: ASN | K21: PNS | L21: PNS | M21: P | N21: IV/c | O21: 4C | P21: 01-10-2019 | R21: 22 | S21: 7 | U21: 220 | W21: Jakarta | X21: 20-10-1967 | Y21: =YEAR(NOW())-YEAR(X21) -> #VALUE! | Z21: =IF(AND(Y21>=21,Y21<=35),"21-35",IF(AND(Y21>35,Y21<=45),"36-45",IF(AND(Y21>45,Y21<=58),"46-58",IF(Y21>58,"Lebih dari 58",0)))) -> #VALUE! | AB21: Apoteker + Magister Sains | AC21: TENAGA KESEHATAN LAIN | AD21: TENAGA KESEHATAN LAIN | AF21: TKL | AG21: A | AH21: C | AI21: S2 | AL21: 2009 | AM21: Universitas Indonesia | AP21: Instalasi Farmasi | AQ21: 42917 | AR21: MANAJEMEN | AS21: MANAJEMEN | AT21: =_xlfn.IFNA(VLOOKUP(D21,'[1]5. 1 Mei 2022'!$C$7:$F$60,4,FALSE),"") | AU21: Kepala Instalasi | AV21: Kepala Intalasi Farmasi | AW21: 14-02-2022 | AX21: =AW21+1903 -> 46509 | AY21: Direktorat Pelayanan Medik, Keperawatan, dan Penunjang | AZ21: I_FARMASI | BA21: Instalasi Farmasi | BD21: KA_INST | BE21: PM | BF21: Kepala Instalasi Farmasi | BI21: APT | BJ21: Apoteker Ahli Madya | BK21: =N21 -> IV/c | BL21: JFT | BQ21: Apoteker Ahli Madya | BR21: 01-04-2019 | BS21: 726.2880 | BT21: 01-03-1997 | BU21: 01-03-1999 | BV21: 01-12-2010 | BW21: =YEAR(NOW())-YEAR(BV21) -> 13 | BX21: =DATEDIF(BV21,NOW(),"YM") -> 2 | CA21: Kristen Protestan | CB21: Menikah | CC21: 3 | CD21: 1 | CE21: Menanggung | CL21: 19671020/STRA-UI/1993/26129 | CM21: 20-10-2026 | CN21: 126 | CO21: 42/B.19/31.74.06.1001.05.023.S.2.a.b/3/-1.779.3/e/2022 | CP21: 20-10-2026 | CQ21: 126 | CR21: 4406 | CS21: Benar Lulusan S2 Ilmu Kefarmasian FMIPA UI | CT21: 1188/H2.F3/PDP.03.01.05/2012 | CU21: 07-11-2012 | CV21: KP.00.02/II.4/2832/2012 | CW21: S2 Farmasi Klinik UI | CX21: 16-10-2012 | DB21: Benar STRA dikeluarkan oleh Komite Farmasi Nasional | DC21: UM.01.05/KF/348/2019 | DD21: 25-09-2019 | DE21: 2021 | DI21: HK.02.03/VIII.2/11705/2019 | DJ21: 04-09-2019 | DM21: 68.851.725.9-412.000 | DO21: 0 | DP21: 3276036010670006 | DQ21: Kel. Serua Rt. 002 / 001 Kel. Serua Kec. Bojongsari Depok | DS21: 081286551661 | DT21: lenasanjaya1@gmail.com | DU21: 3 | DV21: Moderna | DY21: 13469/2022 | DZ21: 20-12-2021 | EA21: 20-10-2024 | EB21: 0 | EC21: Pharmacist | ED21: MANAJERIAL
A22: 20 | B22: Ns. Minarni, S.Kep, M.Kes | C22: 140208301 | D22: 196705111988032002 | F22: Ahli Madya | G22: =IF(F22="Ahli Madya",60,IF(F22="Ahli Utama",65,58)) -> 60 | H22: =DATE(YEAR(X22)+G22,MONTH(X22)+1,1) -> 46539 | J22: ASN | K22: PNS | L22: PNS | M22: P | N22: IV/b | O22: 4B | P22: 01-04-2020 | R22: 28 | S22: 8 | U22: 963 | W22: Kulon Progo | X22: 11-05-1967 | Y22: =YEAR(NOW())-YEAR(X22) -> 56 | Z22: =IF(AND(Y22>=21,Y22<=35),"21-35",IF(AND(Y22>35,Y22<=45),"36-45",IF(AND(Y22>45,Y22<=58),"46-58",IF(Y22>58,"Lebih dari 58",0)))) -> 46-58 | AB22: Magister Kesehatan Masyarakat | AC22: PERAWAT | AD22: PERAWAT | AF22: PRW | AG22: B | AH22: B | AI22: S2 | AJ22: 20140000177 | AK22: No.502/S2-KESMAS/STIKIM/2017 | AL22: 13-03-2017 | AM22: STIKES INDONESIA MAJU | AP22: Instalasi Sterilisasi Sentral dan Binatu | AQ22: 01-08-2019 | AR22: MANAJEMEN | AS22: MANAJEMEN | AT22: =_xlfn.IFNA(VLOOKUP(D22,'[1]5. 1 Mei 2022'!$C$7:$F$60,4,FALSE),"") | AU22: Kepala Instalasi | AV22: Kepala Instalasi Sterilisasi dan Binatu | AW22: 14-02-2022 | AX22: =AW22+1903 -> 46509 | AY22: Direktorat Perencanaan, Organisasi, dan Umum | AZ22: ISSB | BA22: Instalasi Sterilisasi Sentral dan Binatu | BD22: KA_INST | BE22: MJ | BF22: Kepala Instalasi Sterilisasi dan Binatu | BI22: PER | BJ22: Perawat Ahli Madya | BK22: =N22 -> IV/b | BL22: JFT | BP22: - | BQ22: Perawat Ahli Madya | BR22: 01-08-2019 | BS22: 559.6080 | BT22: 01-03-1988 | BV22: 01-08-1986 | BW22: =YEAR(NOW())-YEAR(BV22) -> 37 | BX22: =DATEDIF(BV22,NOW(),"YM") -> 3 | CA22: Islam | CB22: Menikah | CC22: 2 | CD22: 1 | CE22: Menanggung | CG22: 2004 | CH22: 2004 dan 2008 | CI22: 2008 | CJ22: 222/MENKES/SK/VII/2012 | CL22: 120172217-1423813 | CM22: 05-11-2022 | CN22: 122 | CO22: 322/B.16/31.74.06.1001/-1.779.3/e/2019 | CP22: 05-11-2022 | CQ22: 122 | CR22: 3704 | CS22: Dicek Melalui Situs Pangkalan Data Pendidikan Tinggi (Ners) // Dicek Melalui Forlap Dikti (S2) | CV22: KP.00.02/II.4/553/2012 // KP.00.02/II.4/589/2014 | CW22: 0 // S1 Keperawatan Universitas Muhammadiyah Jakarta | CX22: 29-02-2012 // 21-01-2014 | DB22: STR Tenaga Perawat Benar Dikeluarkan oleh MTKI | DC22: TU.08.01/MTKI/335/2013 | DD22: 20-05-2013 | DI22: HK.02.03/VIII.2/9651/2019 | DJ22: 30-07-2019 | DK22: HK.02.03/VIII.2/16164/2019 | DL22: 13-11-2019 | DM22: 78.451.793.0-411.000 | DO22: 3674062808200022 | DP22: 3674065105670006 | DQ22: Jl. Bratasena IX Blok T-5/12 Rt. 007 / 014 Kel. Pondok Benda Kec. Pamulang Tangerang Selatan | DS22: 081212880704 | DT22: minarni.dali@yahoo.com | DU22: 3 | DV22: Moderna | DX22: PK4 | DY22: 4638/2021 | DZ22: 31-03-2021 | EB22: 0 | EC22: Tenaga Perawat | ED22: MANAJERIAL
