Workbook
Name _select_from_SELECT_max_sakti_sakti_kode_klp_as_sakti_kode_klp_m_202303280648: migrasiSAwal!$A$1:$P$35
Name _select_from_SELECT_max_sakti_sakti_kode_klp_as_sakti_kode_klp_m_202303280652: selisihMinus!$A$1:$P$1346
Name _select_from_SELECT_max_sakti_sakti_kode_klp_as_sakti_kode_klp_m_202303280655: selisihPlus!$A$1:$P$394
Name _select_from_SELECT_max_sakti_sakti_kode_klp_as_sakti_kode_klp_m_202303280658: selisihNol!$A$1:$P$2634
Name _SELECT_max_sakti_sakti_kode_klp_as_sakti_kode_klp_max_sakti_sak_202303280642: Total!$A$1:$P$4405

Sheet Statistik
B2: URAIAN | C2: SAKTI | F2: SIMRS
C3: Saldo Awal | D3: TakTermigrasi | E3: Saldo Akhir | F3: SaldoAkhir | G3: Pembulatan
B4: TOTAL | C4: =Total!E4406 -> 7084287 | D4: =Total!F4406 -> 40926 | E4: =Total!G4406 -> 3194659 | F4: =Total!I4406 -> 3273671 | G4: =Total!I4406-Total!H4406 -> 57.58
B5: migrasSAwal | C5: =migrasiSAwal!E36 -> 0 | D5: =migrasiSAwal!F36 -> 39687 | E5: =migrasiSAwal!G36 -> 0 | F5: =migrasiSAwal!I36 -> 20235 | G5: =migrasiSAwal!I36-migrasiSAwal!H36 -> 0
B6: selisihMinus | C6: =selisihMinus!E1347 -> 3792854 | D6: =selisihMinus!F1347 -> 789 | E6: =selisihMinus!G1347 -> 2035359 | F6: =selisihMinus!I1347 -> 1467366 | G6: =selisihMinus!I1347-selisihMinus!H1347 -> 44.4
B7: selisihPlus | C7: =selisihPlus!E395 -> 1639516 | D7: =selisihPlus!F395 -> 406 | E7: =selisihPlus!G395 -> 500514 | F7: =selisihPlus!I395 -> 1127284 | G7: =selisihPlus!I395-selisihPlus!H395 -> 13.18
B8: selisihNol (cocok) | C8: =selisihNol!E2635 -> 1651917 | D8: =selisihNol!F2635 -> 44 | E8: =selisihNol!G2635 -> 658786 | F8: =selisihNol!I2635 -> 658786 | G8: =selisihNol!I2635-selisihNol!H2635 -> 0
B9: HITUNG TOTAL | C9: =C5+C6+C7+C8 -> 7084287 | D9: =D5+D6+D7+D8 -> 40926 | E9: =E5+E6+E7+E8 -> 3194659 | F9: =F5+F6+F7+F8 -> 3273671 | G9: =G5+G6+G7+G8 -> 57.58

Sheet Total
A1: sakti_kode_klp | B1: sakti_kode | C1: katalog_grp | D1: sakti_grp | E1: qty_awal | F1: sakti_awal_add | G1: sakti_akhir | H1: simrs_akhir | I1: pembulatan | J1: simrs_trx | K1: selisih_abs | L1: selisih | M1: katalog_kode | N1: katalog_nama | O1: sakti_nama | P1: sakti_nama_klp
A2: 1010401002 | B2: 000478 | C2: 1 | D2: 1 | E2: 17589 | F2: 0 | G2: 5887 | H2: 9490 | I2: 9490 | J2: 3603 | K2: 3603 | L2: 3603 | M2: 10A025 | N2: ADALAT OROS TAB 30 MG | O2: ADALAT OROS TAB 30 MG | P2: OBAT PADAT (PERSEDIAAN LAINNYA)
A3: 1010401002 | B3: 000477 | C3: 1 | D3: 1 | E3: 259 | F3: 0 | G3: 7 | H3: 7 | I3: 7 | J3: 0 | K3: 0 | L3: 0 | M3: 10A044 | N3: ALLORIS TABLET 10 MG | O3: ALLORIS TABLET 10 MG | P3: OBAT PADAT (PERSEDIAAN LAINNYA)
A4: 1010401002 | B4: 000548 | C4: 2 | D4: 2 | E4: 24685 | F4: 0 | G4: 3234 | H4: 1994.67 | I4: 1995 | J4: -1239.33 | K4: 1239.33 | L4: -1239.33 | M4: 10A054 | N4: AMBROXOL 30 mg | O4: AMBROXOL TAB 30MG | P4: OBAT PADAT (PERSEDIAAN LAINNYA)
A5: 1010401002 | B5: 000474 | C5: 1 | D5: 1 | E5: 112934 | F5: 0 | G5: 64 | K5: 64 | L5: -64 | M5: 10A059 | N5: AMLODIPIN TAB 5 MG | O5: AMLODIPIN TAB 5 MG | P5: OBAT PADAT (PERSEDIAAN LAINNYA)
A6: 1010401002 | B6: 000473 | C6: 1 | D6: 1 | E6: 81 | F6: 0 | G6: 0 | K6: 0 | L6: 0 | M6: 10A085 | N6: ARCALION 200 TAB | O6: ARCALION 200 TAB | P6: OBAT PADAT (PERSEDIAAN LAINNYA)
A7: 1010401002 | B7: 000472 | C7: 1 | D7: 1 | E7: 30983 | F7: 0 | G7: 0 | K7: 0 | L7: 0 | M7: 10A095 | N7: ASAM FOLAT 1 MG | O7: ASAM FOLAT 1 MG | P7: OBAT PADAT (PERSEDIAAN LAINNYA)
A8: 1010401002 | B8: 000570 | C8: 1 | D8: 1 | E8: 0 | F8: 0 | G8: 545 | H8: 525 | I8: 525 | J8: -20 | K8: 20 | L8: -20 | M8: 10A097.1 | N8: ARIPIPRAZOLE TAB 5MG | O8: ARIPIPRAZOLE TAB 5MG | P8: OBAT PADAT (PERSEDIAAN LAINNYA)
A9: 1010401002 | B9: 000055 | C9: 1 | D9: 1 | E9: 265 | F9: 0 | G9: 0 | K9: 0 | L9: 0 | M9: 10A098 | N9: ASCARDIA TABLET SALUT ENTERIK 80 MG | O9: ASCARDIA TABLET SALUT ENTERIK 80 MG | P9: OBAT PADAT (PERSEDIAAN LAINNYA)
A10: 1010401002 | B10: 000003 | C10: 1 | D10: 1 | E10: 22 | F10: 0 | G10: 31 | H10: 30 | I10: 30 | J10: -1 | K10: 1 | L10: -1 | M10: 10A105 | N10: ASPILETS 80 MG TAB | O10: ASPILETS 80 MG TAB | P10: OBAT PADAT (PERSEDIAAN LAINNYA)
A11: 1010401002 | B11: 000471 | C11: 1 | D11: 1 | E11: 295 | F11: 0 | G11: 0 | K11: 0 | L11: 0 | M11: 10A112 | N11: ATIVAN TAB 1 MG | O11: ATIVAN TAB 1 MG | P11: OBAT PADAT (PERSEDIAAN LAINNYA)
A12: 1010401002 | B12: 000470 | C12: 1 | D12: 1 | E12: 0 | F12: 0 | G12: 5 | K12: 5 | L12: -5 | M12: 10A128 | N12: ARDIUM TAB 500 MG | O12: ARDIUM TAB 500 MG | P12: OBAT PADAT (PERSEDIAAN LAINNYA)
A13: 1010401002 | B13: 000469 | C13: 1 | D13: 1 | E13: 539 | F13: 0 | G13: 90 | H13: 70 | I13: 70 | J13: -20 | K13: 20 | L13: -20 | M13: 10A161 | N13: ANALSIK | O13: ANALSIK | P13: OBAT PADAT (PERSEDIAAN LAINNYA)
A14: 1010401002 | B14: 000468 | C14: 1 | D14: 1 | E14: 326 | F14: 0 | G14: 20 | H14: 20 | I14: 20 | J14: 0 | K14: 0 | L14: 0 | M14: 10A164 | N14: ARCOXIA TAB 60 MG | O14: ARCOXIA TAB 60 MG | P14: OBAT PADAT (PERSEDIAAN LAINNYA)
A15: 1010401002 | B15: 000467 | C15: 1 | D15: 1 | E15: 107 | F15: 0 | G15: 1 | K15: 1 | L15: -1 | M15: 10A165 | N15: ARCOXIA TAB 90 MG | O15: ARCOXIA TAB 90 MG | P15: OBAT PADAT (PERSEDIAAN LAINNYA)
A16: 1010401002 | B16: 000466 | C16: 1 | D16: 1 | E16: 123 | F16: 0 | G16: 26 | H16: 10 | I16: 10 | J16: -16 | K16: 16 | L16: -16 | M16: 10A166 | N16: ARCOXIA TAB 120 MG | O16: ARCOXIA TAB 120 MG | P16: OBAT PADAT (PERSEDIAAN LAINNYA)
A17: 1010401002 | B17: 000465 | C17: 1 | D17: 1 | E17: 20 | F17: 0 | G17: 0 | K17: 0 | L17: 0 | M17: 10A171 | N17: ABBOTIC XL TAB 500 MG | O17: ABBOTIC XL TAB 500 MG | P17: OBAT PADAT (PERSEDIAAN LAINNYA)
A18: 1010401002 | B18: 000023 | C18: 1 | D18: 1 | E18: 244 | F18: 0 | G18: 0 | K18: 0 | L18: 0 | M18: 10A175 | N18: ABILIFY 10 MG TAB | O18: ABILIFY 10 MG TAB | P18: OBAT PADAT (PERSEDIAAN LAINNYA)
A19: 1010401002 | B19: 000518 | C19: 1 | D19: 1 | E19: 0 | F19: 0 | G19: 0 | K19: 0 | L19: 0 | M19: 10A176 | N19: ABILIFY 15 MG TAB | O19: ABILIFY 15 MG TAB | P19: OBAT PADAT (PERSEDIAAN LAINNYA)
A20: 1010401002 | B20: 000464 | C20: 1 | D20: 1 | E20: 7222 | F20: 0 | G20: 19 | H20: 19 | I20: 19 | J20: 0 | K20: 0 | L20: 0 | M20: 10A177 | N20: AVODART TAB 0.5 MG | O20: AVODART TAB 0.5 MG | P20: OBAT PADAT (PERSEDIAAN LAINNYA)
A21: 1010401002 | B21: 000463 | C21: 1 | D21: 1 | E21: 75 | F21: 0 | G21: 40 | H21: 40 | I21: 40 | J21: 0 | K21: 0 | L21: 0 | M21: 10A185 | N21: ARTRODAR CAP 50 MG | O21: ARTRODAR CAP 50 MG | P21: OBAT PADAT (PERSEDIAAN LAINNYA)
A22: 1010401002 | B22: 000455 | C22: 1 | D22: 1 | E22: 72215 | F22: 0 | G22: 40485 | K22: 40485 | L22: -40485 | M22: 10A191 | N22: ATORVASTATIN TAB 20 MG | O22: ATORVASTATIN TABLET 20 MG | P22: OBAT PADAT (PERSEDIAAN LAINNYA)
A23: 1010401002 | B23: 000462 | C23: 1 | D23: 1 | E23: 447 | F23: 0 | G23: 300 | H23: 285 | I23: 285 | J23: -15 | K23: 15 | L23: -15 | M23: 10A192 | N23: ACPULSIF TAB 5 MG | O23: ACPULSIF TAB 5 MG | P23: OBAT PADAT (PERSEDIAAN LAINNYA)
A24: 1010401002 | B24: 000461 | C24: 1 | D24: 1 | E24: 23 | F24: 0 | G24: 0 | H24: 0 | I24: 0 | J24: 0 | K24: 0 | L24: 0 | M24: 10A200 | N24: AERIUS TAB 5 MG | O24: AERIUS TAB 5 MG | P24: OBAT PADAT (PERSEDIAAN LAINNYA)
A25: 1010401002 | B25: 000571 | C25: 1 | D25: 1 | E25: 0 | F25: 0 | G25: 300 | H25: 300 | I25: 300 | J25: 0 | K25: 0 | L25: 0 | M25: 10A201 | N25: ARIPIPRAZOLE TAB DISPERSIBEL 10MG | O25: ARIPIPRAZOLE TAB DISPERSIBEL 10MG | P25: OBAT PADAT (PERSEDIAAN LAINNYA)
A26: 1010401002 | B26: 000081 | C26: 1 | D26: 1 | E26: 156 | F26: 0 | G26: 37 | H26: 21 | I26: 21 | J26: -16 | K26: 16 | L26: -16 | M26: 10A203 | N26: ALBENDAZOLE TAB 400 MG | O26: ALBENDAZOLE TAB 400 MG | P26: OBAT PADAT (PERSEDIAAN LAINNYA)
A27: 1010401002 | B27: 000460 | C27: 1 | D27: 1 | E27: 75 | F27: 0 | G27: 35 | K27: 35 | L27: -35 | M27: 10A204 | N27: ALERTEN Q25 CAP | O27: ALERTEN Q25 CAP | P27: OBAT PADAT (PERSEDIAAN LAINNYA)
A28: 1010401999 | B28: 003414 | C28: 2 | D28: 2 | E28: 9285 | F28: 0 | G28: 149 | H28: 4 | I28: 4 | J28: -66 | K28: 145 | L28: -145 | M28: 10A249 | N28: AZITROMISIN TABLET 500 MG | O28: AZITROMISIN TABLET 500 MG | P28: OBAT PADAT (PERSEDIAAN LAINNYA)
A29: 1010401999 | B29: 003571 | C29: 1 | D29: 1 | E29: 62017 | F29: 0 | G29: 10412 | H29: 3587.5 | I29: 3588 | J29: -6824.5 | K29: 6824.5 | L29: -6824.5 | M29: 10A250 | N29: ASAM MEFENAMAT 500 MG TABLET | O29: ASAM MEFENAMAT 500 MG TABLET | P29: OBAT LAINNYA (PERSEDIAAN LAINNYA)
A30: 1010401002 | B30: 000457 | C30: 1 | D30: 1 | E30: 47 | F30: 0 | G30: 26 | K30: 26 | L30: -26 | M30: 10A253 | N30: ABIXA 10 MG TAB | O30: ABIXA 10 MG TAB | P30: OBAT PADAT (PERSEDIAAN LAINNYA)
A31: 1010401999 | B31: 000351 | C31: 2 | D31: 2 | E31: 142889 | F31: 0 | G31: 0 | H31: 10279 | I31: 10279 | J31: 10279 | K31: 10279 | L31: 10279 | M31: 10A254 | N31: ACETYLCYSTEIN 200 MG CAPSUL | O31: ACETYLCYSTEIN 200 MG CAPSUL | P31: OBAT PADAT (PERSEDIAAN LAINNYA)
A32: 1010401002 | B32: 000456 | C32: 1 | D32: 1 | E32: 1702 | F32: 0 | G32: 0 | K32: 0 | L32: 0 | M32: 10A255 | N32: ALPENTIN 100 MG CAPS | O32: ALPENTIN 100 MG CAPS | P32: OBAT PADAT (PERSEDIAAN LAINNYA)
A33: 1010401002 | B33: 000454 | C33: 1 | D33: 1 | E33: 23983 | F33: 0 | G33: 11421 | H33: 20516 | I33: 20516 | J33: 9095 | K33: 9095 | L33: 9095 | M33: 10A258 | N33: ACARBOSE TABLET 100 MG | O33: ACARBOSE TABLET 100 MG | P33: OBAT PADAT (PERSEDIAAN LAINNYA)
A34: 1010401002 | B34: 000453 | C34: 1 | D34: 1 | E34: 6364 | F34: 0 | G34: 3709 | H34: 6414 | I34: 6414 | J34: 2705 | K34: 2705 | L34: 2705 | M34: 10A259 | N34: ACARBOSE TAB 50 MG | O34: ACARBOSE TAB 50 MG | P34: OBAT PADAT (PERSEDIAAN LAINNYA)
A35: 1010401002 | B35: 000452 | C35: 1 | D35: 1 | E35: 30738 | F35: 0 | G35: 5686 | H35: 3014 | I35: 3014 | J35: -2037 | K35: 2672 | L35: -2672 | M35: 10A260 | N35: ALLOPURINOL TAB 100 MG | O35: ALLOPURINOL TAB 100 MG | P35: OBAT PADAT (PERSEDIAAN LAINNYA)
A36: 1010401999 | B36: 001047 | C36: 2 | D36: 2 | E36: 90854 | F36: 0 | G36: 3193 | K36: 3193 | L36: -3193 | M36: 10A261 | N36: AMLODIPIN TAB 10 MG | O36: AMLODIPINE TAB 10MG | P36: OBAT PADAT (PERSEDIAAN LAINNYA)
A37: 1010401002 | B37: 000450 | C37: 1 | D37: 1 | E37: 2881 | F37: 0 | G37: 1173 | H37: 663 | I37: 663 | J37: -510 | K37: 510 | L37: -510 | M37: 10A269 | N37: ARICEPT TABLET 10 MG | O37: ARICEPT TABLET 10 MG | P37: OBAT PADAT (PERSEDIAAN LAINNYA)
A38: 1010401002 | B38: 000449 | C38: 1 | D38: 1 | E38: 1188 | F38: 0 | G38: 92 | H38: 4.25 | I38: 5 | J38: -88 | K38: 87.75 | L38: -87.75 | M38: 10A275 | N38: ALPRAZOLAM TABLET 0,5 MG | O38: ALPRAZOLAM TABLET 0,5 MG | P38: OBAT PADAT (PERSEDIAAN LAINNYA)
A39: 1010401002 | B39: 000480 | C39: 2 | D39: 2 | E39: 161 | F39: 0 | G39: 3783 | H39: 2870.99 | I39: 2871 | J39: -912.01 | K39: 912.01 | L39: -912.01 | M39: 10A276 | N39: AMITRIPTILINE TABLET 25 MG | O39: AMITRIPTYLLINE TAB 25 MG | P39: OBAT PADAT (PERSEDIAAN LAINNYA)
A40: 1010401002 | B40: 000538 | C40: 1 | D40: 1 | E40: 0 | F40: 0 | G40: 0 | K40: 0 | L40: 0 | M40: 10A279 | N40: AMOXYCILLIN TAB 500 MG | O40: AMOXYCILLIN TAB 500 MG | P40: OBAT PADAT (PERSEDIAAN LAINNYA)
...

Sheet migrasiSAwal
A1: sakti_kode_klp | B1: sakti_kode | C1: katalog_grp | D1: sakti_grp | E1: qty_awal | F1: sakti_awal_add | G1: sakti_akhir | H1: simrs_akhir | I1: pembulatan | J1: simrs_trx | K1: selisih_abs | L1: selisih | M1: katalog_kode | N1: katalog_nama | O1: sakti_nama | P1: sakti_nama_klp
C2: 1 | D2: 0 | E2: 0 | F2: 255 | G2: 0 | K2: 0 | L2: 0 | M2: 10F149 | N2: FUROSEMID 40 MG TAB | O2: FUROSEMID 40 MG TAB | P2: Obat Padat(Persediaan Lainnya)
C3: 1 | D3: 0 | E3: 0 | F3: 5 | G3: 0 | K3: 0 | L3: 0 | M3: 10H023.14174 | N3: HERBESSER AMPUL 5 MG / ML 5 ML | O3: HERBESSER AMPUL 5 MG / ML 5 ML | P3: Obat Cair(Persediaan Lainnya)
C4: 1 | D4: 0 | E4: 0 | F4: 18 | G4: 0 | K4: 0 | L4: 0 | M4: 10H079 | N4: HYOSCINE INJ INJEKSI 20MG/ML, AMPUL @ 1 ML | O4: HYOSCINE INJ INJEKSI 20MG/ML, AMPUL @ 1 ML | P4: Obat Cair(Persediaan Lainnya)
C5: 1 | D5: 0 | E5: 0 | F5: 3 | G5: 0 | K5: 0 | L5: 0 | M5: 10W004 | N5: WARFARIN NA TABLET 1 MG | O5: WARFARIN NA TABLET 1 MG | P5: Obat Padat(Persediaan Lainnya)
C6: 1 | D6: 0 | E6: 0 | F6: 31 | G6: 0 | K6: 0 | L6: 0 | M6: 14E003 | N6: EFEPOETIN ALFA 0,6 MG (P) | O6: EFEPOETIN ALFA 0,6 MG (P) | P6: Obat Lainnya(Persediaan Lainnya)
C7: 1 | D7: 0 | E7: 0 | F7: 7 | G7: 0 | K7: 0 | L7: 0 | M7: 14E004 | N7: EFEPOETIN ALFA 1 MG (P) | O7: EFEPOETIN ALFA 1 MG (P) | P7: Obat Lainnya(Persediaan Lainnya)
C8: 1 | D8: 0 | E8: 0 | F8: 130 | G8: 0 | K8: 0 | L8: 0 | M8: 14F014 | N8: FG TROCHES BNPB | O8: FG TROCHES BNPB | P8: Obat Lainnya(Persediaan Lainnya)
C9: 1 | D9: 0 | E9: 0 | F9: 320 | G9: 0 | K9: 0 | L9: 0 | M9: 14H014 | N9: HEMAVITON STAMINA PLUS TAB BNPB | O9: HEMAVITON STAMINA PLUS TAB BNPB | P9: Obat Lainnya(Persediaan Lainnya)
C10: 1 | D10: 0 | E10: 0 | F10: 1 | G10: 0 | K10: 0 | L10: 0 | M10: 14I004 | N10: IMBOOST KIDS REG 60ML BNPB | O10: IMBOOST KIDS REG 60ML BNPB | P10: Obat Lainnya(Persediaan Lainnya)
C11: 1 | D11: 0 | E11: 0 | F11: 84 | G11: 0 | H11: 84 | I11: 84 | J11: 0 | K11: 84 | L11: 84 | M11: 14L012 | N11: LIANHUA QINGWEN CAPSULES @12 TABLET | O11: LIANHUA QINGWEN CAPSULES @12 TABLET | P11: Obat Lainnya(Persediaan Lainnya)
C12: 1 | D12: 0 | E12: 0 | F12: 14 | G12: 0 | K12: 0 | L12: 0 | M12: 14M003 | N12: MIRCERA 50 MCG (P) | O12: MIRCERA 50 MCG (P) | P12: Obat Lainnya(Persediaan Lainnya)
C13: 1 | D13: 0 | E13: 0 | F13: 6850 | G13: 0 | K13: 0 | L13: 0 | M13: 14M014.1 | N13: MULTIVITAMIN & MINERAL (COVID-19) | O13: MULTIVITAMIN & MINERAL (COVID-19) | P13: Obat Lainnya(Persediaan Lainnya)
C14: 1 | D14: 0 | E14: 0 | F14: 6 | G14: 0 | K14: 0 | L14: 0 | M14: 14M019 | N14: MIRCERA 100 MCG (P) | O14: MIRCERA 100 MCG (P) | P14: Obat Lainnya(Persediaan Lainnya)
C15: 1 | D15: 0 | E15: 0 | F15: 19876 | G15: 0 | H15: 15854 | I15: 15854 | J15: -126 | K15: 15854 | L15: 15854 | M15: 14N004 | N15: NORMUDAL 2MG TABLET BNPB | O15: NORMUDAL 2MG TABLET BNPB | P15: Obat Lainnya(Persediaan Lainnya)
C16: 1 | D16: 0 | E16: 0 | F16: 15 | G16: 0 | K16: 0 | L16: 0 | M16: 14N006 | N16: NACL 0,9% 500 ML (P) | O16: NACL 0,9% 500 ML (P) | P16: Obat Lainnya(Persediaan Lainnya)
C17: 1 | D17: 0 | E17: 0 | F17: 16 | G17: 0 | K17: 0 | L17: 0 | M17: 14O004 | N17: OBH COMBI BATUK FLU MADU 100ML BNPB | O17: OBH COMBI BATUK FLU MADU 100ML BNPB | P17: Obat Lainnya(Persediaan Lainnya)
C18: 1 | D18: 0 | E18: 0 | F18: 1 | G18: 0 | H18: 2 | I18: 2 | J18: 0 | K18: 2 | L18: 2 | M18: 14P014 | N18: PAKET DLBS (P) | O18: PAKET DLBS (P) | P18: Obat Lainnya(Persediaan Lainnya)
C19: 1 | D19: 0 | E19: 0 | F19: 204 | G19: 0 | K19: 0 | L19: 0 | M19: 14S005 | N19: SUCRALFATE TABLET 500MG BNPB | O19: SUCRALFATE TABLET 500MG BNPB | P19: Obat Lainnya(Persediaan Lainnya)
C20: 1 | D20: 0 | E20: 0 | F20: 7228 | G20: 0 | H20: 4080 | I20: 4080 | J20: 0 | K20: 4080 | L20: 4080 | M20: 14S006 | N20: SP TROCHES BNPB | O20: SP TROCHES BNPB | P20: Obat Lainnya(Persediaan Lainnya)
C21: 1 | D21: 0 | E21: 0 | F21: 330 | G21: 0 | K21: 0 | L21: 0 | M21: 14S010 | N21: SANGOBION CAPSUL(P) | O21: SANGOBION CAPSUL(P) | P21: Obat Lainnya(Persediaan Lainnya)
C22: 1 | D22: 0 | E22: 0 | F22: 90 | G22: 0 | K22: 0 | L22: 0 | M22: 14V008 | N22: VERMINT CAPSUL BNPB | O22: VERMINT CAPSUL BNPB | P22: Obat Lainnya(Persediaan Lainnya)
C23: 1 | D23: 0 | E23: 0 | F23: 1 | G23: 0 | K23: 0 | L23: 0 | M23: 30K020 | N23: KETOPROFEN SUPP 100 MG | O23: KETOPROFEN SUPP 100 MG | P23: Obat Gel/Salep(Persediaan Lainnya)
C24: 1 | D24: 0 | E24: 0 | F24: 30 | G24: 0 | K24: 0 | L24: 0 | M24: 40E039 | N24: ECOSOL NACL 500 ML (S) | O24: ECOSOL NACL 500 ML (S) | P24: Obat Lainnya(Persediaan Lainnya)
C25: 1 | D25: 0 | E25: 0 | F25: 2 | G25: 0 | K25: 0 | L25: 0 | M25: 40N058 | N25: NEFROFER INJ 100 MG/5 ML | O25: NEFROFER INJ 100 MG/5 ML | P25: Obat Cair(Persediaan Lainnya)
C26: 1 | D26: 0 | E26: 0 | F26: 8 | G26: 0 | H26: 114 | I26: 114 | J26: -9 | K26: 114 | L26: 114 | M26: 80E033.2 | N26: ELECTRODE KHUSUS NEONATUS | O26: ELECTRODE KHUSUS NEONATUS | P26: Alat/Obat Kontrasepsi Keluarga Berencana(Persediaan Lainnya)
C27: 1 | D27: 0 | E27: 0 | F27: 1 | G27: 0 | H27: 1 | I27: 1 | J27: 0 | K27: 1 | L27: 1 | M27: 80K102 | N27: KERTAS CTG / ECG 63 MM X 30 M ALPHA | O27: KERTAS CTG / ECG 63 MM X 30 M ALPHA | P27: Alat/Obat Kontrasepsi Keluarga Berencana(Persediaan Lainnya)
C28: 1 | D28: 0 | E28: 0 | F28: 39 | G28: 0 | K28: 0 | L28: 0 | M28: 80M034.1 | N28: MATA PISAU CARBON STEEL NO 11 | O28: MATA PISAU CARBON STEEL NO 11 | P28: Obat Lainnya(Persediaan Lainnya)
C29: 1 | D29: 0 | E29: 0 | F29: 1 | G29: 0 | K29: 0 | L29: 0 | M29: 80M216 | N29: MASK ANAESTHESIA SIZE 5 | O29: MASK ANAESTHESIA SIZE 5 | P29: Obat Lainnya(Persediaan Lainnya)
C30: 1 | D30: 0 | E30: 0 | F30: 2 | G30: 0 | H30: 0 | I30: 0 | J30: 0 | K30: 0 | L30: 0 | M30: 80M219 | N30: MASK ANAESTHESIA SIZE 3 | O30: MASK ANAESTHESIA SIZE 3 | P30: Obat Lainnya(Persediaan Lainnya)
C31: 1 | D31: 0 | E31: 0 | F31: 91 | G31: 0 | K31: 0 | L31: 0 | M31: 82H003 | N31: HAZMAT COVERALL (APD) ALL SIZE (COVID-19) | O31: HAZMAT COVERALL (APD) ALL SIZE (COVID-19) | P31: Obat Lainnya(Persediaan Lainnya)
C32: 1 | D32: 0 | E32: 0 | F32: 3600 | G32: 0 | K32: 0 | L32: 0 | M32: 82H007 | N32: HANDSCHOEN DISPOSIBLE ALL SIZE (COVID-19) | O32: HANDSCHOEN DISPOSIBLE ALL SIZE (COVID-19) | P32: Obat Lainnya(Persediaan Lainnya)
C33: 1 | D33: 0 | E33: 0 | F33: 22 | G33: 0 | K33: 0 | L33: 0 | M33: 82H010 | N33: HAND SANITIZER (COVID-19) | O33: HAND SANITIZER (COVID-19) | P33: Obat Lainnya(Persediaan Lainnya)
C34: 1 | D34: 0 | E34: 0 | F34: 106 | G34: 0 | H34: 100 | I34: 100 | J34: 0 | K34: 100 | L34: 100 | M34: 82M003 | N34: MASKER N95 (COVID 19) | O34: MASKER N95 (COVID 19) | P34: Obat Lainnya(Persediaan Lainnya)
C35: 1 | D35: 0 | E35: 0 | F35: 300 | G35: 0 | K35: 0 | L35: 0 | M35: 82S006 | N35: SHOE COVER (COVID-19) | O35: SHOE COVER (COVID-19) | P35: Obat Lainnya(Persediaan Lainnya)
E36: =SUM(E2:E35) -> 0 | F36: =SUM(F2:F35) -> 39687 | G36: =SUM(G2:G35) -> 0 | H36: =SUM(H2:H35) -> 20235 | I36: =SUM(I2:I35) -> 20235

Sheet selisihMinus
A1: sakti_kode_klp | B1: sakti_kode | C1: katalog_grp | D1: sakti_grp | E1: qty_awal | F1: sakti_awal_add | G1: sakti_akhir | H1: simrs_akhir | I1: pembulatan | J1: simrs_trx | K1: selisih_abs | L1: selisih | M1: katalog_kode | N1: katalog_nama | O1: sakti_nama | P1: sakti_nama_klp
A2: 1010401002 | B2: 000548 | C2: 2 | D2: 2 | E2: 24685 | F2: 0 | G2: 3234 | H2: 1994.67 | I2: 1995 | J2: -1239.33 | K2: 1239.33 | L2: -1239.33 | M2: 10A054 | N2: AMBROXOL 30 mg | O2: AMBROXOL TAB 30MG | P2: OBAT PADAT (PERSEDIAAN LAINNYA)
A3: 1010401002 | B3: 000474 | C3: 1 | D3: 1 | E3: 112934 | F3: 0 | G3: 64 | K3: 64 | L3: -64 | M3: 10A059 | N3: AMLODIPIN TAB 5 MG | O3: AMLODIPIN TAB 5 MG | P3: OBAT PADAT (PERSEDIAAN LAINNYA)
A4: 1010401002 | B4: 000570 | C4: 1 | D4: 1 | E4: 0 | F4: 0 | G4: 545 | H4: 525 | I4: 525 | J4: -20 | K4: 20 | L4: -20 | M4: 10A097.1 | N4: ARIPIPRAZOLE TAB 5MG | O4: ARIPIPRAZOLE TAB 5MG | P4: OBAT PADAT (PERSEDIAAN LAINNYA)
A5: 1010401002 | B5: 000003 | C5: 1 | D5: 1 | E5: 22 | F5: 0 | G5: 31 | H5: 30 | I5: 30 | J5: -1 | K5: 1 | L5: -1 | M5: 10A105 | N5: ASPILETS 80 MG TAB | O5: ASPILETS 80 MG TAB | P5: OBAT PADAT (PERSEDIAAN LAINNYA)
A6: 1010401002 | B6: 000470 | C6: 1 | D6: 1 | E6: 0 | F6: 0 | G6: 5 | K6: 5 | L6: -5 | M6: 10A128 | N6: ARDIUM TAB 500 MG | O6: ARDIUM TAB 500 MG | P6: OBAT PADAT (PERSEDIAAN LAINNYA)
A7: 1010401002 | B7: 000469 | C7: 1 | D7: 1 | E7: 539 | F7: 0 | G7: 90 | H7: 70 | I7: 70 | J7: -20 | K7: 20 | L7: -20 | M7: 10A161 | N7: ANALSIK | O7: ANALSIK | P7: OBAT PADAT (PERSEDIAAN LAINNYA)
A8: 1010401002 | B8: 000467 | C8: 1 | D8: 1 | E8: 107 | F8: 0 | G8: 1 | K8: 1 | L8: -1 | M8: 10A165 | N8: ARCOXIA TAB 90 MG | O8: ARCOXIA TAB 90 MG | P8: OBAT PADAT (PERSEDIAAN LAINNYA)
A9: 1010401002 | B9: 000466 | C9: 1 | D9: 1 | E9: 123 | F9: 0 | G9: 26 | H9: 10 | I9: 10 | J9: -16 | K9: 16 | L9: -16 | M9: 10A166 | N9: ARCOXIA TAB 120 MG | O9: ARCOXIA TAB 120 MG | P9: OBAT PADAT (PERSEDIAAN LAINNYA)
A10: 1010401002 | B10: 000455 | C10: 1 | D10: 1 | E10: 72215 | F10: 0 | G10: 40485 | K10: 40485 | L10: -40485 | M10: 10A191 | N10: ATORVASTATIN TAB 20 MG | O10: ATORVASTATIN TABLET 20 MG | P10: OBAT PADAT (PERSEDIAAN LAINNYA)
A11: 1010401002 | B11: 000462 | C11: 1 | D11: 1 | E11: 447 | F11: 0 | G11: 300 | H11: 285 | I11: 285 | J11: -15 | K11: 15 | L11: -15 | M11: 10A192 | N11: ACPULSIF TAB 5 MG | O11: ACPULSIF TAB 5 MG | P11: OBAT PADAT (PERSEDIAAN LAINNYA)
A12: 1010401002 | B12: 000081 | C12: 1 | D12: 1 | E12: 156 | F12: 0 | G12: 37 | H12: 21 | I12: 21 | J12: -16 | K12: 16 | L12: -16 | M12: 10A203 | N12: ALBENDAZOLE TAB 400 MG | O12: ALBENDAZOLE TAB 400 MG | P12: OBAT PADAT (PERSEDIAAN LAINNYA)
A13: 1010401002 | B13: 000460 | C13: 1 | D13: 1 | E13: 75 | F13: 0 | G13: 35 | K13: 35 | L13: -35 | M13: 10A204 | N13: ALERTEN Q25 CAP | O13: ALERTEN Q25 CAP | P13: OBAT PADAT (PERSEDIAAN LAINNYA)
A14: 1010401999 | B14: 003414 | C14: 2 | D14: 2 | E14: 9285 | F14: 0 | G14: 149 | H14: 4 | I14: 4 | J14: -66 | K14: 145 | L14: -145 | M14: 10A249 | N14: AZITROMISIN TABLET 500 MG | O14: AZITROMISIN TABLET 500 MG | P14: OBAT PADAT (PERSEDIAAN LAINNYA)
A15: 1010401999 | B15: 003571 | C15: 1 | D15: 1 | E15: 62017 | F15: 0 | G15: 10412 | H15: 3587.5 | I15: 3588 | J15: -6824.5 | K15: 6824.5 | L15: -6824.5 | M15: 10A250 | N15: ASAM MEFENAMAT 500 MG TABLET | O15: ASAM MEFENAMAT 500 MG TABLET | P15: OBAT LAINNYA (PERSEDIAAN LAINNYA)
A16: 1010401002 | B16: 000457 | C16: 1 | D16: 1 | E16: 47 | F16: 0 | G16: 26 | K16: 26 | L16: -26 | M16: 10A253 | N16: ABIXA 10 MG TAB | O16: ABIXA 10 MG TAB | P16: OBAT PADAT (PERSEDIAAN LAINNYA)
A17: 1010401002 | B17: 000452 | C17: 1 | D17: 1 | E17: 30738 | F17: 0 | G17: 5686 | H17: 3014 | I17: 3014 | J17: -2037 | K17: 2672 | L17: -2672 | M17: 10A260 | N17: ALLOPURINOL TAB 100 MG | O17: ALLOPURINOL TAB 100 MG | P17: OBAT PADAT (PERSEDIAAN LAINNYA)
A18: 1010401999 | B18: 001047 | C18: 2 | D18: 2 | E18: 90854 | F18: 0 | G18: 3193 | K18: 3193 | L18: -3193 | M18: 10A261 | N18: AMLODIPIN TAB 10 MG | O18: AMLODIPINE TAB 10MG | P18: OBAT PADAT (PERSEDIAAN LAINNYA)
A19: 1010401002 | B19: 000450 | C19: 1 | D19: 1 | E19: 2881 | F19: 0 | G19: 1173 | H19: 663 | I19: 663 | J19: -510 | K19: 510 | L19: -510 | M19: 10A269 | N19: ARICEPT TABLET 10 MG | O19: ARICEPT TABLET 10 MG | P19: OBAT PADAT (PERSEDIAAN LAINNYA)
A20: 1010401002 | B20: 000449 | C20: 1 | D20: 1 | E20: 1188 | F20: 0 | G20: 92 | H20: 4.25 | I20: 5 | J20: -88 | K20: 87.75 | L20: -87.75 | M20: 10A275 | N20: ALPRAZOLAM TABLET 0,5 MG | O20: ALPRAZOLAM TABLET 0,5 MG | P20: OBAT PADAT (PERSEDIAAN LAINNYA)
A21: 1010401002 | B21: 000480 | C21: 2 | D21: 2 | E21: 161 | F21: 0 | G21: 3783 | H21: 2870.99 | I21: 2871 | J21: -912.01 | K21: 912.01 | L21: -912.01 | M21: 10A276 | N21: AMITRIPTILINE TABLET 25 MG | O21: AMITRIPTYLLINE TAB 25 MG | P21: OBAT PADAT (PERSEDIAAN LAINNYA)
A22: 1010401002 | B22: 000446 | C22: 1 | D22: 1 | E22: 188 | F22: 0 | G22: 2012 | H22: 1090 | I22: 1090 | J22: -247 | K22: 922 | L22: -922 | M22: 10A282 | N22: ACYCLOVIR 400 MG TAB | O22: ACYCLOVIR 400 MG TAB | P22: OBAT PADAT (PERSEDIAAN LAINNYA)
A23: 1010401999 | B23: 000470 | C23: 2 | D23: 2 | E23: 613 | F23: 0 | G23: 67 | H23: 0 | I23: 0 | J23: -34 | K23: 67 | L23: -67 | M23: 10A285 | N23: AMIODARON TAB 200 MG | O23: KENDARON TAB 200 MG | P23: OBAT PADAT (PERSEDIAAN LAINNYA)
A24: 1010401999 | B24: 003569 | C24: 1 | D24: 1 | E24: 15626 | F24: 0 | G24: 2517 | H24: 1014 | I24: 1014 | J24: -1503 | K24: 1503 | L24: -1503 | M24: 10A289 | N24: ALLOPURINOL TAB 300MG | O24: ALLOPURINOL TAB 300MG | P24: OBAT LAINNYA (PERSEDIAAN LAINNYA)
A25: 1010401999 | B25: 003570 | C25: 2 | D25: 2 | E25: 3436 | F25: 0 | G25: 209 | H25: 58.25 | I25: 59 | J25: -150 | K25: 150.75 | L25: -150.75 | M25: 10A306 | N25: ALPRAZOLAM TAB 1MG | O25: ALPRAZOLAM TABL 1 MG | P25: OBAT LAINNYA (PERSEDIAAN LAINNYA)
A26: 1010401999 | B26: 001245 | C26: 2 | D26: 2 | E26: 1760 | F26: 0 | G26: 231 | H26: 212 | I26: 212 | J26: -19 | K26: 19 | L26: -19 | M26: 10A307 | N26: ANTASIDA TAB | O26: ANTASIDA TAB | P26: OBAT PADAT (PERSEDIAAN LAINNYA)
A27: 1010401999 | B27: 001167 | C27: 1 | D27: 1 | E27: 101 | F27: 0 | G27: 345 | H27: 310 | I27: 310 | J27: -35 | K27: 35 | L27: -35 | M27: 10A311 | N27: ARIPIPRAZOLE TAB DISPERSIBEL 15MG | O27: ARIPIPRAZOLE TAB DISPERSIBEL 15MG | P27: OBAT LAINNYA (PERSEDIAAN LAINNYA)
A28: 1010401999 | B28: 000191 | C28: 1 | D28: 1 | E28: 202000 | F28: 0 | G28: 65950 | H28: 45521 | I28: 45521 | J28: -20375 | K28: 20429 | L28: -20429 | M28: 10A314 | N28: ASAM FOLAT TAB 1MG | O28: ASAM FOLAT TAB 1MG | P28: OBAT LAINNYA (PERSEDIAAN LAINNYA)
A29: 1010401999 | B29: 003619 | C29: 1 | D29: 1 | E29: 0 | F29: 0 | G29: 316 | H29: 247 | I29: 247 | J29: -69 | K29: 69 | L29: -69 | M29: 10A316 | N29: ASAM FOLAT TAB 0,4MG | O29: ASAM FOLAT TAB 0,4MG | P29: OBAT LAINNYA (PERSEDIAAN LAINNYA)
A30: 1010401002 | B30: 000556 | C30: 1 | D30: 1 | E30: 0 | F30: 0 | G30: 852 | H30: 692 | I30: 692 | J30: -160 | K30: 160 | L30: -160 | M30: 10A627 | N30: AMINORAL | O30: AMINORAL | P30: OBAT PADAT (PERSEDIAAN LAINNYA)
A31: 1010401002 | B31: 000444 | C31: 1 | D31: 1 | E31: 160 | F31: 0 | G31: 4 | K31: 4 | L31: -4 | M31: 10B033 | N31: BETABLOK TABLET 100 MG | O31: BETABLOK TABLET 100 MG | P31: OBAT PADAT (PERSEDIAAN LAINNYA)
A32: 1010401002 | B32: 000443 | C32: 1 | D32: 1 | E32: 171 | F32: 0 | G32: 5 | K32: 5 | L32: -5 | M32: 10B035 | N32: BETASERC 8 MG TAB | O32: BETASERC 8 MG TAB | P32: OBAT PADAT (PERSEDIAAN LAINNYA)
A33: 1010401002 | B33: 000442 | C33: 1 | D33: 1 | E33: 690 | F33: 0 | G33: 224 | H33: 199 | I33: 199 | J33: -25 | K33: 25 | L33: -25 | M33: 10B065 | N33: BRAXIDIN TAB | O33: BRAXIDIN TAB | P33: OBAT PADAT (PERSEDIAAN LAINNYA)
A34: 1010401999 | B34: 000675 | C34: 1 | D34: 1 | E34: 1385 | F34: 0 | G34: 1002 | H34: 688 | I34: 688 | J34: -314 | K34: 314 | L34: -314 | M34: 10B113 | N34: BETAHISTIN MESILAT TAB 24 MG | O34: BETAHISTIN MESILAT TAB 24 MG | P34: OBAT LAINNYA (PERSEDIAAN LAINNYA)
A35: 1010401002 | B35: 000523 | C35: 1 | D35: 1 | E35: 0 | F35: 0 | G35: 10457 | H35: 7353.25 | I35: 7354 | J35: -3103.75 | K35: 3103.75 | L35: -3103.75 | M35: 10B118 | N35: BAMGETOL FC KAPLET 200 MG | O35: BAMGETOL FC KAPLET 200 MG | P35: OBAT PADAT (PERSEDIAAN LAINNYA)
A36: 1010401002 | B36: 000437 | C36: 1 | D36: 1 | E36: 701 | F36: 0 | G36: 1112 | H36: 917 | I36: 917 | J36: -195 | K36: 195 | L36: -195 | M36: 10B119 | N36: BACTESYN 375 MG | O36: BACTESYN 375 MG | P36: OBAT PADAT (PERSEDIAAN LAINNYA)
A37: 1010401002 | B37: 000436 | C37: 1 | D37: 1 | E37: 2822 | F37: 0 | G37: 679 | H37: 514 | I37: 514 | J37: -165 | K37: 165 | L37: -165 | M37: 10B122 | N37: BIOPREXUM TAB 5 MG | O37: BIOPREXUM TAB 5 MG | P37: OBAT PADAT (PERSEDIAAN LAINNYA)
A38: 1010401999 | B38: 003562 | C38: 1 | D38: 1 | E38: 218 | F38: 0 | G38: 1811 | H38: 1807 | I38: 1807 | J38: -4 | K38: 4 | L38: -4 | M38: 10B131 | N38: BRILINTA FC TAB 90 MG | O38: BRILINTA FC TAB 90 MG | P38: OBAT LAINNYA (PERSEDIAAN LAINNYA)
A39: 1010401999 | B39: 003557 | C39: 3 | D39: 3 | E39: 71338 | F39: 0 | G39: 3643 | H39: 2149 | I39: 2149 | J39: -2413 | K39: 1494 | L39: -1494 | M39: 10B140 | N39: BICARBONAT NATRICUS 500MG TAB | O39: BICARBONAT NATRICUS 500MG TAB | P39: OBAT PADAT (PERSEDIAAN LAINNYA)
A40: 1010401999 | B40: 003602 | C40: 2 | D40: 2 | E40: 0 | F40: 0 | G40: 181 | H40: 167 | I40: 167 | J40: -14 | K40: 14 | L40: -14 | M40: 10B142 | N40: BISACODYL TABLET SALUT 5MG | O40: BISAKODIL TABLET 5 mg | P40: OBAT LAINNYA (PERSEDIAAN LAINNYA)
...

Sheet selisihNol
A1: sakti_kode_klp | B1: sakti_kode | C1: katalog_grp | D1: sakti_grp | E1: qty_awal | F1: sakti_awal_add | G1: sakti_akhir | H1: simrs_akhir | I1: pembulatan | J1: simrs_trx | K1: selisih_abs | L1: selisih | M1: katalog_kode | N1: katalog_nama | O1: sakti_nama | P1: sakti_nama_klp
A2: 1010401999 | B2: 004174 | C2: 14 | D2: 14 | E2: 0 | F2: 0 | G2: 0 | K2: 0 | L2: 0 | O2: TAPROS 1.88 MG | P2: OBAT LAINNYA (PERSEDIAAN LAINNYA)
A3: 1010401002 | B3: 000477 | C3: 1 | D3: 1 | E3: 259 | F3: 0 | G3: 7 | H3: 7 | I3: 7 | J3: 0 | K3: 0 | L3: 0 | M3: 10A044 | N3: ALLORIS TABLET 10 MG | O3: ALLORIS TABLET 10 MG | P3: OBAT PADAT (PERSEDIAAN LAINNYA)
A4: 1010401002 | B4: 000473 | C4: 1 | D4: 1 | E4: 81 | F4: 0 | G4: 0 | K4: 0 | L4: 0 | M4: 10A085 | N4: ARCALION 200 TAB | O4: ARCALION 200 TAB | P4: OBAT PADAT (PERSEDIAAN LAINNYA)
A5: 1010401002 | B5: 000472 | C5: 1 | D5: 1 | E5: 30983 | F5: 0 | G5: 0 | K5: 0 | L5: 0 | M5: 10A095 | N5: ASAM FOLAT 1 MG | O5: ASAM FOLAT 1 MG | P5: OBAT PADAT (PERSEDIAAN LAINNYA)
A6: 1010401002 | B6: 000055 | C6: 1 | D6: 1 | E6: 265 | F6: 0 | G6: 0 | K6: 0 | L6: 0 | M6: 10A098 | N6: ASCARDIA TABLET SALUT ENTERIK 80 MG | O6: ASCARDIA TABLET SALUT ENTERIK 80 MG | P6: OBAT PADAT (PERSEDIAAN LAINNYA)
A7: 1010401002 | B7: 000471 | C7: 1 | D7: 1 | E7: 295 | F7: 0 | G7: 0 | K7: 0 | L7: 0 | M7: 10A112 | N7: ATIVAN TAB 1 MG | O7: ATIVAN TAB 1 MG | P7: OBAT PADAT (PERSEDIAAN LAINNYA)
A8: 1010401002 | B8: 000468 | C8: 1 | D8: 1 | E8: 326 | F8: 0 | G8: 20 | H8: 20 | I8: 20 | J8: 0 | K8: 0 | L8: 0 | M8: 10A164 | N8: ARCOXIA TAB 60 MG | O8: ARCOXIA TAB 60 MG | P8: OBAT PADAT (PERSEDIAAN LAINNYA)
A9: 1010401002 | B9: 000465 | C9: 1 | D9: 1 | E9: 20 | F9: 0 | G9: 0 | K9: 0 | L9: 0 | M9: 10A171 | N9: ABBOTIC XL TAB 500 MG | O9: ABBOTIC XL TAB 500 MG | P9: OBAT PADAT (PERSEDIAAN LAINNYA)
A10: 1010401002 | B10: 000023 | C10: 1 | D10: 1 | E10: 244 | F10: 0 | G10: 0 | K10: 0 | L10: 0 | M10: 10A175 | N10: ABILIFY 10 MG TAB | O10: ABILIFY 10 MG TAB | P10: OBAT PADAT (PERSEDIAAN LAINNYA)
A11: 1010401002 | B11: 000518 | C11: 1 | D11: 1 | E11: 0 | F11: 0 | G11: 0 | K11: 0 | L11: 0 | M11: 10A176 | N11: ABILIFY 15 MG TAB | O11: ABILIFY 15 MG TAB | P11: OBAT PADAT (PERSEDIAAN LAINNYA)
A12: 1010401002 | B12: 000464 | C12: 1 | D12: 1 | E12: 7222 | F12: 0 | G12: 19 | H12: 19 | I12: 19 | J12: 0 | K12: 0 | L12: 0 | M12: 10A177 | N12: AVODART TAB 0.5 MG | O12: AVODART TAB 0.5 MG | P12: OBAT PADAT (PERSEDIAAN LAINNYA)
A13: 1010401002 | B13: 000463 | C13: 1 | D13: 1 | E13: 75 | F13: 0 | G13: 40 | H13: 40 | I13: 40 | J13: 0 | K13: 0 | L13: 0 | M13: 10A185 | N13: ARTRODAR CAP 50 MG | O13: ARTRODAR CAP 50 MG | P13: OBAT PADAT (PERSEDIAAN LAINNYA)
A14: 1010401002 | B14: 000461 | C14: 1 | D14: 1 | E14: 23 | F14: 0 | G14: 0 | H14: 0 | I14: 0 | J14: 0 | K14: 0 | L14: 0 | M14: 10A200 | N14: AERIUS TAB 5 MG | O14: AERIUS TAB 5 MG | P14: OBAT PADAT (PERSEDIAAN LAINNYA)
A15: 1010401002 | B15: 000571 | C15: 1 | D15: 1 | E15: 0 | F15: 0 | G15: 300 | H15: 300 | I15: 300 | J15: 0 | K15: 0 | L15: 0 | M15: 10A201 | N15: ARIPIPRAZOLE TAB DISPERSIBEL 10MG | O15: ARIPIPRAZOLE TAB DISPERSIBEL 10MG | P15: OBAT PADAT (PERSEDIAAN LAINNYA)
A16: 1010401002 | B16: 000456 | C16: 1 | D16: 1 | E16: 1702 | F16: 0 | G16: 0 | K16: 0 | L16: 0 | M16: 10A255 | N16: ALPENTIN 100 MG CAPS | O16: ALPENTIN 100 MG CAPS | P16: OBAT PADAT (PERSEDIAAN LAINNYA)
A17: 1010401002 | B17: 000538 | C17: 1 | D17: 1 | E17: 0 | F17: 0 | G17: 0 | K17: 0 | L17: 0 | M17: 10A279 | N17: AMOXYCILLIN TAB 500 MG | O17: AMOXYCILLIN TAB 500 MG | P17: OBAT PADAT (PERSEDIAAN LAINNYA)
A18: 1010401002 | B18: 000447 | C18: 1 | D18: 1 | E18: 6 | F18: 0 | G18: 0 | K18: 0 | L18: 0 | M18: 10A281 | N18: ACYCLOVIR 200 MG TAB | O18: ACYCLOVIR 200 MG TAB | P18: OBAT PADAT (PERSEDIAAN LAINNYA)
A19: 1010401999 | B19: 003563 | C19: 1 | D19: 1 | E19: 334 | F19: 0 | G19: 0 | K19: 0 | L19: 0 | M19: 10A304 | N19: AVIGAN TAB 200 MG | O19: AVIGAN TAB 200 MG | P19: OBAT LAINNYA (PERSEDIAAN LAINNYA)
A20: 1010401002 | B20: 000527 | C20: 1 | D20: 1 | E20: 0 | F20: 0 | G20: 0 | K20: 0 | L20: 0 | M20: 10A317 | N20: ABILIFY TAB 5 MG | O20: ABILIFY TAB 5 MG | P20: OBAT PADAT (PERSEDIAAN LAINNYA)
A21: 1010401999 | B21: 000353 | C21: 1 | D21: 1 | E21: 294 | F21: 0 | G21: 294 | H21: 294 | I21: 294 | J21: 0 | K21: 0 | L21: 0 | M21: 10B058 | N21: BIOSAN TAB 275 MG | O21: BIOSAN TAB 275 MG | P21: OBAT LAINNYA (PERSEDIAAN LAINNYA)
A22: 1010401002 | B22: 000440 | C22: 1 | D22: 1 | E22: 188 | F22: 0 | G22: 0 | K22: 0 | L22: 0 | M22: 10B079 | N22: BUSCOPAN PLUS TAB | O22: BUSCOPAN PLUS TAB | P22: OBAT PADAT (PERSEDIAAN LAINNYA)
A23: 1010401002 | B23: 000439 | C23: 1 | D23: 1 | E23: 78 | F23: 0 | G23: 0 | K23: 0 | L23: 0 | M23: 10B093 | N23: BETASERC TAB 24 MG | O23: BETASERC TAB 24 MG | P23: OBAT PADAT (PERSEDIAAN LAINNYA)
A24: 1010401002 | B24: 000438 | C24: 1 | D24: 1 | E24: 0 | F24: 0 | G24: 12 | H24: 12 | I24: 12 | J24: 0 | K24: 0 | L24: 0 | M24: 10B117 | N24: BAQUINOR FORTE KAPL 500 MG | O24: BAQUINOR FORTE KAPL 500 MG | P24: OBAT PADAT (PERSEDIAAN LAINNYA)
A25: 1010401002 | B25: 000573 | C25: 1 | D25: 1 | E25: 0 | F25: 0 | G25: 9 | H25: 9 | I25: 9 | J25: 0 | K25: 0 | L25: 0 | M25: 10B143 | N25: BETARHIN 10MG TAB | O25: BETARHIN 10MG TAB | P25: OBAT PADAT (PERSEDIAAN LAINNYA)
A26: 1010401002 | B26: 000433 | C26: 1 | D26: 1 | E26: 27 | F26: 0 | G26: 4 | H26: 4 | I26: 4 | J26: 0 | K26: 0 | L26: 0 | M26: 10C001.026 | N26: CEFSPAN 200 MG | O26: CEFSPAN 200 MG | P26: OBAT PADAT (PERSEDIAAN LAINNYA)
A27: 1010401002 | B27: 000432 | C27: 1 | D27: 1 | E27: 9 | F27: 0 | G27: 3 | H27: 3 | I27: 3 | J27: 0 | K27: 0 | L27: 0 | M27: 10C001.027 | N27: CEFAT KAPSUL 500 MG | O27: CEFAT KAPSUL 500 MG | P27: OBAT PADAT (PERSEDIAAN LAINNYA)
A28: 1010401002 | B28: 000491 | C28: 1 | D28: 1 | E28: 0 | F28: 0 | G28: 0 | K28: 0 | L28: 0 | M28: 10C001.030 | N28: CELEBREX CAP 200 MG | O28: CELEBREX CAP 200 MG | P28: OBAT PADAT (PERSEDIAAN LAINNYA)
A29: 1010401002 | B29: 000085 | C29: 1 | D29: 1 | E29: 178 | F29: 0 | G29: 64 | H29: 64 | I29: 64 | J29: 0 | K29: 0 | L29: 0 | M29: 10C001.054 | N29: CIPRALEX TAB | O29: CIPRALEX TAB | P29: OBAT PADAT (PERSEDIAAN LAINNYA)
A30: 1010401002 | B30: 000121 | C30: 1 | D30: 1 | E30: 292 | F30: 0 | G30: 293 | H30: 293 | I30: 293 | J30: 0 | K30: 0 | L30: 0 | M30: 10C001.071 | N30: CODITAM TABLET | O30: CODITAM TABLET | P30: OBAT PADAT (PERSEDIAAN LAINNYA)
A31: 1010401002 | B31: 000510 | C31: 1 | D31: 1 | E31: 0 | F31: 0 | G31: 0 | K31: 0 | L31: 0 | M31: 10C001.1.14306 | N31: CYGEST TABLET 200 MG | O31: CYGEST TABLET 200 MG | P31: OBAT PADAT (PERSEDIAAN LAINNYA)
A32: 1010401999 | B32: 001595 | C32: 1 | D32: 1 | E32: 100 | F32: 0 | G32: 0 | K32: 0 | L32: 0 | M32: 10C001.11 | N32: CHLORAMEX TAB 500MG | O32: CHLORAMEX TAB 500MG | P32: OBAT LAINNYA (PERSEDIAAN LAINNYA)
A33: 1010401999 | B33: 001673 | C33: 1 | D33: 1 | E33: 1067 | F33: 0 | G33: 0 | K33: 0 | L33: 0 | M33: 10C001.6 | N33: CURCUMA FORCE TAB | O33: CURCUMA FORCE TAB | P33: OBAT LAINNYA (PERSEDIAAN LAINNYA)
A34: 1010401999 | B34: 003544 | C34: 1 | D34: 1 | E34: 661 | F34: 0 | G34: 0 | K34: 0 | L34: 0 | M34: 10C002 | N34: CERINI KAPL 10 MG | O34: CERINI KAPL 10 MG | P34: OBAT LAINNYA (PERSEDIAAN LAINNYA)
A35: 1010401999 | B35: 001205 | C35: 1 | D35: 1 | E35: 41 | F35: 0 | G35: 21 | H35: 21 | I35: 21 | J35: 0 | K35: 0 | L35: 0 | M35: 10C004 | N35: CALCIUM D REDOXON | O35: CALCIUM D REDOXON | P35: OBAT LAINNYA (PERSEDIAAN LAINNYA)
A36: 1010401002 | B36: 000417 | C36: 1 | D36: 1 | E36: 9327 | F36: 0 | G36: 202 | H36: 202 | I36: 202 | J36: 0 | K36: 0 | L36: 0 | M36: 10C019 | N36: CARBAMAZEPINE TAB 200 MG | O36: CARBAMAZEPINE TAB 200 MG | P36: OBAT PADAT (PERSEDIAAN LAINNYA)
A37: 1010401002 | B37: 000416 | C37: 1 | D37: 1 | E37: 63 | F37: 0 | G37: 0 | K37: 0 | L37: 0 | M37: 10C029 | N37: CATAFLAM TAB 25 MG | O37: CATAFLAM TAB 25 MG | P37: OBAT PADAT (PERSEDIAAN LAINNYA)
A38: 1010401002 | B38: 000415 | C38: 1 | D38: 1 | E38: 3 | F38: 0 | G38: 0 | K38: 0 | L38: 0 | M38: 10C029.1 | N38: CATAFLAM TAB 50 MG | O38: CATAFLAM TAB 50 MG | P38: OBAT PADAT (PERSEDIAAN LAINNYA)
A39: 1010401002 | B39: 000413 | C39: 1 | D39: 1 | E39: 10 | F39: 0 | G39: 0 | K39: 0 | L39: 0 | M39: 10C046 | N39: CEFSPAN CAPSUL 100 mg | O39: CEFSPAN CAPSUL 100 mg | P39: OBAT PADAT (PERSEDIAAN LAINNYA)
A40: 1010401002 | B40: 000566 | C40: 2 | D40: 2 | E40: 20555 | F40: 0 | G40: 0 | K40: 0 | L40: 0 | M40: 10C094 | N40: CLONIDIN TAB | O40: CLONIDINE TAB 0.15MG | P40: OBAT PADAT (PERSEDIAAN LAINNYA)
...

Sheet selisihPlus
A1: sakti_kode_klp | B1: sakti_kode | C1: katalog_grp | D1: sakti_grp | E1: qty_awal | F1: sakti_awal_add | G1: sakti_akhir | H1: simrs_akhir | I1: pembulatan | J1: simrs_trx | K1: selisih_abs | L1: selisih | M1: katalog_kode | N1: katalog_nama | O1: sakti_nama | P1: sakti_nama_klp
A2: 1010401002 | B2: 000478 | C2: 1 | D2: 1 | E2: 17589 | F2: 0 | G2: 5887 | H2: 9490 | I2: 9490 | J2: 3603 | K2: 3603 | L2: 3603 | M2: 10A025 | N2: ADALAT OROS TAB 30 MG | O2: ADALAT OROS TAB 30 MG | P2: OBAT PADAT (PERSEDIAAN LAINNYA)
A3: 1010401999 | B3: 000351 | C3: 2 | D3: 2 | E3: 142889 | F3: 0 | G3: 0 | H3: 10279 | I3: 10279 | J3: 10279 | K3: 10279 | L3: 10279 | M3: 10A254 | N3: ACETYLCYSTEIN 200 MG CAPSUL | O3: ACETYLCYSTEIN 200 MG CAPSUL | P3: OBAT PADAT (PERSEDIAAN LAINNYA)
A4: 1010401002 | B4: 000454 | C4: 1 | D4: 1 | E4: 23983 | F4: 0 | G4: 11421 | H4: 20516 | I4: 20516 | J4: 9095 | K4: 9095 | L4: 9095 | M4: 10A258 | N4: ACARBOSE TABLET 100 MG | O4: ACARBOSE TABLET 100 MG | P4: OBAT PADAT (PERSEDIAAN LAINNYA)
A5: 1010401002 | B5: 000453 | C5: 1 | D5: 1 | E5: 6364 | F5: 0 | G5: 3709 | H5: 6414 | I5: 6414 | J5: 2705 | K5: 2705 | L5: 2705 | M5: 10A259 | N5: ACARBOSE TAB 50 MG | O5: ACARBOSE TAB 50 MG | P5: OBAT PADAT (PERSEDIAAN LAINNYA)
A6: 1010401999 | B6: 003565 | C6: 2 | D6: 2 | E6: 6409 | F6: 0 | G6: 355 | H6: 680 | I6: 680 | J6: 325 | K6: 325 | L6: 325 | M6: 10A300 | N6: AMOXICILLIN TRIHYDRATE KAPLET 500 MG | O6: AMOXSAN CAP 500 MG | P6: OBAT PADAT (PERSEDIAAN LAINNYA)
A7: 1010401999 | B7: 001068 | C7: 2 | D7: 2 | E7: 36185 | F7: 0 | G7: 23959 | H7: 28975 | I7: 28975 | J7: 10865 | K7: 5016 | L7: 5016 | M7: 10B132 | N7: BISOPROLOL TABLET 5 MG | O7: BISOPROLOL TABLET 5 MG | P7: OBAT PADAT (PERSEDIAAN LAINNYA)
A8: 1010401999 | B8: 003560 | C8: 2 | D8: 2 | E8: 6896 | F8: 0 | G8: 776 | H8: 4234 | I8: 4234 | J8: 3378 | K8: 3458 | L8: 3458 | M8: 10B135 | N8: BETAHISTIN MESILAT TABLET 6 MG (DEXA) | O8: BETAHISTIN TABLET 6 MG | P8: OBAT PADAT (PERSEDIAAN LAINNYA)
A9: 1010401999 | B9: 001166 | C9: 1 | D9: 1 | E9: 38149 | F9: 0 | G9: 7686 | H9: 25625 | I9: 25625 | J9: 18628 | K9: 17939 | L9: 17939 | M9: 10B141 | N9: BISOPROLOL TABLET 2,5MG | O9: BISOPROLOL TABLET 2,5MG | P9: OBAT LAINNYA (PERSEDIAAN LAINNYA)
A10: 1010401999 | B10: 003556 | C10: 1 | D10: 1 | E10: 1060 | F10: 0 | G10: 989 | H10: 1417.5 | I10: 1418 | J10: 428.5 | K10: 428.5 | L10: 428.5 | M10: 10C001.002 | N10: CLOZAPINE TABLET 25 MG | O10: CLOZAPINE TABLET 25 MG | P10: OBAT LAINNYA (PERSEDIAAN LAINNYA)
A11: 1010401999 | B11: 003555 | C11: 1 | D11: 1 | E11: 11249 | F11: 0 | G11: 1948 | H11: 3688 | I11: 3688 | J11: 1740 | K11: 1740 | L11: 1740 | M11: 10C001.003 | N11: CIPROFLOXACIN TABLET 500 MG | O11: CIPROFLOXACIN TABLET 500 MG | P11: OBAT LAINNYA (PERSEDIAAN LAINNYA)
A12: 1010401002 | B12: 000434 | C12: 1 | D12: 1 | E12: 3814 | F12: 0 | G12: 13355 | H12: 16022.5 | I12: 16023 | J12: 1187.5 | K12: 2667.5 | L12: 2667.5 | M12: 10C001.023 | N12: CEFIXIME CAP 100 MG | O12: CEFIXIME CAP 100 MG | P12: OBAT PADAT (PERSEDIAAN LAINNYA)
A13: 1010401002 | B13: 000423 | C13: 1 | D13: 1 | E13: 1493 | F13: 0 | G13: 316 | H13: 621 | I13: 621 | J13: 305 | K13: 305 | L13: 305 | M13: 10C001.094 | N13: CRIPSA TAB 2.5 MG | O13: CRIPSA TAB 2.5 MG | P13: OBAT PADAT (PERSEDIAAN LAINNYA)
... A18: 1010401999 | B18: 003543 | C18: 1 | D18: 1 | E18: 5208 | F18: 0 | G18: 4913 | H18: 5024 | I18: 5024 | J18: 0 | K18: 111 | L18: 111 | M18: 10C125 | N18: OSELTAMIVIR TABLET (COVID-19) | O18: OSELTAMIVIR TABLET (COVID-19) | P18: OBAT LAINNYA (PERSEDIAAN LAINNYA)
A19: 1010401999 | B19: 001045 | C19: 3 | D19: 3 | E19: 6242 | F19: 0 | G19: 14 | H19: 112 | I19: 112 | J19: 112 | K19: 98 | L19: 98 | M19: 10D091 | O19: DONPERIDON TAB 10 MG | P19: OBAT PADAT (PERSEDIAAN LAINNYA)
A20: 1010401002 | B20: 000387 | C20: 1 | D20: 1 | E20: 1836 | F20: 0 | G20: 781 | H20: 4593 | I20: 4593 | J20: 3812 | K20: 3812 | L20: 3812 | M20: 10D178 | N20: DEXKETOPROFEN TAB | O20: DEXKETOPROFEN TAB | P20: OBAT PADAT (PERSEDIAAN LAINNYA)
A21: 1010401999 | B21: 000991 | C21: 1 | D21: 1 | E21: 1373 | F21: 0 | G21: 944 | H21: 2375.5 | I21: 2376 | J21: 1432.25 | K21: 1431.5 | L21: 1431.5 | M21: 10D193 | N21: DIAZEPAM TABLET 2 MG | O21: DIAZEPAM TABLET 2 MG | P21: OBAT LAINNYA (PERSEDIAAN LAINNYA)
A22: 1010401999 | B22: 001164 | C22: 1 | D22: 1 | E22: 8105 | F22: 0 | G22: 32 | H22: 12320 | I22: 12320 | J22: 12282 | K22: 12288 | L22: 12288 | M22: 10D199.2 | N22: DIVALPROEX SODIUM KAPLET LEPAS LAMBAT 250MG | O22: DIVALPROEX SODIUM KAPLET LEPAS LAMBAT 250MG | P22: OBAT LAINNYA (PERSEDIAAN LAINNYA)
A23: 1010401999 | B23: 001067 | C23: 1 | D23: 1 | E23: 9008 | F23: 0 | G23: 385 | H23: 8785 | I23: 8785 | J23: 8400 | K23: 8400 | L23: 8400 | M23: 10D200 | N23: DIVALPROEX SODIUM KAPLET LEPAS LAMBAT 500MG | O23: DIVALPROEX SODIUM KAPLET LEPAS LAMBAT 500MG | P23: OBAT LAINNYA (PERSEDIAAN LAINNYA)
A24: 1010401002 | B24: 000384 | C24: 1 | D24: 1 | E24: 100 | F24: 0 | G24: 136 | H24: 229 | I24: 229 | J24: 93 | K24: 93 | L24: 93 | M24: 10E041 | N24: ESILGAN TABLET 1 mg | O24: ESILGAN TABLET 1 mg | P24: OBAT PADAT (PERSEDIAAN LAINNYA)
A25: 1010401002 | B25: 000382 | C25: 1 | D25: 1 | E25: 465 | F25: 0 | G25: 46 | H25: 74 | I25: 74 | J25: 28 | K25: 28 | L25: 28 | M25: 10E081 | N25: ERGOTAMIN COFFEINE | O25: ERGOTAMIN COFFEINE | P25: OBAT PADAT (PERSEDIAAN LAINNYA)
A26: 1010401999 | B26: 001143 | C26: 1 | D26: 1 | E26: 3440 | F26: 0 | G26: 500 | H26: 637.5 | I26: 638 | J26: 137.5 | K26: 137.5 | L26: 137.5 | M26: 10F159 | N26: FLUOXETINE HCL TAB 20MG | O26: FLUOXETINE HCL TAB 20MG | P26: OBAT LAINNYA (PERSEDIAAN LAINNYA)
A27: 1010401999 | B27: 001098 | C27: 1 | D27: 1 | E27: 2122 | F27: 0 | G27: 3032 | H27: 4927 | I27: 4927 | J27: 1895 | K27: 1895 | L27: 1895 | M27: 10F160 | N27: FONYLIN MR 60MG | O27: FONYLIN MR 60MG | P27: OBAT LAINNYA (PERSEDIAAN LAINNYA)
A28: 1010401999 | B28: 000679 | C28: 1 | D28: 1 | E28: 117 | F28: 0 | G28: 634 | H28: 1371 | I28: 1371 | J28: 737 | K28: 737 | L28: 737 | M28: 10F161 | N28: FENOFIBRAT CAPS 100MG | O28: FENOFIBRAT CAPS 100MG | P28: OBAT LAINNYA (PERSEDIAAN LAINNYA)
A29: 1010401002 | B29: 000361 | C29: 1 | D29: 1 | E29: 8685 | F29: 0 | G29: 1784 | H29: 8354.5 | I29: 8355 | J29: 6570.5 | K29: 6570.5 | L29: 6570.5 | M29: 10G081 | N29: GLIQUIDONE TABLET 30 MG | O29: GLIQUIDONE TABLET 30 MG | P29: OBAT PADAT (PERSEDIAAN LAINNYA)
A30: 1010401999 | B30: 003528 | C30: 2 | D30: 2 | E30: 10695 | F30: 0 | G30: 1088 | H30: 2224 | I30: 2224 | J30: 1136 | K30: 1136 | L30: 1136 | M30: 10G123 | N30: GLIMEPIRIDE TAB 1MG | O30: GLIMEPIRIDE TAB 1MG | P30: OBAT PADAT (PERSEDIAAN LAINNYA)
A31: 1010401999 | B31: 001019 | C31: 1 | D31: 1 | E31: 15402 | F31: 0 | G31: 1187 | H31: 6399 | I31: 6399 | J31: 5026 | K31: 5212 | L31: 5212 | M31: 10G132 | N31: GABAPENTIN KAPSUL 300MG | O31: GABAPENTIN KAPSUL 300MG | P31: OBAT LAINNYA (PERSEDIAAN LAINNYA)
... A261: 1010401999 | B261: 004232 | C261: 1 | D261: 1 | E261: 0 | F261: 0 | G261: 0 | H261: 1 | I261: 1 | J261: 1 | K261: 1 | L261: 1 | M261: 42M329 | N261: MATA BOR CUTTING ULTRA 5PK 3MM LONG (31313069U) | O261: MATA BOR CUTTING ULTRA 5PK 3MM LONG (31313069U) | P261: OBAT LAINNYA (PERSEDIAAN LAINNYA)
A262: 1010401999 | B262: 004234 | C262: 1 | D262: 1 | E262: 0 | F262: 0 | G262: 1 | H262: 4 | I262: 4 | J262: 3 | K262: 3 | L262: 3 | M262: 42M339 | O262: MATA BOR CUTTING ULTRA 5PK 5MM LONG (31315066U) | P262: OBAT LAINNYA (PERSEDIAAN LAINNYA)
A263: 1010401999 | B263: 004236 | C263: 1 | D263: 1 | E263: 0 | F263: 0 | G263: 2 | H263: 4.6 | I263: 5 | J263: 2.6 | K263: 2.6 | L263: 2.6 | M263: 42M340 | O263: MATA BOR DIAMOND 2MM FINE (31132070) | P263: OBAT LAINNYA (PERSEDIAAN LAINNYA)
A264: 1010401999 | B264: 004237 | C264: 1 | D264: 1 | E264: 0 | F264: 0 | G264: 4 | H264: 7.2 | I264: 8 | J264: 3.2 | K264: 3.2 | L264: 3.2 | M264: 42M341 | N264: MATA BOR DIAMOND 4MM FINE LONG (31134068) | O264: MATA BOR DIAMOND 4MM FINE LONG (31134068) | P264: OBAT LAINNYA (PERSEDIAAN LAINNYA)
A265: 1010401999 | B265: 004245 | C265: 1 | D265: 1 | E265: 0 | F265: 0 | G265: 0 | H265: 2 | I265: 2 | J265: 2 | K265: 2 | L265: 2 | M265: 42N077 | N265: NAIL SCREW | O265: NOVOSIS | P265: OBAT LAINNYA (PERSEDIAAN LAINNYA)
A266: 1010401999 | B266: 000086 | C266: 1 | D266: 1 | E266: 0 | F266: 0 | G266: 0 | H266: 1 | I266: 1 | J266: 1 | K266: 1 | L266: 1 | M266: 42N124 | N266: NEOGEN LOCKING SCREW 4.5 X 26-90 MM | O266: NEOGEN LOCKING SCREW 4.5 X 26-90 MM | P266: OBAT LAINNYA (PERSEDIAAN LAINNYA)
A267: 1010401006 | B267: 000043 | C267: 1 | D267: 1 | E267: 0 | F267: 0 | G267: 0 | H267: 2 | I267: 2 | J267: 2 | K267: 2 | L267: 2 | M267: 42P233 | N267: PARCUS BRAID V-LOX PEEK CF SUTURE ANCHOR 10324T | O267: PARCUS BRAID V-LOX PEEK CF SUTURE ANCHOR 10324T | P267: ALAT/ OBAT KONTRASEPSI KELUARGA BERENCANA(PERSEDIAAN LAINNYA)
A268: 1010401999 | B268: 002991 | C268: 1 | D268: 1 | E268: 0 | F268: 0 | G268: 0 | H268: 1 | I268: 1 | J268: 1 | K268: 1 | L268: 1 | M268: 42P339 | N268: PROXIMAL TIBIAL ├â╦£4.5/5.0 LCP 4-10 HOLE Ti L/R | O268: PROXIMAL TIBIAL ├ÿ4.5/5.0 LCP 4-10 HOLE Ti L/R | P268: OBAT LAINNYA (PERSEDIAAN LAINNYA)
A269: 1010401999 | B269: 002989 | C269: 1 | D269: 1 | E269: 0 | F269: 0 | G269: 1 | H269: 5 | I269: 5 | J269: 4 | K269: 4 | L269: 4 | M269: 42P344 | N269: PHILOS | O269: PHILOS | P269: OBAT LAINNYA (PERSEDIAAN LAINNYA)
A270: 1010401999 | B270: 002987 | C270: 1 | D270: 1 | E270: 0 | F270: 0 | G270: 2 | H270: 6 | I270: 6 | J270: 4 | K270: 4 | L270: 4 | M270: 42P359 | N270: PFNA-II NAIL | O270: PFNA-II NAIL | P270: OBAT LAINNYA (PERSEDIAAN LAINNYA)
A271: 1010401999 | B271: 002986 | C271: 1 | D271: 1 | E271: 0 | F271: 0 | G271: 2 | H271: 6 | I271: 6 | J271: 4 | K271: 4 | L271: 4 | M271: 42P360 | N271: PFNA-II BLADE | O271: PFNA-II BLADE | P271: OBAT LAINNYA (PERSEDIAAN LAINNYA)
A272: 1010401999 | B272: 002985 | C272: 1 | D272: 1 | E272: 0 | F272: 0 | G272: 2 | H272: 5 | I272: 5 | J272: 3 | K272: 3 | L272: 3 | M272: 42P361 | N272: PFNA-II END CAP | O272: PFNA-II END CAP | P272: OBAT LAINNYA (PERSEDIAAN LAINNYA)
A273: 1010401999 | B273: 002984 | C273: 1 | D273: 1 | E273: 0 | F273: 0 | G273: 5 | H273: 40 | I273: 40 | J273: 35 | K273: 35 | L273: 35 | M273: 42P362 | N273: PFNA-II - A2FN - ETN - 5.0 LOCKING SCREWS | O273: PFNA-II - A2FN - ETN - 5.0 LOCKING SCREWS | P273: OBAT LAINNYA (PERSEDIAAN LAINNYA)
...
