Workbook

Sheet MASTER
B1: Manual Filling
B2: Semi Automatic (Bisa dari kode 93 lookup berentet, ataupun diinput manual)
A4: WAJIB DIISI | B4: WAJIB DIISI | C4: OPTIONAL | D4: OPTIONAL | E4: OPTIONAL | F4: WAJIB DIISI | G4: WAJIB DIISI (Untuk obat branded/ada pabrik manufaktur) | H4: WAJIB DIISI (Untuk obat branded/ada pabrik manufaktur) | I4: WAJIB DIISI | J4: WAJIB DIISI | K4: WAJIB DIISI | L4: WAJIB DIISI | M4: WAJIB DIISI | N4: WAJIB DIISI | O4: WAJIB DIISI | P4: WAJIB DIISI
A6: ID Obat SIMRS | B6: Nama Obat | C6: Satuan Dosis (mg/mL) | D6: Satuan obat yang biasanya digunakan untuk pengadaan stok | E6: Satuan Eceran (Sediaan obat dalam apa yang diresepkan kepada pasien) | F6: Formulat | G6: Kode KFA Varian Aktual (93xxxxxx) | H6: Display KFA Varian Aktual (POA) (93xxxxxx) | I6: Kode KFA Varian Template (92xxxxxx) | J6: Display KFA Varian Template (POV) (92xxxxxx) | K6: Kode KFA Ingredients (91xxxxxx) | L6: Display KFA Ingredients (91xxxxxx) | M6: Dosis KFA Ingredients | N6: Satuan KFA Ingredients | O6: Dosis satuan | P6: Pembagi Obat
A7: xxxxxxxxx | B7: ASCARDIA TABLET, DELAYED ACTION, ENTERIC COATED 80 MG | C7: MG | D7: BOX | E7: TAB | F7: ACETYLSALICYLIC ACID | G7: 93000407 | H7: =IFERROR(VLOOKUP($G7,'93. POA (Update 06 Sep)'!$A$1:$D$1380,2,0),"") -> Asam Asetilsalisilat 80 mg Tablet Salut Enterik (ASCARDIA) | I7: =VLOOKUP($G7,'93. POA (Update 06 Sep)'!$A$1:$D$1380,3,0) -> 92000293 | J7: Asam Asetilsalisilat 80 mg Tablet Salut Enterik | K7: =VLOOKUP(L7,'91. BZA (Update 06 Sep)'!$B$1:$C$580,2,0) -> 91000299 | L7: Aspirin | M7: 80 | N7: mg | O7: 1 | P7: TAB
A8: xxxxxxxxx | B8: CONCOR TABLET 1.25 MG | C8: MG | D8: TAB | E8: TAB | F8: BISOPROLOL FUMARATE | G8: 93001345 | H8: =IFERROR(VLOOKUP($G8,'93. POA (Update 06 Sep)'!$A$1:$D$1380,2,0),"") -> Bisoprolol Fumarate 1,25 mg Tablet Salut Selaput (CONCOR) | I8: 92000780 | J8: Bisoprolol Fumarate 1,25 mg Tablet Salut Selaput | K8: =VLOOKUP(L8,'91. BZA (Update 06 Sep)'!$B$1:$C$580,2,0) -> 91000362 | L8: Bisoprolol | M8: 1.25 | N8: mg | O8: 1 | P8: TAB
A9: xxxxxxxxx | B9: BETASERC 24 MG TABLET | C9: MG | D9: BOX | E9: TAB | F9: BETAHISTINE DIHIDROCHLORIDE | G9: 92000451 | H9: Betahistine Hydrochloride 24 mg Tablet | I9: 92000451 | J9: Betahistine Hydrochloride 24 mg Tablet | K9: 91000424 | L9: Betahistine | M9: 24 | N9: mg | O9: 1 | P9: TAB
A10: xxxxxxxxx | B10: ACARBOSE TABLET 100 MG | C10: MG | D10: BOX | E10: TAB | F10: ACARBOSE | H10: =IFERROR(VLOOKUP($G10,'93. POA (Update 06 Sep)'!$A$1:$D$1380,2,0),"") | I10: 92000372 | J10: Acarbose 100 mg Tablet | K10: =VLOOKUP(L10,'91. BZA (Update 06 Sep)'!$B$1:$C$580,2,0) -> 91000314 | L10: Acarbose | M10: 100 | N10: mg | O10: 1 | P10: TAB
A11: xxxxxxxxx | B11: Tenofovir (TDF) 300 mg (Obat Program) | C11: TAB | D11: BOX | E11: TAB | F11: Tenofovir Disoproxil | H11: =IFERROR(VLOOKUP($G11,'93. POA (Update 06 Sep)'!$A$1:$D$1380,2,0),"") | I11: 92000342 | J11: Tenofovir Disoproxil 300 mg Tablet Salut Selaput | K11: =VLOOKUP(L11,'91. BZA (Update 06 Sep)'!$B$1:$C$580,2,0) -> 91000175 | L11: Tenofovir Disoproxil | M11: 300 | N11: mg | O11: 1 | P11: TAB
A12: xxxxxxxxx | B12: Tenofovir (TDF)/Emtricitabine (FTC) 300mg/200mg (Obat Program) | C12: TAB | D12: BOX | E12: TAB | F12: Tenofovir Disoproxil, Emtricitabine | H12: =IFERROR(VLOOKUP($G12,'93. POA (Update 06 Sep)'!$A$1:$D$1380,2,0),"") | I12: 92000161 | J12: Tenofovir Disoproxil 300 mg / Emtricitabine 200 mg Tablet Salut Selaput | K12: =VLOOKUP(L12,'91. BZA (Update 06 Sep)'!$B$1:$C$580,2,0) -> 91000175 | L12: Tenofovir Disoproxil | M12: 300 | N12: mg | O12: 1 | P12: TAB
A13: xxxxxxxxx | B13: Tenofovir (TDF)/Emtricitabine (FTC) 300mg/200mg (Obat Program) | C13: TAB | D13: BOX | E13: TAB | F13: Tenofovir Disoproxil, Emtricitabine | H13: =IFERROR(VLOOKUP($G13,'93. POA (Update 06 Sep)'!$A$1:$D$1380,2,0),"") | I13: 92000161 | J13: Tenofovir Disoproxil 300 mg / Emtricitabine 200 mg Tablet Salut Selaput | K13: =VLOOKUP(L13,'91. BZA (Update 06 Sep)'!$B$1:$C$580,2,0) -> 91000176 | L13: Emtricitabine | M13: 200 | N13: mg | O13: 1 | P13: TAB
A14: xxxxxxxxx | B14: FARMADOL 100 ML SOLUTION, INJECTION 10 MG/ML | C14: ML | D14: VIL | E14: VIL | F14: ACETAMINOPHEN | G14: - | H14: =IFERROR(VLOOKUP($G14,'93. POA (Update 06 Sep)'!$A$1:$D$1380,2,0),"") | I14: - | K14: =VLOOKUP(L14,'91. BZA (Update 06 Sep)'!$B$1:$C$580,2,0) -> 91000101 | L14: Paracetamol | M14: 10 | N14: mg | O14: 1 | P14: mL
A15: xxxxxxxxx | B15: PAMOL TABLET 500 MG | C15: MG | D15: BOX | E15: TAB | F15: ACETAMINOPHEN | G15: - | H15: =IFERROR(VLOOKUP($G15,'93. POA (Update 06 Sep)'!$A$1:$D$1380,2,0),"") | I15: - | K15: =VLOOKUP(L15,'91. BZA (Update 06 Sep)'!$B$1:$C$580,2,0) -> 91000101 | L15: Paracetamol | M15: 500 | N15: mg | O15: 1 | P15: TAB
A16: xxxxxxxxx | B16: GLAUSETA TABLET 250 MG | C16: MG | D16: BOX | E16: TAB | F16: ACETAZOLAMIDE | G16: - | H16: =IFERROR(VLOOKUP($G16,'93. POA (Update 06 Sep)'!$A$1:$D$1380,2,0),"") | I16: - | K16: =VLOOKUP(L16,'91. BZA (Update 06 Sep)'!$B$1:$C$580,2,0) -> 91000279 | L16: Acetazolamide | M16: 250 | N16: mg | O16: 1 | P16: TAB
A17: xxxxxxxxx | B17: Paracetamol 120 mg / 5 mL Sirup | C17: MG | D17: BOX | E17: TAB | F17: ACETAZOLAMIDE | H17: =IFERROR(VLOOKUP($G17,'93. POA (Update 06 Sep)'!$A$1:$D$1380,2,0),"") | I17: 92000511 | J17: Paracetamol 120 mg / 5 mL Sirup | K17: =VLOOKUP(L17,'91. BZA (Update 06 Sep)'!$B$1:$C$580,2,0) -> 91000101 | L17: Paracetamol | M17: 120 | N17: mg | O17: 5 | P17: mL

Sheet 91. BZA (Update 06 Sep)
A1: Kode KFA Ingredients (91xxxxxx) | B1: Display KFA Ingredients (91xxxxxx) | D1: Unit of Measure (UCUM) | E1: URL
A2: 91000472 | B2: (((1-Methyl-2-(5-Methyl-3-Oxazolidinyl)Ethoxy)Methoxy)Methoxy)Methanol | C2: {=IF(A2:A1000<>"",(A2:A1000))} -> 91000472 | D2: mg | E2: =_xlfn.TEXTJOIN("/",,"https://dto.kemkes.go.id/kfacode",A2) -> https://dto.kemkes.go.id/kfacode/91000472
A3: 91000553 | B3: ((2S,3S,5S)-2-(2-(2,6-Dimethylphenoxy)Acetamido)-5-((S)-3-Methyl-2-(2-Oxotetrahydropyrimidin-1(2H)-Yl)Butanamido)-1,6-Diphenylhexan-3-Yl) 3-Methyl-2-(2-Oxotetrahydropyrimidin-1(2H)-Yl)Butanoate, (S)- | C3: 91000553 | D3: mg | E3: =_xlfn.TEXTJOIN("/",,"https://dto.kemkes.go.id/kfacode",A3) -> https://dto.kemkes.go.id/kfacode/91000553
A4: 91000557 | B4: (-)-Ambroxide | C4: 91000557 | D4: mg | E4: =_xlfn.TEXTJOIN("/",,"https://dto.kemkes.go.id/kfacode",A4) -> https://dto.kemkes.go.id/kfacode/91000557
A5: 91000476 | B5: (2-(((2-(2-Amino-3-Hydroxy-2-(Hydroxymethyl)Propoxy)-1-Hydroxypropyl)Hydroxyphosphoryl)Oxy)-1-Hydroxypropyl)Phosphonate | C5: 91000476 | D5: mg | E5: =_xlfn.TEXTJOIN("/",,"https://dto.kemkes.go.id/kfacode",A5) -> https://dto.kemkes.go.id/kfacode/91000476
A6: 91000538 | B6: .Alpha.N-(Methoxycarbonyl)-L-Arginine | C6: 91000538 | D6: mg | E6: =_xlfn.TEXTJOIN("/",,"https://dto.kemkes.go.id/kfacode",A6) -> https://dto.kemkes.go.id/kfacode/91000538
A7: 91000651 | B7: Abacavir | C7: 91000651 | D7: mg | E7: =_xlfn.TEXTJOIN("/",,"https://dto.kemkes.go.id/kfacode",A7) -> https://dto.kemkes.go.id/kfacode/91000651
A8: 91000314 | B8: Acarbose | C8: 91000314 | D8: mg | E8: =_xlfn.TEXTJOIN("/",,"https://dto.kemkes.go.id/kfacode",A8) -> https://dto.kemkes.go.id/kfacode/91000314
A9: 91000279 | B9: Acetazolamide | C9: 91000279 | D9: mg | E9: =_xlfn.TEXTJOIN("/",,"https://dto.kemkes.go.id/kfacode",A9) -> https://dto.kemkes.go.id/kfacode/91000279
A10: 91000447 | B10: Acetylcysteine | C10: 91000447 | D10: mg | E10: =_xlfn.TEXTJOIN("/",,"https://dto.kemkes.go.id/kfacode",A10) -> https://dto.kemkes.go.id/kfacode/91000447
A11: 91000433 | B11: Aciclovir | C11: 91000433 | D11: mg | E11: =_xlfn.TEXTJOIN("/",,"https://dto.kemkes.go.id/kfacode",A11) -> https://dto.kemkes.go.id/kfacode/91000433
A12: 91000548 | B12: Adina Rubella Root Extract | C12: 91000548 | D12: mg | E12: =_xlfn.TEXTJOIN("/",,"https://dto.kemkes.go.id/kfacode",A12) -> https://dto.kemkes.go.id/kfacode/91000548
A13: 91000386 | B13: Alanine | C13: 91000386 | D13: mg | E13: =_xlfn.TEXTJOIN("/",,"https://dto.kemkes.go.id/kfacode",A13) -> https://dto.kemkes.go.id/kfacode/91000386
A14: 91000278 | B14: Alanylglutamine | C14: 91000278 | D14: mg | E14: =_xlfn.TEXTJOIN("/",,"https://dto.kemkes.go.id/kfacode",A14) -> https://dto.kemkes.go.id/kfacode/91000278
... A580: 91000700 | B580: Zonisamide | C580: 91000700 | D580: mg | E580: =_xlfn.TEXTJOIN("/",,"https://dto.kemkes.go.id/kfacode",A580) -> https://dto.kemkes.go.id/kfacode/91000700
C581: FALSE
C582: FALSE
C583: FALSE
C584: FALSE
C585: FALSE
C586: FALSE
C587: FALSE
C588: FALSE
C589: FALSE
C590: FALSE
C591: FALSE
C592: FALSE
... C1000: FALSE

Sheet 92. POV (Update 06 Sep)
A1: Kode KFA Varian Template (92xxxxxx) | B1: Display KFA Varian Template (POV) (92xxxxxx) | C1: Kode KFA Varian Template (92xxxxxx) | D1: Unit of Measure | E1: Jenis Farmalkes | F1: Jumlah Produk Obat Aktual | G1: URL
A2: 92000888 | B2: Abacavir Sulfate 300 mg Tablet Salut Selaput | C2: 92000888 | D2: Tablet | E2: Obat | F2: 2 | G2: =_xlfn.TEXTJOIN("/",,"https://dto.kemkes.go.id/kfacode",A2) -> https://dto.kemkes.go.id/kfacode/92000888
A3: 92000372 | B3: Acarbose 100 mg Tablet | C3: 92000372 | D3: Tablet | E3: Obat | F3: 10 | G3: =_xlfn.TEXTJOIN("/",,"https://dto.kemkes.go.id/kfacode",A3) -> https://dto.kemkes.go.id/kfacode/92000372
A4: 92000371 | B4: Acarbose 50 mg Tablet | C4: 92000371 | D4: Tablet | E4: Obat | F4: 10 | G4: =_xlfn.TEXTJOIN("/",,"https://dto.kemkes.go.id/kfacode",A4) -> https://dto.kemkes.go.id/kfacode/92000371
A5: 92000283 | B5: Acetazolamide 250 mg Tablet | C5: 92000283 | D5: Tablet | E5: Obat | F5: 2 | G5: =_xlfn.TEXTJOIN("/",,"https://dto.kemkes.go.id/kfacode",A5) -> https://dto.kemkes.go.id/kfacode/92000283
A6: 92000867 | B6: Acetylcysteine 100 mg / mL Cairan Inhalasi | C6: 92000867 | D6: Ampul | E6: Obat | F6: 2 | G6: =_xlfn.TEXTJOIN("/",,"https://dto.kemkes.go.id/kfacode",A6) -> https://dto.kemkes.go.id/kfacode/92000867
A7: 92000868 | B7: Acetylcysteine 200 mg Granule | C7: 92000868 | D7: Sachet | E7: Obat | F7: 2 | G7: =_xlfn.TEXTJOIN("/",,"https://dto.kemkes.go.id/kfacode",A7) -> https://dto.kemkes.go.id/kfacode/92000868
A8: 92000610 | B8: Acetylcysteine 200 mg Kapsul | C8: 92000610 | D8: Kapsul | E8: Obat | F8: 2 | G8: =_xlfn.TEXTJOIN("/",,"https://dto.kemkes.go.id/kfacode",A8) -> https://dto.kemkes.go.id/kfacode/92000610
A9: 92000472 | B9: Aciclovir 200 mg Tablet | C9: 92000472 | D9: Tablet | E9: Obat | F9: 3 | G9: =_xlfn.TEXTJOIN("/",,"https://dto.kemkes.go.id/kfacode",A9) -> https://dto.kemkes.go.id/kfacode/92000472
A10: 92000770 | B10: Aciclovir 400 mg Tablet | C10: 92000770 | D10: Tablet | E10: Obat | F10: 1 | G10: =_xlfn.TEXTJOIN("/",,"https://dto.kemkes.go.id/kfacode",A10) -> https://dto.kemkes.go.id/kfacode/92000770
A11: 92000160 | B11: Acidum Methylen Disphosponicum 10 mg / Stannous Chloride Dihydrate 0.238 mg / Acidum Ascorbicum 2 mg Serbuk Injeksi | C11: 92000160 | D11: Vial | E11: Obat | F11: 2 | G11: =_xlfn.TEXTJOIN("/",,"https://dto.kemkes.go.id/kfacode",A11) -> https://dto.kemkes.go.id/kfacode/92000160
A12: 92000640 | B12: Acyclovir 3% Salep Mata | C12: 92000640 | D12: Tube | E12: Obat | F12: 2 | G12: =_xlfn.TEXTJOIN("/",,"https://dto.kemkes.go.id/kfacode",A12) -> https://dto.kemkes.go.id/kfacode/92000640
A13: 92000248 | B13: Air Untuk Injeksi / Aqua Pro Injection / Water For Injection 10 ml | C13: 92000248 | D13: Ampul | E13: Obat | F13: 2 | G13: =_xlfn.TEXTJOIN("/",,"https://dto.kemkes.go.id/kfacode",A13) -> https://dto.kemkes.go.id/kfacode/92000248
... A795: 92000929 | B795: Zonisamide 100 mg Tablet Salut Selaput | C795: 92000929 | D795: Tablet | E795: Obat | F795: 2 | G795: =_xlfn.TEXTJOIN("/",,"https://dto.kemkes.go.id/kfacode",A795) -> https://dto.kemkes.go.id/kfacode/92000929

Sheet 93. POA (Update 06 Sep)
A1: Kode KFA Varian Aktual (93xxxxxx) | B1: Display KFA Varian Aktual (POA) (93xxxxxx) | C1: Kode KFA Varian Template (92xxxxxx) | D1: Display KFA Varian Template (POV) (92xxxxxx) | E1: Nama Dagang | F1: Unit Logistik Terkecil | G1: Bentuk Sediaan | H1: Golongan Obat | I1: URL
A2: 93001546 | B2: Abacavir Sulfate 300 mg Tablet Salut Selaput (KIMIA FARMA Tbk.) | C2: {=IF(A2:A2049<>"",VLOOKUP(D2:D2049,'92. POV (Update 06 Sep)'!$B$1:$C2049,2,0),"")} -> 92000888 | D2: Abacavir Sulfate 300 mg Tablet Salut Selaput | E2: ABACAVIR SULFATE | F2: Tablet | G2: Tablet Salut Selaput | H2: Obat Keras | I2: =_xlfn.TEXTJOIN("/",,"https://dto.kemkes.go.id/kfacode",A2) -> https://dto.kemkes.go.id/kfacode/93001546 | J2: insert into mkatalog_kfa93 (kode, uraian, kode_92, uraian_92, nama_dagang, satuan_kecil, sediaan, golongan, url, userid_updt, sysdate_updt) values | K2: =CONCATENATE(J2,"('",A2,"','",B2,"','",C2,"','",D2,"','",E2,"','",F2,"','",G2,"','",H2,"','",I2,"',0,'2023-05-01');") -> insert into mkatalog_kfa93 (kode, uraian, kode_92, uraian_92, nama_dagang, satuan_kecil, sediaan, golongan, url, userid_updt, sysdate_updt) values ('93001546','Abacavir Sulfate 300 mg Tablet Salut Selaput (KIMIA FARMA Tbk.)','92000888','Abacavir Sulfate 300 mg Tablet Salut Selaput','ABACAVIR SULFATE','Tablet','Tablet Salut Selaput','Obat Keras','https://dto.kemkes.go.id/kfacode/93001546',0,'2023-05-01');
A3: 93000502 | B3: Acarbose 100 mg Tablet (ACRIOS) | C3: 92000372 | D3: Acarbose 100 mg Tablet | E3: ACRIOS | F3: Tablet | G3: Tablet | H3: Obat Keras | I3: =_xlfn.TEXTJOIN("/",,"https://dto.kemkes.go.id/kfacode",A3) -> https://dto.kemkes.go.id/kfacode/93000502 | J3: insert into mkatalog_kfa93 (kode, uraian, kode_92, uraian_92, nama_dagang, satuan_kecil, sediaan, golongan, url, userid_updt, sysdate_updt) values | K3: =CONCATENATE(J3,"('",A3,"','",B3,"','",C3,"','",D3,"','",E3,"','",F3,"','",G3,"','",H3,"','",I3,"',0,'2023-05-01');") -> insert into mkatalog_kfa93 (kode, uraian, kode_92, uraian_92, nama_dagang, satuan_kecil, sediaan, golongan, url, userid_updt, sysdate_updt) values ('93000502','Acarbose 100 mg Tablet (ACRIOS)','92000372','Acarbose 100 mg Tablet','ACRIOS','Tablet','Tablet','Obat Keras','https://dto.kemkes.go.id/kfacode/93000502',0,'2023-05-01');
A4: 93000490 | B4: Acarbose 100 mg Tablet (BETA PHARMACON) | C4: 92000372 | D4: Acarbose 100 mg Tablet | E4: ACARBOSE | F4: Tablet | G4: Tablet | H4: Obat Keras | I4: =_xlfn.TEXTJOIN("/",,"https://dto.kemkes.go.id/kfacode",A4) -> https://dto.kemkes.go.id/kfacode/93000490 | J4: insert into mkatalog_kfa93 (kode, uraian, kode_92, uraian_92, nama_dagang, satuan_kecil, sediaan, golongan, url, userid_updt, sysdate_updt) values | K4: =CONCATENATE(J4,"('",A4,"','",B4,"','",C4,"','",D4,"','",E4,"','",F4,"','",G4,"','",H4,"','",I4,"',0,'2023-05-01');") -> insert into mkatalog_kfa93 (kode, uraian, kode_92, uraian_92, nama_dagang, satuan_kecil, sediaan, golongan, url, userid_updt, sysdate_updt) values ('93000490','Acarbose 100 mg Tablet (BETA PHARMACON)','92000372','Acarbose 100 mg Tablet','ACARBOSE','Tablet','Tablet','Obat Keras','https://dto.kemkes.go.id/kfacode/93000490',0,'2023-05-01');
A5: 93000503 | B5: Acarbose 100 mg Tablet (CAPRIBOSE 100) | C5: 92000372 | D5: Acarbose 100 mg Tablet | E5: CAPRIBOSE | F5: Tablet | G5: Tablet | H5: Obat Keras | I5: =_xlfn.TEXTJOIN("/",,"https://dto.kemkes.go.id/kfacode",A5) -> https://dto.kemkes.go.id/kfacode/93000503 | J5: insert into mkatalog_kfa93 (kode, uraian, kode_92, uraian_92, nama_dagang, satuan_kecil, sediaan, golongan, url, userid_updt, sysdate_updt) values | K5: =CONCATENATE(J5,"('",A5,"','",B5,"','",C5,"','",D5,"','",E5,"','",F5,"','",G5,"','",H5,"','",I5,"',0,'2023-05-01');") -> insert into mkatalog_kfa93 (kode, uraian, kode_92, uraian_92, nama_dagang, satuan_kecil, sediaan, golongan, url, userid_updt, sysdate_updt) values ('93000503','Acarbose 100 mg Tablet (CAPRIBOSE 100)','92000372','Acarbose 100 mg Tablet','CAPRIBOSE','Tablet','Tablet','Obat Keras','https://dto.kemkes.go.id/kfacode/93000503',0,'2023-05-01');
A6: 93000465 | B6: Acarbose 100 mg Tablet (DEXA MEDICA) | C6: 92000372 | D6: Acarbose 100 mg Tablet | E6: ACARBOSE | F6: Tablet | G6: Tablet | H6: Obat Keras | I6: =_xlfn.TEXTJOIN("/",,"https://dto.kemkes.go.id/kfacode",A6) -> https://dto.kemkes.go.id/kfacode/93000465 | J6: insert into mkatalog_kfa93 (kode, uraian, kode_92, uraian_92, nama_dagang, satuan_kecil, sediaan, golongan, url, userid_updt, sysdate_updt) values | K6: =CONCATENATE(J6,"('",A6,"','",B6,"','",C6,"','",D6,"','",E6,"','",F6,"','",G6,"','",H6,"','",I6,"',0,'2023-05-01');") -> insert into mkatalog_kfa93 (kode, uraian, kode_92, uraian_92, nama_dagang, satuan_kecil, sediaan, golongan, url, userid_updt, sysdate_updt) values ('93000465','Acarbose 100 mg Tablet (DEXA MEDICA)','92000372','Acarbose 100 mg Tablet','ACARBOSE','Tablet','Tablet','Obat Keras','https://dto.kemkes.go.id/kfacode/93000465',0,'2023-05-01');
A7: 93000506 | B7: Acarbose 100 mg Tablet (DITRIUM 100) | C7: 92000372 | D7: Acarbose 100 mg Tablet | E7: DITRIUM 100 | F7: Tablet | G7: Tablet | H7: Obat Keras | I7: =_xlfn.TEXTJOIN("/",,"https://dto.kemkes.go.id/kfacode",A7) -> https://dto.kemkes.go.id/kfacode/93000506 | J7: insert into mkatalog_kfa93 (kode, uraian, kode_92, uraian_92, nama_dagang, satuan_kecil, sediaan, golongan, url, userid_updt, sysdate_updt) values | K7: =CONCATENATE(J7,"('",A7,"','",B7,"','",C7,"','",D7,"','",E7,"','",F7,"','",G7,"','",H7,"','",I7,"',0,'2023-05-01');") -> insert into mkatalog_kfa93 (kode, uraian, kode_92, uraian_92, nama_dagang, satuan_kecil, sediaan, golongan, url, userid_updt, sysdate_updt) values ('93000506','Acarbose 100 mg Tablet (DITRIUM 100)','92000372','Acarbose 100 mg Tablet','DITRIUM 100','Tablet','Tablet','Obat Keras','https://dto.kemkes.go.id/kfacode/93000506',0,'2023-05-01');
A8: 93000487 | B8: Acarbose 100 mg Tablet (ECLID) | C8: 92000372 | D8: Acarbose 100 mg Tablet | E8: ECLID | F8: Tablet | G8: Tablet | H8: Obat Keras | I8: =_xlfn.TEXTJOIN("/",,"https://dto.kemkes.go.id/kfacode",A8) -> https://dto.kemkes.go.id/kfacode/93000487 | J8: insert into mkatalog_kfa93 (kode, uraian, kode_92, uraian_92, nama_dagang, satuan_kecil, sediaan, golongan, url, userid_updt, sysdate_updt) values | K8: =CONCATENATE(J8,"('",A8,"','",B8,"','",C8,"','",D8,"','",E8,"','",F8,"','",G8,"','",H8,"','",I8,"',0,'2023-05-01');") -> insert into mkatalog_kfa93 (kode, uraian, kode_92, uraian_92, nama_dagang, satuan_kecil, sediaan, golongan, url, userid_updt, sysdate_updt) values ('93000487','Acarbose 100 mg Tablet (ECLID)','92000372','Acarbose 100 mg Tablet','ECLID','Tablet','Tablet','Obat Keras','https://dto.kemkes.go.id/kfacode/93000487',0,'2023-05-01');
A9: 93000494 | B9: Acarbose 100 mg Tablet (GLUBOSE) | C9: 92000372 | D9: Acarbose 100 mg Tablet | E9: GLUBOSE | F9: Tablet | G9: Tablet | H9: Obat Keras | I9: =_xlfn.TEXTJOIN("/",,"https://dto.kemkes.go.id/kfacode",A9) -> https://dto.kemkes.go.id/kfacode/93000494 | J9: insert into mkatalog_kfa93 (kode, uraian, kode_92, uraian_92, nama_dagang, satuan_kecil, sediaan, golongan, url, userid_updt, sysdate_updt) values | K9: =CONCATENATE(J9,"('",A9,"','",B9,"','",C9,"','",D9,"','",E9,"','",F9,"','",G9,"','",H9,"','",I9,"',0,'2023-05-01');") -> insert into mkatalog_kfa93 (kode, uraian, kode_92, uraian_92, nama_dagang, satuan_kecil, sediaan, golongan, url, userid_updt, sysdate_updt) values ('93000494','Acarbose 100 mg Tablet (GLUBOSE)','92000372','Acarbose 100 mg Tablet','GLUBOSE','Tablet','Tablet','Obat Keras','https://dto.kemkes.go.id/kfacode/93000494',0,'2023-05-01');
A10: 93000505 | B10: Acarbose 100 mg Tablet (GLUCOBAY 100) | C10: 92000372 | D10: Acarbose 100 mg Tablet | E10: GLUCOBAY 100 | F10: Tablet | G10: Tablet | H10: Obat Keras | I10: =_xlfn.TEXTJOIN("/",,"https://dto.kemkes.go.id/kfacode",A10) -> https://dto.kemkes.go.id/kfacode/93000505 | J10: insert into mkatalog_kfa93 (kode, uraian, kode_92, uraian_92, nama_dagang, satuan_kecil, sediaan, golongan, url, userid_updt, sysdate_updt) values | K10: =CONCATENATE(J10,"('",A10,"','",B10,"','",C10,"','",D10,"','",E10,"','",F10,"','",G10,"','",H10,"','",I10,"',0,'2023-05-01');") -> insert into mkatalog_kfa93 (kode, uraian, kode_92, uraian_92, nama_dagang, satuan_kecil, sediaan, golongan, url, userid_updt, sysdate_updt) values ('93000505','Acarbose 100 mg Tablet (GLUCOBAY 100)','92000372','Acarbose 100 mg Tablet','GLUCOBAY 100','Tablet','Tablet','Obat Keras','https://dto.kemkes.go.id/kfacode/93000505',0,'2023-05-01');
A11: 93000485 | B11: Acarbose 100 mg Tablet (PRATAPA NIRMALA) | C11: 92000372 | D11: Acarbose 100 mg Tablet | E11: ACARBOSE | F11: Tablet | G11: Tablet | H11: Obat Keras | I11: =_xlfn.TEXTJOIN("/",,"https://dto.kemkes.go.id/kfacode",A11) -> https://dto.kemkes.go.id/kfacode/93000485 | J11: insert into mkatalog_kfa93 (kode, uraian, kode_92, uraian_92, nama_dagang, satuan_kecil, sediaan, golongan, url, userid_updt, sysdate_updt) values | K11: =CONCATENATE(J11,"('",A11,"','",B11,"','",C11,"','",D11,"','",E11,"','",F11,"','",G11,"','",H11,"','",I11,"',0,'2023-05-01');") -> insert into mkatalog_kfa93 (kode, uraian, kode_92, uraian_92, nama_dagang, satuan_kecil, sediaan, golongan, url, userid_updt, sysdate_updt) values ('93000485','Acarbose 100 mg Tablet (PRATAPA NIRMALA)','92000372','Acarbose 100 mg Tablet','ACARBOSE','Tablet','Tablet','Obat Keras','https://dto.kemkes.go.id/kfacode/93000485',0,'2023-05-01');
A12: 93000548 | B12: Acarbose 50 mg Tablet (ACRIOS) | C12: 92000371 | D12: Acarbose 50 mg Tablet | E12: ACRIOS | F12: Tablet | G12: Tablet | H12: Obat Keras | I12: =_xlfn.TEXTJOIN("/",,"https://dto.kemkes.go.id/kfacode",A12) -> https://dto.kemkes.go.id/kfacode/93000548 | J12: insert into mkatalog_kfa93 (kode, uraian, kode_92, uraian_92, nama_dagang, satuan_kecil, sediaan, golongan, url, userid_updt, sysdate_updt) values | K12: =CONCATENATE(J12,"('",A12,"','",B12,"','",C12,"','",D12,"','",E12,"','",F12,"','",G12,"','",H12,"','",I12,"',0,'2023-05-01');") -> insert into mkatalog_kfa93 (kode, uraian, kode_92, uraian_92, nama_dagang, satuan_kecil, sediaan, golongan, url, userid_updt, sysdate_updt) values ('93000548','Acarbose 50 mg Tablet (ACRIOS)','92000371','Acarbose 50 mg Tablet','ACRIOS','Tablet','Tablet','Obat Keras','https://dto.kemkes.go.id/kfacode/93000548',0,'2023-05-01');
A13: 93000546 | B13: Acarbose 50 mg Tablet (BETA PHARMACON) | C13: 92000371 | D13: Acarbose 50 mg Tablet | E13: ACARBOSE | F13: Tablet | G13: Tablet | H13: Obat Keras | I13: =_xlfn.TEXTJOIN("/",,"https://dto.kemkes.go.id/kfacode",A13) -> https://dto.kemkes.go.id/kfacode/93000546 | J13: insert into mkatalog_kfa93 (kode, uraian, kode_92, uraian_92, nama_dagang, satuan_kecil, sediaan, golongan, url, userid_updt, sysdate_updt) values | K13: =CONCATENATE(J13,"('",A13,"','",B13,"','",C13,"','",D13,"','",E13,"','",F13,"','",G13,"','",H13,"','",I13,"',0,'2023-05-01');") -> insert into mkatalog_kfa93 (kode, uraian, kode_92, uraian_92, nama_dagang, satuan_kecil, sediaan, golongan, url, userid_updt, sysdate_updt) values ('93000546','Acarbose 50 mg Tablet (BETA PHARMACON)','92000371','Acarbose 50 mg Tablet','ACARBOSE','Tablet','Tablet','Obat Keras','https://dto.kemkes.go.id/kfacode/93000546',0,'2023-05-01');
A14: 93000549 | B14: Acarbose 50 mg Tablet (CAPRIBOSE) | C14: 92000371 | D14: Acarbose 50 mg Tablet | E14: CAPRIBOSE | F14: Tablet | G14: Tablet | H14: Obat Keras | I14: =_xlfn.TEXTJOIN("/",,"https://dto.kemkes.go.id/kfacode",A14) -> https://dto.kemkes.go.id/kfacode/93000549 | J14: insert into mkatalog_kfa93 (kode, uraian, kode_92, uraian_92, nama_dagang, satuan_kecil, sediaan, golongan, url, userid_updt, sysdate_updt) values | K14: =CONCATENATE(J14,"('",A14,"','",B14,"','",C14,"','",D14,"','",E14,"','",F14,"','",G14,"','",H14,"','",I14,"',0,'2023-05-01');") -> insert into mkatalog_kfa93 (kode, uraian, kode_92, uraian_92, nama_dagang, satuan_kecil, sediaan, golongan, url, userid_updt, sysdate_updt) values ('93000549','Acarbose 50 mg Tablet (CAPRIBOSE)','92000371','Acarbose 50 mg Tablet','CAPRIBOSE','Tablet','Tablet','Obat Keras','https://dto.kemkes.go.id/kfacode/93000549',0,'2023-05-01');
... A77: 93000410 | B77: Asam Asetilsalisilat 80 mg Tablet Salut Enterik (THROMBO ASPILETS) | C77: 92000293 | D77: Asam Asetilsalisilat 80 mg Tablet Salut Enterik | E77: THROMBO ASPILETS | F77: Tablet | G77: Tablet Salut Enterik | H77: Obat Keras | I77: =_xlfn.TEXTJOIN("/",,"https://dto.kemkes.go.id/kfacode",A77) -> https://dto.kemkes.go.id/kfacode/93000410 | J77: insert into mkatalog_kfa93 (kode, uraian, kode_92, uraian_92, nama_dagang, satuan_kecil, sediaan, golongan, url, userid_updt, sysdate_updt) values | K77: =CONCATENATE(J77,"('",A77,"','",B77,"','",C77,"','",D77,"','",E77,"','",F77,"','",G77,"','",H77,"','",I77,"',0,'2023-05-01');") -> insert into mkatalog_kfa93 (kode, uraian, kode_92, uraian_92, nama_dagang, satuan_kecil, sediaan, golongan, url, userid_updt, sysdate_updt) values ('93000410','Asam Asetilsalisilat 80 mg Tablet Salut Enterik (THROMBO ASPILETS)','92000293','Asam Asetilsalisilat 80 mg Tablet Salut Enterik','THROMBO ASPILETS','Tablet','Tablet Salut Enterik','Obat Keras','https://dto.kemkes.go.id/kfacode/93000410',0,'2023-05-01');
A78: 93000946 | B78: Ascorbic Acid / Asam Askorbat / Vitamin C 250 mg Tablet (AFIFARMA) | C78: 92000129 | D78: Ascorbic Acid / Asam Askorbat / Vitamin C 250 mg Tablet | F78: Tablet | G78: Tablet | H78: Obat Bebas | I78: =_xlfn.TEXTJOIN("/",,"https://dto.kemkes.go.id/kfacode",A78) -> https://dto.kemkes.go.id/kfacode/93000946 | J78: insert into mkatalog_kfa93 (kode, uraian, kode_92, uraian_92, nama_dagang, satuan_kecil, sediaan, golongan, url, userid_updt, sysdate_updt) values | K78: =CONCATENATE(J78,"('",A78,"','",B78,"','",C78,"','",D78,"','",E78,"','",F78,"','",G78,"','",H78,"','",I78,"',0,'2023-05-01');") -> insert into mkatalog_kfa93 (kode, uraian, kode_92, uraian_92, nama_dagang, satuan_kecil, sediaan, golongan, url, userid_updt, sysdate_updt) values ('93000946','Ascorbic Acid / Asam Askorbat / Vitamin C 250 mg Tablet (AFIFARMA)','92000129','Ascorbic Acid / Asam Askorbat / Vitamin C 250 mg Tablet','','Tablet','Tablet','Obat Bebas','https://dto.kemkes.go.id/kfacode/93000946',0,'2023-05-01');
A79: 93000139 | B79: Ascorbic Acid / Asam Askorbat / Vitamin C 250 mg Tablet (IMFARMIND) | C79: 92000129 | D79: Ascorbic Acid / Asam Askorbat / Vitamin C 250 mg Tablet | E79: VITAMIN C 250 MG | F79: Tablet | G79: Tablet | H79: Obat Bebas | I79: =_xlfn.TEXTJOIN("/",,"https://dto.kemkes.go.id/kfacode",A79) -> https://dto.kemkes.go.id/kfacode/93000139 | J79: insert into mkatalog_kfa93 (kode, uraian, kode_92, uraian_92, nama_dagang, satuan_kecil, sediaan, golongan, url, userid_updt, sysdate_updt) values | K79: =CONCATENATE(J79,"('",A79,"','",B79,"','",C79,"','",D79,"','",E79,"','",F79,"','",G79,"','",H79,"','",I79,"',0,'2023-05-01');") -> insert into mkatalog_kfa93 (kode, uraian, kode_92, uraian_92, nama_dagang, satuan_kecil, sediaan, golongan, url, userid_updt, sysdate_updt) values ('93000139','Ascorbic Acid / Asam Askorbat / Vitamin C 250 mg Tablet (IMFARMIND)','92000129','Ascorbic Acid / Asam Askorbat / Vitamin C 250 mg Tablet','VITAMIN C 250 MG','Tablet','Tablet','Obat Bebas','https://dto.kemkes.go.id/kfacode/93000139',0,'2023-05-01');
A80: 93000716 | B80: Ascorbic Acid / Asam Askorbat / Vitamin C 50 mg Tablet (IMFARMIND FARMASI INDUSTRI) | C80: 92000517 | D80: Ascorbic Acid / Asam Askorbat / Vitamin C 50 mg Tablet | E80: VITAMIN C 50 MG | F80: Tablet | G80: Tablet | H80: Obat Bebas | I80: =_xlfn.TEXTJOIN("/",,"https://dto.kemkes.go.id/kfacode",A80) -> https://dto.kemkes.go.id/kfacode/93000716 | J80: insert into mkatalog_kfa93 (kode, uraian, kode_92, uraian_92, nama_dagang, satuan_kecil, sediaan, golongan, url, userid_updt, sysdate_updt) values | K80: =CONCATENATE(J80,"('",A80,"','",B80,"','",C80,"','",D80,"','",E80,"','",F80,"','",G80,"','",H80,"','",I80,"',0,'2023-05-01');") -> insert into mkatalog_kfa93 (kode, uraian, kode_92, uraian_92, nama_dagang, satuan_kecil, sediaan, golongan, url, userid_updt, sysdate_updt) values ('93000716','Ascorbic Acid / Asam Askorbat / Vitamin C 50 mg Tablet (IMFARMIND FARMASI INDUSTRI)','92000517','Ascorbic Acid / Asam Askorbat / Vitamin C 50 mg Tablet','VITAMIN C 50 MG','Tablet','Tablet','Obat Bebas','https://dto.kemkes.go.id/kfacode/93000716',0,'2023-05-01');
A81: 93001648 | B81: ASERING-5 Infus (ASERING-5) | C81: 92000943 | D81: ASERING-5 Infus | E81: ASERING-5 | F81: Botol Plastik | G81: Infus | H81: Obat Keras | I81: =_xlfn.TEXTJOIN("/",,"https://dto.kemkes.go.id/kfacode",A81) -> https://dto.kemkes.go.id/kfacode/93001648 | J81: insert into mkatalog_kfa93 (kode, uraian, kode_92, uraian_92, nama_dagang, satuan_kecil, sediaan, golongan, url, userid_updt, sysdate_updt) values | K81: =CONCATENATE(J81,"('",A81,"','",B81,"','",C81,"','",D81,"','",E81,"','",F81,"','",G81,"','",H81,"','",I81,"',0,'2023-05-01');") -> insert into mkatalog_kfa93 (kode, uraian, kode_92, uraian_92, nama_dagang, satuan_kecil, sediaan, golongan, url, userid_updt, sysdate_updt) values ('93001648','ASERING-5 Infus (ASERING-5)','92000943','ASERING-5 Infus','ASERING-5','Botol Plastik','Infus','Obat Keras','https://dto.kemkes.go.id/kfacode/93001648',0,'2023-05-01');
A82: 93000310 | B82: Asparaginase 10.000 IU Serbuk Injeksi (LEUNASE) | C82: 92000208 | D82: Asparaginase 10.000 IU Serbuk Injeksi | E82: LEUNASE | F82: Vial | G82: Serbuk Injeksi | H82: Obat Keras | I82: =_xlfn.TEXTJOIN("/",,"https://dto.kemkes.go.id/kfacode",A82) -> https://dto.kemkes.go.id/kfacode/93000310 | J82: insert into mkatalog_kfa93 (kode, uraian, kode_92, uraian_92, nama_dagang, satuan_kecil, sediaan, golongan, url, userid_updt, sysdate_updt) values | K82: =CONCATENATE(J82,"('",A82,"','",B82,"','",C82,"','",D82,"','",E82,"','",F82,"','",G82,"','",H82,"','",I82,"',0,'2023-05-01');") -> insert into mkatalog_kfa93 (kode, uraian, kode_92, uraian_92, nama_dagang, satuan_kecil, sediaan, golongan, url, userid_updt, sysdate_updt) values ('93000310','Asparaginase 10.000 IU Serbuk Injeksi (LEUNASE)','92000208','Asparaginase 10.000 IU Serbuk Injeksi','LEUNASE','Vial','Serbuk Injeksi','Obat Keras','https://dto.kemkes.go.id/kfacode/93000310',0,'2023-05-01');
A83: 93000731 | B83: Atorvastatin 20 mg Tablet (DEXA MEDICA - Indonesia - -) | C83: 92000524 | D83: Atorvastatin 20 mg Tablet | E83: ATORVASTATIN CALCIUM TRIHYDRATE | F83: Tablet | G83: Tablet Pelepasan Lambat | H83: Obat Keras | I83: =_xlfn.TEXTJOIN("/",,"https://dto.kemkes.go.id/kfacode",A83) -> https://dto.kemkes.go.id/kfacode/93000731 | J83: insert into mkatalog_kfa93 (kode, uraian, kode_92, uraian_92, nama_dagang, satuan_kecil, sediaan, golongan, url, userid_updt, sysdate_updt) values | K83: =CONCATENATE(J83,"('",A83,"','",B83,"','",C83,"','",D83,"','",E83,"','",F83,"','",G83,"','",H83,"','",I83,"',0,'2023-05-01');") -> insert into mkatalog_kfa93 (kode, uraian, kode_92, uraian_92, nama_dagang, satuan_kecil, sediaan, golongan, url, userid_updt, sysdate_updt) values ('93000731','Atorvastatin 20 mg Tablet (DEXA MEDICA - Indonesia - -)','92000524','Atorvastatin 20 mg Tablet','ATORVASTATIN CALCIUM TRIHYDRATE','Tablet','Tablet Pelepasan Lambat','Obat Keras','https://dto.kemkes.go.id/kfacode/93000731',0,'2023-05-01');
A84: 93001127 | B84: Atorvastatin Calcium Trihydrate 10 mg Tablet Salut Selaput (DEXA MEDICA) | C84: 92000355 | D84: Atorvastatin Calcium Trihydrate 10 mg Tablet Salut Selaput | E84: ATORVASTATIN CALCIUM TRIHYDRATE | F84: Tablet | G84: Tablet Salut Selaput | H84: Obat Keras | I84: =_xlfn.TEXTJOIN("/",,"https://dto.kemkes.go.id/kfacode",A84) -> https://dto.kemkes.go.id/kfacode/93001127 | J84: insert into mkatalog_kfa93 (kode, uraian, kode_92, uraian_92, nama_dagang, satuan_kecil, sediaan, golongan, url, userid_updt, sysdate_updt) values | K84: =CONCATENATE(J84,"('",A84,"','",B84,"','",C84,"','",D84,"','",E84,"','",F84,"','",G84,"','",H84,"','",I84,"',0,'2023-05-01');") -> insert into mkatalog_kfa93 (kode, uraian, kode_92, uraian_92, nama_dagang, satuan_kecil, sediaan, golongan, url, userid_updt, sysdate_updt) values ('93001127','Atorvastatin Calcium Trihydrate 10 mg Tablet Salut Selaput (DEXA MEDICA)','92000355','Atorvastatin Calcium Trihydrate 10 mg Tablet Salut Selaput','ATORVASTATIN CALCIUM TRIHYDRATE','Tablet','Tablet Salut Selaput','Obat Keras','https://dto.kemkes.go.id/kfacode/93001127',0,'2023-05-01');
A85: 93001397 | B85: Atracurium Besilate 10 mg / mL Injeksi (ETHICA, 2,5 mL) | C85: 92000742 | D85: Atracurium Besilate 10 mg / mL Injeksi | E85: ATRACURIUM BESILATE | F85: Ampul | G85: Larutan Injeksi | H85: Obat Keras | I85: =_xlfn.TEXTJOIN("/",,"https://dto.kemkes.go.id/kfacode",A85) -> https://dto.kemkes.go.id/kfacode/93001397 | J85: insert into mkatalog_kfa93 (kode, uraian, kode_92, uraian_92, nama_dagang, satuan_kecil, sediaan, golongan, url, userid_updt, sysdate_updt) values | K85: =CONCATENATE(J85,"('",A85,"','",B85,"','",C85,"','",D85,"','",E85,"','",F85,"','",G85,"','",H85,"','",I85,"',0,'2023-05-01');") -> insert into mkatalog_kfa93 (kode, uraian, kode_92, uraian_92, nama_dagang, satuan_kecil, sediaan, golongan, url, userid_updt, sysdate_updt) values ('93001397','Atracurium Besilate 10 mg / mL Injeksi (ETHICA, 2,5 mL)','92000742','Atracurium Besilate 10 mg / mL Injeksi','ATRACURIUM BESILATE','Ampul','Larutan Injeksi','Obat Keras','https://dto.kemkes.go.id/kfacode/93001397',0,'2023-05-01');
A86: 93001396 | B86: Atracurium Besilate 10 mg / mL Injeksi (ETHICA, 5 mL) | C86: 92000742 | D86: Atracurium Besilate 10 mg / mL Injeksi | E86: ATRACURIUM BESILATE | F86: Ampul | G86: Larutan Injeksi | H86: Obat Keras | I86: =_xlfn.TEXTJOIN("/",,"https://dto.kemkes.go.id/kfacode",A86) -> https://dto.kemkes.go.id/kfacode/93001396 | J86: insert into mkatalog_kfa93 (kode, uraian, kode_92, uraian_92, nama_dagang, satuan_kecil, sediaan, golongan, url, userid_updt, sysdate_updt) values | K86: =CONCATENATE(J86,"('",A86,"','",B86,"','",C86,"','",D86,"','",E86,"','",F86,"','",G86,"','",H86,"','",I86,"',0,'2023-05-01');") -> insert into mkatalog_kfa93 (kode, uraian, kode_92, uraian_92, nama_dagang, satuan_kecil, sediaan, golongan, url, userid_updt, sysdate_updt) values ('93001396','Atracurium Besilate 10 mg / mL Injeksi (ETHICA, 5 mL)','92000742','Atracurium Besilate 10 mg / mL Injeksi','ATRACURIUM BESILATE','Ampul','Larutan Injeksi','Obat Keras','https://dto.kemkes.go.id/kfacode/93001396',0,'2023-05-01');
A87: 93000658 | B87: Atropine Sulfate 0,25 mg / mL Injeksi (ETHICA) | C87: 92000114 | D87: Atropine Sulfate 0,25 mg / mL Injeksi | E87: ATROPINE SULFATE | F87: Ampul | G87: Larutan Injeksi | H87: Obat Keras | I87: =_xlfn.TEXTJOIN("/",,"https://dto.kemkes.go.id/kfacode",A87) -> https://dto.kemkes.go.id/kfacode/93000658 | J87: insert into mkatalog_kfa93 (kode, uraian, kode_92, uraian_92, nama_dagang, satuan_kecil, sediaan, golongan, url, userid_updt, sysdate_updt) values | K87: =CONCATENATE(J87,"('",A87,"','",B87,"','",C87,"','",D87,"','",E87,"','",F87,"','",G87,"','",H87,"','",I87,"',0,'2023-05-01');") -> insert into mkatalog_kfa93 (kode, uraian, kode_92, uraian_92, nama_dagang, satuan_kecil, sediaan, golongan, url, userid_updt, sysdate_updt) values ('93000658','Atropine Sulfate 0,25 mg / mL Injeksi (ETHICA)','92000114','Atropine Sulfate 0,25 mg / mL Injeksi','ATROPINE SULFATE','Ampul','Larutan Injeksi','Obat Keras','https://dto.kemkes.go.id/kfacode/93000658',0,'2023-05-01');
A88: 93000777 | B88: Azathioprine 50 mg Tablet Salut Selaput (IMURAN) | C88: 92000549 | D88: Azathioprine 50 mg Tablet Salut Selaput | E88: IMURAN | F88: Tablet | G88: Tablet Salut Selaput | H88: Obat Keras | I88: =_xlfn.TEXTJOIN("/",,"https://dto.kemkes.go.id/kfacode",A88) -> https://dto.kemkes.go.id/kfacode/93000777 | J88: insert into mkatalog_kfa93 (kode, uraian, kode_92, uraian_92, nama_dagang, satuan_kecil, sediaan, golongan, url, userid_updt, sysdate_updt) values | K88: =CONCATENATE(J88,"('",A88,"','",B88,"','",C88,"','",D88,"','",E88,"','",F88,"','",G88,"','",H88,"','",I88,"',0,'2023-05-01');") -> insert into mkatalog_kfa93 (kode, uraian, kode_92, uraian_92, nama_dagang, satuan_kecil, sediaan, golongan, url, userid_updt, sysdate_updt) values ('93000777','Azathioprine 50 mg Tablet Salut Selaput (IMURAN)','92000549','Azathioprine 50 mg Tablet Salut Selaput','IMURAN','Tablet','Tablet Salut Selaput','Obat Keras','https://dto.kemkes.go.id/kfacode/93000777',0,'2023-05-01');
A89: 93000357 | B89: Azithromycin 500 mg Kaplet Salut Selaput (HEXPHARM JAYA LABORATORIES) | C89: 92000230 | D89: Azithromycin 500 mg Kaplet Salut Selaput | E89: AZITHROMYCIN DIHYDRATE | F89: Kaplet | G89: Kaplet Salut Selaput | H89: Obat Keras | I89: =_xlfn.TEXTJOIN("/",,"https://dto.kemkes.go.id/kfacode",A89) -> https://dto.kemkes.go.id/kfacode/93000357 | J89: insert into mkatalog_kfa93 (kode, uraian, kode_92, uraian_92, nama_dagang, satuan_kecil, sediaan, golongan, url, userid_updt, sysdate_updt) values | K89: =CONCATENATE(J89,"('",A89,"','",B89,"','",C89,"','",D89,"','",E89,"','",F89,"','",G89,"','",H89,"','",I89,"',0,'2023-05-01');") -> insert into mkatalog_kfa93 (kode, uraian, kode_92, uraian_92, nama_dagang, satuan_kecil, sediaan, golongan, url, userid_updt, sysdate_updt) values ('93000357','Azithromycin 500 mg Kaplet Salut Selaput (HEXPHARM JAYA LABORATORIES)','92000230','Azithromycin 500 mg Kaplet Salut Selaput','AZITHROMYCIN DIHYDRATE','Kaplet','Kaplet Salut Selaput','Obat Keras','https://dto.kemkes.go.id/kfacode/93000357',0,'2023-05-01');
A90: 93000359 | B90: Azithromycin 500 mg Kaplet Salut Selaput (KIMIA FARMA) | C90: 92000230 | D90: Azithromycin 500 mg Kaplet Salut Selaput | E90: AZITHROMYCIN | F90: Kaplet | G90: Kaplet Salut Selaput | H90: Obat Keras | I90: =_xlfn.TEXTJOIN("/",,"https://dto.kemkes.go.id/kfacode",A90) -> https://dto.kemkes.go.id/kfacode/93000359 | J90: insert into mkatalog_kfa93 (kode, uraian, kode_92, uraian_92, nama_dagang, satuan_kecil, sediaan, golongan, url, userid_updt, sysdate_updt) values | K90: =CONCATENATE(J90,"('",A90,"','",B90,"','",C90,"','",D90,"','",E90,"','",F90,"','",G90,"','",H90,"','",I90,"',0,'2023-05-01');") -> insert into mkatalog_kfa93 (kode, uraian, kode_92, uraian_92, nama_dagang, satuan_kecil, sediaan, golongan, url, userid_updt, sysdate_updt) values ('93000359','Azithromycin 500 mg Kaplet Salut Selaput (KIMIA FARMA)','92000230','Azithromycin 500 mg Kaplet Salut Selaput','AZITHROMYCIN','Kaplet','Kaplet Salut Selaput','Obat Keras','https://dto.kemkes.go.id/kfacode/93000359',0,'2023-05-01');
... A140: 93000741 | B140: Bisoprolol Fumarate 5 mg Tablet (SELBIX) | C140: 92000526 | D140: Bisoprolol Fumarate 5 mg Tablet | E140: SELBIX | F140: Tablet | G140: Tablet Pelepasan Lambat | H140: Obat Keras | I140: =_xlfn.TEXTJOIN("/",,"https://dto.kemkes.go.id/kfacode",A140) -> https://dto.kemkes.go.id/kfacode/93000741 | J140: insert into mkatalog_kfa93 (kode, uraian, kode_92, uraian_92, nama_dagang, satuan_kecil, sediaan, golongan, url, userid_updt, sysdate_updt) values | K140: =CONCATENATE(J140,"('",A140,"','",B140,"','",C140,"','",D140,"','",E140,"','",F140,"','",G140,"','",H140,"','",I140,"',0,'2023-05-01');") -> insert into mkatalog_kfa93 (kode, uraian, kode_92, uraian_92, nama_dagang, satuan_kecil, sediaan, golongan, url, userid_updt, sysdate_updt) values ('93000741','Bisoprolol Fumarate 5 mg Tablet (SELBIX)','92000526','Bisoprolol Fumarate 5 mg Tablet','SELBIX','Tablet','Tablet Pelepasan Lambat','Obat Keras','https://dto.kemkes.go.id/kfacode/93000741',0,'2023-05-01');
A141: 93000745 | B141: Bisoprolol Fumarate 5 mg Tablet (TENCARD) | C141: 92000526 | D141: Bisoprolol Fumarate 5 mg Tablet | F141: Tablet | G141: Tablet Pelepasan Lambat | H141: Obat Keras | I141: =_xlfn.TEXTJOIN("/",,"https://dto.kemkes.go.id/kfacode",A141) -> https://dto.kemkes.go.id/kfacode/93000745 | J141: insert into mkatalog_kfa93 (kode, uraian, kode_92, uraian_92, nama_dagang, satuan_kecil, sediaan, golongan, url, userid_updt, sysdate_updt) values | K141: =CONCATENATE(J141,"('",A141,"','",B141,"','",C141,"','",D141,"','",E141,"','",F141,"','",G141,"','",H141,"','",I141,"',0,'2023-05-01');") -> insert into mkatalog_kfa93 (kode, uraian, kode_92, uraian_92, nama_dagang, satuan_kecil, sediaan, golongan, url, userid_updt, sysdate_updt) values ('93000745','Bisoprolol Fumarate 5 mg Tablet (TENCARD)','92000526','Bisoprolol Fumarate 5 mg Tablet','','Tablet','Tablet Pelepasan Lambat','Obat Keras','https://dto.kemkes.go.id/kfacode/93000745',0,'2023-05-01');
A142: 93000394 | B142: Bleomycin 15 mg Serbuk Injeksi (BLEOCIN) | C142: 92000285 | D142: Bleomycin 15 mg Serbuk Injeksi | E142: BLEOCIN | F142: Vial | G142: Serbuk Injeksi | H142: Obat Keras | I142: =_xlfn.TEXTJOIN("/",,"https://dto.kemkes.go.id/kfacode",A142) -> https://dto.kemkes.go.id/kfacode/93000394 | J142: insert into mkatalog_kfa93 (kode, uraian, kode_92, uraian_92, nama_dagang, satuan_kecil, sediaan, golongan, url, userid_updt, sysdate_updt) values | K142: =CONCATENATE(J142,"('",A142,"','",B142,"','",C142,"','",D142,"','",E142,"','",F142,"','",G142,"','",H142,"','",I142,"',0,'2023-05-01');") -> insert into mkatalog_kfa93 (kode, uraian, kode_92, uraian_92, nama_dagang, satuan_kecil, sediaan, golongan, url, userid_updt, sysdate_updt) values ('93000394','Bleomycin 15 mg Serbuk Injeksi (BLEOCIN)','92000285','Bleomycin 15 mg Serbuk Injeksi','BLEOCIN','Vial','Serbuk Injeksi','Obat Keras','https://dto.kemkes.go.id/kfacode/93000394',0,'2023-05-01');
A143: 93001608 | B143: Bortezomib 3,5 mg Serbuk Injeksi Liofilisasi (BORMIB) | C143: 92000912 | D143: Bortezomib 3,5 mg Serbuk Injeksi Liofilisasi | E143: BORMIB | F143: Vial | G143: Serbuk Injeksi Liofilisasi | H143: Obat Keras | I143: =_xlfn.TEXTJOIN("/",,"https://dto.kemkes.go.id/kfacode",A143) -> https://dto.kemkes.go.id/kfacode/93001608 | J143: insert into mkatalog_kfa93 (kode, uraian, kode_92, uraian_92, nama_dagang, satuan_kecil, sediaan, golongan, url, userid_updt, sysdate_updt) values | K143: =CONCATENATE(J143,"('",A143,"','",B143,"','",C143,"','",D143,"','",E143,"','",F143,"','",G143,"','",H143,"','",I143,"',0,'2023-05-01');") -> insert into mkatalog_kfa93 (kode, uraian, kode_92, uraian_92, nama_dagang, satuan_kecil, sediaan, golongan, url, userid_updt, sysdate_updt) values ('93001608','Bortezomib 3,5 mg Serbuk Injeksi Liofilisasi (BORMIB)','92000912','Bortezomib 3,5 mg Serbuk Injeksi Liofilisasi','BORMIB','Vial','Serbuk Injeksi Liofilisasi','Obat Keras','https://dto.kemkes.go.id/kfacode/93001608',0,'2023-05-01');
A144: 93001596 | B144: Bortezomib 3,5 mg Serbuk Injeksi Liofilisasi (BORTERO) | C144: 92000912 | D144: Bortezomib 3,5 mg Serbuk Injeksi Liofilisasi | E144: BORTERO | F144: Vial | G144: Serbuk Injeksi Liofilisasi | H144: Obat Keras | I144: =_xlfn.TEXTJOIN("/",,"https://dto.kemkes.go.id/kfacode",A144) -> https://dto.kemkes.go.id/kfacode/93001596 | J144: insert into mkatalog_kfa93 (kode, uraian, kode_92, uraian_92, nama_dagang, satuan_kecil, sediaan, golongan, url, userid_updt, sysdate_updt) values | K144: =CONCATENATE(J144,"('",A144,"','",B144,"','",C144,"','",D144,"','",E144,"','",F144,"','",G144,"','",H144,"','",I144,"',0,'2023-05-01');") -> insert into mkatalog_kfa93 (kode, uraian, kode_92, uraian_92, nama_dagang, satuan_kecil, sediaan, golongan, url, userid_updt, sysdate_updt) values ('93001596','Bortezomib 3,5 mg Serbuk Injeksi Liofilisasi (BORTERO)','92000912','Bortezomib 3,5 mg Serbuk Injeksi Liofilisasi','BORTERO','Vial','Serbuk Injeksi Liofilisasi','Obat Keras','https://dto.kemkes.go.id/kfacode/93001596',0,'2023-05-01');
A145: 93001597 | B145: Bortezomib 3,5 mg Serbuk Injeksi Liofilisasi (FONKOZOMIB) | C145: 92000912 | D145: Bortezomib 3,5 mg Serbuk Injeksi Liofilisasi | E145: FONKOZOMIB | F145: Vial | G145: Serbuk Injeksi Liofilisasi | H145: Obat Keras | I145: =_xlfn.TEXTJOIN("/",,"https://dto.kemkes.go.id/kfacode",A145) -> https://dto.kemkes.go.id/kfacode/93001597 | J145: insert into mkatalog_kfa93 (kode, uraian, kode_92, uraian_92, nama_dagang, satuan_kecil, sediaan, golongan, url, userid_updt, sysdate_updt) values | K145: =CONCATENATE(J145,"('",A145,"','",B145,"','",C145,"','",D145,"','",E145,"','",F145,"','",G145,"','",H145,"','",I145,"',0,'2023-05-01');") -> insert into mkatalog_kfa93 (kode, uraian, kode_92, uraian_92, nama_dagang, satuan_kecil, sediaan, golongan, url, userid_updt, sysdate_updt) values ('93001597','Bortezomib 3,5 mg Serbuk Injeksi Liofilisasi (FONKOZOMIB)','92000912','Bortezomib 3,5 mg Serbuk Injeksi Liofilisasi','FONKOZOMIB','Vial','Serbuk Injeksi Liofilisasi','Obat Keras','https://dto.kemkes.go.id/kfacode/93001597',0,'2023-05-01');
A146: 93000651 | B146: Budesonid 0.25 mg/mL Spray (BUDESMA) | C146: 92000489 | D146: Budesonid 0.25 mg/mL Spray | E146: BUDESMA | F146: Botol | G146: Larutan Inhalasi | H146: Obat Keras | I146: =_xlfn.TEXTJOIN("/",,"https://dto.kemkes.go.id/kfacode",A146) -> https://dto.kemkes.go.id/kfacode/93000651 | J146: insert into mkatalog_kfa93 (kode, uraian, kode_92, uraian_92, nama_dagang, satuan_kecil, sediaan, golongan, url, userid_updt, sysdate_updt) values | K146: =CONCATENATE(J146,"('",A146,"','",B146,"','",C146,"','",D146,"','",E146,"','",F146,"','",G146,"','",H146,"','",I146,"',0,'2023-05-01');") -> insert into mkatalog_kfa93 (kode, uraian, kode_92, uraian_92, nama_dagang, satuan_kecil, sediaan, golongan, url, userid_updt, sysdate_updt) values ('93000651','Budesonid 0.25 mg/mL Spray (BUDESMA)','92000489','Budesonid 0.25 mg/mL Spray','BUDESMA','Botol','Larutan Inhalasi','Obat Keras','https://dto.kemkes.go.id/kfacode/93000651',0,'2023-05-01');
A147: 93000655 | B147: Budesonid 0.25 mg/mL Spray (PRATAPA NIRMALA - Indonesia - -) | C147: 92000489 | D147: Budesonid 0.25 mg/mL Spray | F147: Botol | G147: Larutan Inhalasi | H147: Obat Keras | I147: =_xlfn.TEXTJOIN("/",,"https://dto.kemkes.go.id/kfacode",A147) -> https://dto.kemkes.go.id/kfacode/93000655 | J147: insert into mkatalog_kfa93 (kode, uraian, kode_92, uraian_92, nama_dagang, satuan_kecil, sediaan, golongan, url, userid_updt, sysdate_updt) values | K147: =CONCATENATE(J147,"('",A147,"','",B147,"','",C147,"','",D147,"','",E147,"','",F147,"','",G147,"','",H147,"','",I147,"',0,'2023-05-01');") -> insert into mkatalog_kfa93 (kode, uraian, kode_92, uraian_92, nama_dagang, satuan_kecil, sediaan, golongan, url, userid_updt, sysdate_updt) values ('93000655','Budesonid 0.25 mg/mL Spray (PRATAPA NIRMALA - Indonesia - -)','92000489','Budesonid 0.25 mg/mL Spray','','Botol','Larutan Inhalasi','Obat Keras','https://dto.kemkes.go.id/kfacode/93000655',0,'2023-05-01');
A148: 93000649 | B148: Budesonid 0.25 mg/mL Spray (PULMICORT RESPULES) | C148: 92000489 | D148: Budesonid 0.25 mg/mL Spray | E148: PULMICORT RESPULES | F148: Botol | G148: Larutan Inhalasi | H148: Obat Keras | I148: =_xlfn.TEXTJOIN("/",,"https://dto.kemkes.go.id/kfacode",A148) -> https://dto.kemkes.go.id/kfacode/93000649 | J148: insert into mkatalog_kfa93 (kode, uraian, kode_92, uraian_92, nama_dagang, satuan_kecil, sediaan, golongan, url, userid_updt, sysdate_updt) values | K148: =CONCATENATE(J148,"('",A148,"','",B148,"','",C148,"','",D148,"','",E148,"','",F148,"','",G148,"','",H148,"','",I148,"',0,'2023-05-01');") -> insert into mkatalog_kfa93 (kode, uraian, kode_92, uraian_92, nama_dagang, satuan_kecil, sediaan, golongan, url, userid_updt, sysdate_updt) values ('93000649','Budesonid 0.25 mg/mL Spray (PULMICORT RESPULES)','92000489','Budesonid 0.25 mg/mL Spray','PULMICORT RESPULES','Botol','Larutan Inhalasi','Obat Keras','https://dto.kemkes.go.id/kfacode/93000649',0,'2023-05-01');
A149: 93000652 | B149: Budesonid 0.25 mg/mL Spray (SONIDE 0,25) | C149: 92000489 | D149: Budesonid 0.25 mg/mL Spray | E149: SONIDE 0,25 | F149: Botol | G149: Larutan Inhalasi | H149: Obat Keras | I149: =_xlfn.TEXTJOIN("/",,"https://dto.kemkes.go.id/kfacode",A149) -> https://dto.kemkes.go.id/kfacode/93000652 | J149: insert into mkatalog_kfa93 (kode, uraian, kode_92, uraian_92, nama_dagang, satuan_kecil, sediaan, golongan, url, userid_updt, sysdate_updt) values | K149: =CONCATENATE(J149,"('",A149,"','",B149,"','",C149,"','",D149,"','",E149,"','",F149,"','",G149,"','",H149,"','",I149,"',0,'2023-05-01');") -> insert into mkatalog_kfa93 (kode, uraian, kode_92, uraian_92, nama_dagang, satuan_kecil, sediaan, golongan, url, userid_updt, sysdate_updt) values ('93000652','Budesonid 0.25 mg/mL Spray (SONIDE 0,25)','92000489','Budesonid 0.25 mg/mL Spray','SONIDE 0,25','Botol','Larutan Inhalasi','Obat Keras','https://dto.kemkes.go.id/kfacode/93000652',0,'2023-05-01');
A150: 93000705 | B150: Budesonide 0,25 mg / mL Cairan Inhalasi (PULMICORT RESPULES) | C150: 92000481 | D150: Budesonide 0,25 mg / mL Cairan Inhalasi | E150: PULMICORT RESPULES | F150: Respules | G150: Larutan Inhalasi | H150: Obat Keras | I150: =_xlfn.TEXTJOIN("/",,"https://dto.kemkes.go.id/kfacode",A150) -> https://dto.kemkes.go.id/kfacode/93000705 | J150: insert into mkatalog_kfa93 (kode, uraian, kode_92, uraian_92, nama_dagang, satuan_kecil, sediaan, golongan, url, userid_updt, sysdate_updt) values | K150: =CONCATENATE(J150,"('",A150,"','",B150,"','",C150,"','",D150,"','",E150,"','",F150,"','",G150,"','",H150,"','",I150,"',0,'2023-05-01');") -> insert into mkatalog_kfa93 (kode, uraian, kode_92, uraian_92, nama_dagang, satuan_kecil, sediaan, golongan, url, userid_updt, sysdate_updt) values ('93000705','Budesonide 0,25 mg / mL Cairan Inhalasi (PULMICORT RESPULES)','92000481','Budesonide 0,25 mg / mL Cairan Inhalasi','PULMICORT RESPULES','Respules','Larutan Inhalasi','Obat Keras','https://dto.kemkes.go.id/kfacode/93000705',0,'2023-05-01');
A151: 93001056 | B151: Budesonide 0,25 mg / mL Suspensi Inhalasi (PRATAPA NIRMALA) | C151: 92000739 | D151: Budesonide 0,25 mg / mL Suspensi Inhalasi | E151: BUDESONIDE | F151: Ampul | G151: Suspensi Inhalasi | H151: Obat Keras | I151: =_xlfn.TEXTJOIN("/",,"https://dto.kemkes.go.id/kfacode",A151) -> https://dto.kemkes.go.id/kfacode/93001056 | J151: insert into mkatalog_kfa93 (kode, uraian, kode_92, uraian_92, nama_dagang, satuan_kecil, sediaan, golongan, url, userid_updt, sysdate_updt) values | K151: =CONCATENATE(J151,"('",A151,"','",B151,"','",C151,"','",D151,"','",E151,"','",F151,"','",G151,"','",H151,"','",I151,"',0,'2023-05-01');") -> insert into mkatalog_kfa93 (kode, uraian, kode_92, uraian_92, nama_dagang, satuan_kecil, sediaan, golongan, url, userid_updt, sysdate_updt) values ('93001056','Budesonide 0,25 mg / mL Suspensi Inhalasi (PRATAPA NIRMALA)','92000739','Budesonide 0,25 mg / mL Suspensi Inhalasi','BUDESONIDE','Ampul','Suspensi Inhalasi','Obat Keras','https://dto.kemkes.go.id/kfacode/93001056',0,'2023-05-01');
...
